Workbook

Sheet Como usar
A1: OPPA — O MAPA DA PLANILHA
A2: Catorze abas, mas você só precisa de quatro no dia a dia. A cor da aba diz o que fazer com ela.
B4: O CAMINHO MAIS CURTO
B5: 1. | C5: Abra o RESUMO e veja onde o negócio está nos três cenários.
B6: 2. | C6: Abra PREÇO para entender de onde sai o valor da assinatura e testar um preço.
B7: 3. | C7: Mude o que quiser em PREMISSAS. Tudo recalcula sozinho — não há nada para rodar.
B8: 4. | C8: Volte ao RESUMO e compare.
B10: ABA | C10: PARA QUE SERVE | D10: VOCÊ DIGITA?
B11: COMECE AQUI
B12: Como usar | C12: O mapa. Esta tela. | D12: não
B13: LEIA O RESULTADO
B14: Resumo | C14: Os três cenários lado a lado e o diagnóstico. É a aba para mostrar a um sócio ou investidor. | D14: não
B15: Preço | C15: De onde sai o valor da assinatura: nuvem, suporte, pessoas, marketing, administrativo, impostos, comissão da loja e margem. Tem um campo para testar um preço. | D15: só 3 campos
B16: DIGITE AQUI
B17: Premissas | C17: Todos os números do negócio: preços, conversão, churn, custos, tributação. É aqui que você passa a maior parte do tempo. | D17: SIM
B18: O RESULTADO EM DETALHE
B19: DRE Projetada | C19: O resultado mês a mês, de jan/2026 a dez/2030 — colunas B até BI. A soma por ano fica no rodapé, depois do detalhe mensal. | D19: não
B20: Análise Fluxo | C20: O caixa mês a mês, mais VPL, TIR e payback. Traz a linha de verificação que precisa ficar zerada. | D20: não
B21: AJUSTE E ACOMPANHAMENTO POSTERIOR
B22: Pessoas | C22: O time, linha a linha, com data de entrada e de saída de cada pessoa. | D22: SIM
B23: Aportes | C23: Todo o capital: quem aportou, quanto, quando e em que status. | D23: SIM
B24: Investimentos | C24: Cronograma de equipamentos, marca e certificações. | D24: SIM
B25: Sócios | C25: Lucro distribuível e rateio por participação. Os percentuais ainda são provisórios. | D25: SIM
B26: MOTOR E APOIO — ABAS OCULTAS
B27: Faturamento | C27: A receita aberta por linha de negócio. Mesma informação da DRE, em outro corte. | D27: não
B28: Usuários | C28: O funil de usuários e as métricas de unidade (CAC, LTV, churn). | D28: não
B29: Cenários | C29: O motor. Os três cenários rodam aqui e todas as outras abas leem daqui. Nunca edite. | D29: não
B30: Tributos | C30: As tabelas do Simples Nacional (Anexos III e V) e o Fator R. | D30: não
B32: PARA VER UMA ABA OCULTA
B33: Clique com o botão direito em qualquer aba na barra de baixo e escolha 'Reexibir' (Excel) ou 'Mostrar planilha' (LibreOffice). Elas estão ocultas porque são o motor e o apoio — nada se perde, e nada ali precisa ser editado.
B35: AS CORES DAS CÉLULAS
B36: Azul | C36: você digita — é uma premissa sua.
B37: Fundo amarelo | C37: premissa-chave: mexer nela desloca bastante o resultado.
B38: Preto | C38: fórmula calculada na própria aba. Não mexa.
B39: Verde | C39: valor que vem de outra aba. Mude na origem.
B41: SE ALGUM NÚMERO PARECER ERRADO
B42: • Na ANÁLISE FLUXO há uma linha de verificação que compara o detalhe com o motor. Ela tem de ficar zerada em todos os meses.
B43: • Na aba PREÇO há duas linhas de conferência que comparam a decomposição de custo com a DRE. Também têm de ficar zeradas.
B44: • Em PREMISSAS, a linha 'Verificação do mix' tem de somar 100% em todos os anos.
B45: • Se alguma delas sair de zero, uma fórmula foi sobrescrita por um valor digitado. Desfaça a última edição ou peça o arquivo novo.

Sheet Resumo
A1: OPPA — VIABILIDADE FINANCEIRA · PAINEL EXECUTIVO
A2: Projeção de 60 meses (jan/2026 – dez/2030). Os três cenários são calculados simultaneamente. Todos os números vêm de fórmulas — nada está digitado à mão.
B4: INDICADOR | C4: CONSERVADOR | D4: PROVÁVEL | E4: AGRESSIVO
B5: Cenário em uso nas abas de detalhe | C5: =IF(Premissas!$B$6=1,"◀ ATIVO","") | D5: =IF(Premissas!$B$6=2,"◀ ATIVO","") -> ◀ ATIVO | E5: =IF(Premissas!$B$6=3,"◀ ATIVO","")
A7: TRAÇÃO — USUÁRIOS E RECEITA
B8: Usuários na base em dez/2026 | C8: =Cenários!$M$13 -> 10860 | D8: =Cenários!$M$59 -> 18100 | E8: =Cenários!$M$105 -> 25340 | G8: Meta do brief: 50 mil usuários ao final de 2026.
B9: Usuários na base em dez/2030 | C9: =Cenários!$BI$13 -> 421839.4 | D9: =Cenários!$BI$59 -> 1115800.7 | E9: =Cenários!$BI$105 -> 2420142.7
B10: Assinantes pagantes em dez/2026 | C10: =Cenários!$M$15 -> 18 | D10: =Cenários!$M$61 -> 90 | E10: =Cenários!$M$107 -> 253 | G10: Meta do brief: 5% da base pagante.
B11: Assinantes pagantes em dez/2030 | C11: =Cenários!$BI$15 -> 4390 | D11: =Cenários!$BI$61 -> 37675 | E11: =Cenários!$BI$107 -> 183322
B12: Receita bruta de 2026 | C12: =SUMIFS(Cenários!$B$28:$BI$28,Cenários!$B$6:$BI$6,2026) -> 1438.2 | D12: =SUMIFS(Cenários!$B$74:$BI$74,Cenários!$B$6:$BI$6,2026) -> 7191 | E12: =SUMIFS(Cenários!$B$120:$BI$120,Cenários!$B$6:$BI$6,2026) -> 20214.7
B13: Receita bruta de 2030 | C13: =SUMIFS(Cenários!$B$28:$BI$28,Cenários!$B$6:$BI$6,2030) -> 4924325.7 | D13: =SUMIFS(Cenários!$B$74:$BI$74,Cenários!$B$6:$BI$6,2030) -> 35439898 | E13: =SUMIFS(Cenários!$B$120:$BI$120,Cenários!$B$6:$BI$6,2030) -> 1.6137721e+08
B14: Receita bruta acumulada em 5 anos | C14: =SUM(Cenários!$B$28:$BI$28) -> 11000912 | D14: =SUM(Cenários!$B$74:$BI$74) -> 72831521 | E14: =SUM(Cenários!$B$120:$BI$120) -> 3.0581403e+08
A16: RESULTADO OPERACIONAL
B17: EBITDA de 2026 | C17: =SUMIFS(Cenários!$B$40:$BI$40,Cenários!$B$6:$BI$6,2026) -> -36984.939 | D17: =SUMIFS(Cenários!$B$86:$BI$86,Cenários!$B$6:$BI$6,2026) -> -36635.697 | E17: =SUMIFS(Cenários!$B$132:$BI$132,Cenários!$B$6:$BI$6,2026) -> -27725.692
B18: EBITDA de 2030 | C18: =SUMIFS(Cenários!$B$40:$BI$40,Cenários!$B$6:$BI$6,2030) -> -5656476 | D18: =SUMIFS(Cenários!$B$86:$BI$86,Cenários!$B$6:$BI$6,2030) -> 4516917.9 | E18: =SUMIFS(Cenários!$B$132:$BI$132,Cenários!$B$6:$BI$6,2030) -> 47924931
B19: EBITDA acumulado em 5 anos | C19: =SUM(Cenários!$B$40:$BI$40) -> -12365859 | D19: =SUM(Cenários!$B$86:$BI$86) -> 7774451.7 | E19: =SUM(Cenários!$B$132:$BI$132) -> 86915003
B20: Margem EBITDA em 2030 (% da receita bruta) | C20: =IFERROR(C18/C13,0) -> -1.1486803 | D20: =IFERROR(D18/D13,0) -> 0.1274529 | E20: =IFERROR(E18/E13,0) -> 0.29697459
B21: Break-even do EBITDA | C21: =IF(SUM(Cenários!$B$46:$BI$46)=0,"não atinge",CHOOSE(MOD(60-SUM(Cenários!$B$46:$BI$46),12)+1,"jan","fev","mar","abr","mai","jun","jul","ago","set","out","nov","dez")&"/"&(2026+INT((60-SUM(Cenários!$B$46:$BI$46))/12))) -> não atinge | D21: =IF(SUM(Cenários!$B$92:$BI$92)=0,"não atinge",CHOOSE(MOD(60-SUM(Cenários!$B$92:$BI$92),12)+1,"jan","fev","mar","abr","mai","jun","jul","ago","set","out","nov","dez")&"/"&(2026+INT((60-SUM(Cenários!$B$92:$BI$92))/12))) -> jun/2027 | E21: =IF(SUM(Cenários!$B$138:$BI$138)=0,"não atinge",CHOOSE(MOD(60-SUM(Cenários!$B$138:$BI$138),12)+1,"jan","fev","mar","abr","mai","jun","jul","ago","set","out","nov","dez")&"/"&(2026+INT((60-SUM(Cenários!$B$138:$BI$138))/12))) -> mar/2027 | G21: Primeiro mês com EBITDA positivo — quando a operação passa a se pagar.
A23: CAPITAL E CAIXA
B24: Investimento total (CAPEX) | C24: =-SUM(Cenários!$B$41:$BI$41) -> 124127.82 | D24: =-SUM(Cenários!$B$87:$BI$87) -> 124127.82 | E24: =-SUM(Cenários!$B$133:$BI$133) -> 124127.82
B25: Capital requerido (pico de caixa negativo do FCL) | C25: =-MIN(Cenários!$B$45:$BI$45) -> 12489987 | D25: =-MIN(Cenários!$B$91:$BI$91) -> 343862.1 | E25: =-MIN(Cenários!$B$137:$BI$137) -> 145974.79 | G25: Quanto a operação precisa de capital antes de se sustentar sozinha.
B26: Capital total considerado | C26: =SUM(Aportes!$B$96:$BI$96) -> 317000 | D26: =SUM(Aportes!$B$96:$BI$96) -> 317000 | E26: =SUM(Aportes!$B$96:$BI$96) -> 317000
B27: Caixa mínimo ao longo do período | C27: =MIN(Cenários!$B$49:$BI$49) -> -12172987 | D27: =MIN(Cenários!$B$95:$BI$95) -> -46752.641 | E27: =MIN(Cenários!$B$141:$BI$141) -> -9014.1427 | G27: Se ficar negativo, o capital planejado não é suficiente — falta captar a diferença.
B28: Mês do caixa mínimo | C28: =CHOOSE(MOD(MATCH(MIN(Cenários!$B$49:$BI$49),Cenários!$B$49:$BI$49,0)-1,12)+1,"jan","fev","mar","abr","mai","jun","jul","ago","set","out","nov","dez")&"/"&(2026+INT((MATCH(MIN(Cenários!$B$49:$BI$49),Cenários!$B$49:$BI$49,0)-1)/12)) -> dez/2030 | D28: =CHOOSE(MOD(MATCH(MIN(Cenários!$B$95:$BI$95),Cenários!$B$95:$BI$95,0)-1,12)+1,"jan","fev","mar","abr","mai","jun","jul","ago","set","out","nov","dez")&"/"&(2026+INT((MATCH(MIN(Cenários!$B$95:$BI$95),Cenários!$B$95:$BI$95,0)-1)/12)) -> jan/2027 | E28: =CHOOSE(MOD(MATCH(MIN(Cenários!$B$141:$BI$141),Cenários!$B$141:$BI$141,0)-1,12)+1,"jan","fev","mar","abr","mai","jun","jul","ago","set","out","nov","dez")&"/"&(2026+INT((MATCH(MIN(Cenários!$B$141:$BI$141),Cenários!$B$141:$BI$141,0)-1)/12)) -> jan/2027 | G28: Quando o caixa chega no fundo do poço — é o mês para o qual o aporte precisa chegar antes.
B29: Caixa em dez/2030 | C29: =Cenários!$BI$49 -> -12172987 | D29: =Cenários!$BI$95 -> 7967323.9 | E29: =Cenários!$BI$141 -> 87107876
A31: INDICADORES DE VIABILIDADE (sobre o Fluxo de Caixa Livre)
B32: VPL — Valor Presente Líquido | C32: {=NPV(Premissas!$B$19,Cenários!$B$42:$BI$42)} -> -5662096.4 | D32: {=NPV(Premissas!$B$19,Cenários!$B$88:$BI$88)} -> 3051853.8 | E32: {=NPV(Premissas!$B$19,Cenários!$B$134:$BI$134)} -> 36619447 | G32: Descontado à TMA definida em Premissas. Positivo = o projeto cria valor.
B33: TIR mensal | C33: =IFERROR(IRR(Cenários!$B$42:$BI$42),"n/d") -> n/d | D33: =IFERROR(IRR(Cenários!$B$88:$BI$88),"n/d") -> 0.11586217 | E33: =IFERROR(IRR(Cenários!$B$134:$BI$134),"n/d") -> 0.39509207
B34: TIR anual | C34: =IFERROR((1+C33)^12-1,"n/d") -> n/d | D34: =IFERROR((1+D33)^12-1,"n/d") -> 2.7267192 | E34: =IFERROR((1+E33)^12-1,"n/d") -> 53.354365 | G34: Compare com a TMA. Atenção: quando o investimento inicial é pequeno diante do caixa gerado, a TIR fica muito alta e perde poder de comparação — olhe o VPL junto.
B35: Payback simples (meses) | C35: =IF(Cenários!$BI$45<0,"> 60",MAX(Cenários!$B$50:$BI$50)+1) -> > 60 | D35: =IF(Cenários!$BI$91<0,"> 60",MAX(Cenários!$B$96:$BI$96)+1) -> 28 | E35: =IF(Cenários!$BI$137<0,"> 60",MAX(Cenários!$B$142:$BI$142)+1) -> 17 | G35: Mês em que o FCL acumulado passa a positivo e não volta mais.
B36: Payback descontado (meses) | C36: =IF(Cenários!$BI$44<0,"> 60",MAX(Cenários!$B$51:$BI$51)+1) -> > 60 | D36: =IF(Cenários!$BI$90<0,"> 60",MAX(Cenários!$B$97:$BI$97)+1) -> 29 | E36: =IF(Cenários!$BI$136<0,"> 60",MAX(Cenários!$B$143:$BI$143)+1) -> 17 | G36: Critério de decisão: payback desejado definido em Premissas.
B37: FCL acumulado em 5 anos | C37: =SUM(Cenários!$B$42:$BI$42) -> -12489987 | D37: =SUM(Cenários!$B$88:$BI$88) -> 7650323.9 | E37: =SUM(Cenários!$B$134:$BI$134) -> 86790876
B38: Retorno sobre o capital requerido (múltiplo) | C38: =IFERROR(C37/C25,0) -> -1 | D38: =IFERROR(D37/D25,0) -> 22.248232 | E38: =IFERROR(E37/E25,0) -> 594.56071 | G38: Múltiplo, não percentual: 3,0x significa devolver três vezes o capital que o projeto precisou. Negativo significa que o capital não volta.
A40: TESTE DE DECISÃO — GO / NO-GO
B41: O caixa nunca fica negativo? | C41: =IF(C27>=0,"SIM","NÃO") -> NÃO | D41: =IF(D27>=0,"SIM","NÃO") -> NÃO | E41: =IF(E27>=0,"SIM","NÃO") -> NÃO
B42: O VPL é positivo? | C42: =IF(C32>0,"SIM","NÃO") -> NÃO | D42: =IF(D32>0,"SIM","NÃO") -> SIM | E42: =IF(E32>0,"SIM","NÃO") -> SIM
B43: A TIR anual supera a TMA? | C43: =IF(N(C34)>Premissas!$B$18,"SIM","NÃO") -> NÃO | D43: =IF(N(D34)>Premissas!$B$18,"SIM","NÃO") -> SIM | E43: =IF(N(E34)>Premissas!$B$18,"SIM","NÃO") -> SIM
B44: O payback descontado cabe no prazo desejado? | C44: =IF(AND(ISNUMBER(C36),N(C36)<=Premissas!$B$20),"SIM","NÃO") -> NÃO | D44: =IF(AND(ISNUMBER(D36),N(D36)<=Premissas!$B$20),"SIM","NÃO") -> SIM | E44: =IF(AND(ISNUMBER(E36),N(E36)<=Premissas!$B$20),"SIM","NÃO") -> SIM
B45: DIAGNÓSTICO | C45: =IF(COUNTIF(C41:C44,"SIM")=4,"GO — VIÁVEL",IF(COUNTIF(C41:C44,"SIM")>=2,"GO COM RESSALVAS","NO GO — INVIÁVEL")) -> NO GO — INVIÁVEL | D45: =IF(COUNTIF(D41:D44,"SIM")=4,"GO — VIÁVEL",IF(COUNTIF(D41:D44,"SIM")>=2,"GO COM RESSALVAS","NO GO — INVIÁVEL")) -> GO COM RESSALVAS | E45: =IF(COUNTIF(E41:E44,"SIM")=4,"GO — VIÁVEL",IF(COUNTIF(E41:E44,"SIM")>=2,"GO COM RESSALVAS","NO GO — INVIÁVEL")) -> GO COM RESSALVAS
A47: MÉTRICAS DE UNIDADE — CENÁRIO ATIVO (dez/2030)
...

Sheet Preço
A1: PREÇO — DE ONDE SAI O VALOR DA ASSINATURA
A2: Custo de atender um assinante por mês, componente por componente, e o preço que esse custo exige. Quatro momentos, porque o custo por assinante cai com a escala: o que é caro com 90 assinantes é barato com 37 mil.
A3: =" Cenário ativo: "&Premissas!$B$6&" · todos os valores em R$ por assinante por mês, salvo onde indicado" -> Cenário ativo: 2 · todos os valores em R$ por assinante por mês, salvo onde indicado
A5: 1. OS QUATRO MOMENTOS DA TABELA
A6: Mês nº na linha do tempo (1 = jan/2026 · 60 = dez/2030) | B6: =Premissas!$B$14 -> 12 | C6: =MIN(60,Premissas!$B$14+6) -> 18 | D6: =MIN(60,Premissas!$B$14+12) -> 24 | E6: =60 -> 60 | G6: Lançamento, +6 meses, +12 meses e o último mês do modelo. Digite por cima para olhar qualquer outro mês — é a única célula desta aba que você precisa mexer.
A7: Mês | B7: =INDEX(Cenários!$B$4:$BI$4,B$6) -> 46357 | C7: =INDEX(Cenários!$B$4:$BI$4,C$6) -> 46539 | D7: =INDEX(Cenários!$B$4:$BI$4,D$6) -> 46722 | E7: =INDEX(Cenários!$B$4:$BI$4,E$6) -> 47818
A8: Base total de usuários (pagantes + gratuitos) | B8: =CHOOSE(Premissas!$B$6,INDEX(Cenários!$B$13:$BI$13,B$6),INDEX(Cenários!$B$59:$BI$59,B$6),INDEX(Cenários!$B$105:$BI$105,B$6)) -> 18100 | C8: =CHOOSE(Premissas!$B$6,INDEX(Cenários!$B$13:$BI$13,C$6),INDEX(Cenários!$B$59:$BI$59,C$6),INDEX(Cenários!$B$105:$BI$105,C$6)) -> 146500.55 | D8: =CHOOSE(Premissas!$B$6,INDEX(Cenários!$B$13:$BI$13,D$6),INDEX(Cenários!$B$59:$BI$59,D$6),INDEX(Cenários!$B$105:$BI$105,D$6)) -> 226826.12 | E8: =CHOOSE(Premissas!$B$6,INDEX(Cenários!$B$13:$BI$13,E$6),INDEX(Cenários!$B$59:$BI$59,E$6),INDEX(Cenários!$B$105:$BI$105,E$6)) -> 1115800.7
A9: Assinantes pagantes | B9: =CHOOSE(Premissas!$B$6,INDEX(Cenários!$B$15:$BI$15,B$6),INDEX(Cenários!$B$61:$BI$61,B$6),INDEX(Cenários!$B$107:$BI$107,B$6)) -> 90 | C9: =CHOOSE(Premissas!$B$6,INDEX(Cenários!$B$15:$BI$15,C$6),INDEX(Cenários!$B$61:$BI$61,C$6),INDEX(Cenários!$B$107:$BI$107,C$6)) -> 4527 | D9: =CHOOSE(Premissas!$B$6,INDEX(Cenários!$B$15:$BI$15,D$6),INDEX(Cenários!$B$61:$BI$61,D$6),INDEX(Cenários!$B$107:$BI$107,D$6)) -> 7009 | E9: =CHOOSE(Premissas!$B$6,INDEX(Cenários!$B$15:$BI$15,E$6),INDEX(Cenários!$B$61:$BI$61,E$6),INDEX(Cenários!$B$107:$BI$107,E$6)) -> 37675 | G9: É por este número que todo o custo fixo é dividido. É a variável que manda no preço.
A10: Receita de assinaturas no mês | B10: =CHOOSE(Premissas!$B$6,INDEX(Cenários!$B$23:$BI$23,B$6),INDEX(Cenários!$B$69:$BI$69,B$6),INDEX(Cenários!$B$115:$BI$115,B$6)) -> 7191 | C10: =CHOOSE(Premissas!$B$6,INDEX(Cenários!$B$23:$BI$23,C$6),INDEX(Cenários!$B$69:$BI$69,C$6),INDEX(Cenários!$B$115:$BI$115,C$6)) -> 361707.3 | D10: =CHOOSE(Premissas!$B$6,INDEX(Cenários!$B$23:$BI$23,D$6),INDEX(Cenários!$B$69:$BI$69,D$6),INDEX(Cenários!$B$115:$BI$115,D$6)) -> 560019.1 | E10: =CHOOSE(Premissas!$B$6,INDEX(Cenários!$B$23:$BI$23,E$6),INDEX(Cenários!$B$69:$BI$69,E$6),INDEX(Cenários!$B$115:$BI$115,E$6)) -> 3247283.6
A11: Receita média por assinante hoje (ARPPU) | B11: =IFERROR(CHOOSE(Premissas!$B$6,INDEX(Cenários!$B$23:$BI$23,B$6),INDEX(Cenários!$B$69:$BI$69,B$6),INDEX(Cenários!$B$115:$BI$115,B$6))/B$9,0) -> 79.9 | C11: =IFERROR(CHOOSE(Premissas!$B$6,INDEX(Cenários!$B$23:$BI$23,C$6),INDEX(Cenários!$B$69:$BI$69,C$6),INDEX(Cenários!$B$115:$BI$115,C$6))/C$9,0) -> 79.9 | D11: =IFERROR(CHOOSE(Premissas!$B$6,INDEX(Cenários!$B$23:$BI$23,D$6),INDEX(Cenários!$B$69:$BI$69,D$6),INDEX(Cenários!$B$115:$BI$115,D$6))/D$9,0) -> 79.9 | E11: =IFERROR(CHOOSE(Premissas!$B$6,INDEX(Cenários!$B$23:$BI$23,E$6),INDEX(Cenários!$B$69:$BI$69,E$6),INDEX(Cenários!$B$115:$BI$115,E$6))/E$9,0) -> 86.192 | G11: Média do que cada assinante paga, considerando o mix de planos daquele mês.
A13: 2. CUSTO VARIÁVEL — o que cada assinante a mais custa (R$ por assinante/mês)
A14: Nuvem — do próprio assinante | B14: =INDEX(Premissas!$C$93:$G$93,INDEX(Cenários!$B$7:$BI$7,B$6)) -> 32 | C14: =INDEX(Premissas!$C$93:$G$93,INDEX(Cenários!$B$7:$BI$7,C$6)) -> 31.9 | D14: =INDEX(Premissas!$C$93:$G$93,INDEX(Cenários!$B$7:$BI$7,D$6)) -> 31.9 | E14: =INDEX(Premissas!$C$93:$G$93,INDEX(Cenários!$B$7:$BI$7,E$6)) -> 31.9 | G14: Premissas, seção 6: 'Nuvem — custo variável por usuário PAGANTE'. É o maior item variável e por isso o mais sensível: cada real aqui pede cerca de R$ 1,39 de preço.
A15: Nuvem — rateio dos usuários do plano gratuito | B15: =IFERROR((CHOOSE(Premissas!$B$6,INDEX(Cenários!$B$13:$BI$13,B$6),INDEX(Cenários!$B$59:$BI$59,B$6),INDEX(Cenários!$B$105:$BI$105,B$6))-B$9)*INDEX(Premissas!$C$94:$G$94,INDEX(Cenários!$B$7:$BI$7,B$6))/B$9,0) -> 4.0022222 | C15: =IFERROR((CHOOSE(Premissas!$B$6,INDEX(Cenários!$B$13:$BI$13,C$6),INDEX(Cenários!$B$59:$BI$59,C$6),INDEX(Cenários!$B$105:$BI$105,C$6))-C$9)*INDEX(Premissas!$C$94:$G$94,INDEX(Cenários!$B$7:$BI$7,C$6))/C$9,0) -> 0.62723017 | D15: =IFERROR((CHOOSE(Premissas!$B$6,INDEX(Cenários!$B$13:$BI$13,D$6),INDEX(Cenários!$B$59:$BI$59,D$6),INDEX(Cenários!$B$105:$BI$105,D$6))-D$9)*INDEX(Premissas!$C$94:$G$94,INDEX(Cenários!$B$7:$BI$7,D$6))/D$9,0) -> 0.62724245 | E15: =IFERROR((CHOOSE(Premissas!$B$6,INDEX(Cenários!$B$13:$BI$13,E$6),INDEX(Cenários!$B$59:$BI$59,E$6),INDEX(Cenários!$B$105:$BI$105,E$6))-E$9)*INDEX(Premissas!$C$94:$G$94,INDEX(Cenários!$B$7:$BI$7,E$6))/E$9,0) -> 0.42924711 | G15: O plano gratuito não paga e consome. Quem assina sustenta quem não assina.
A16: Nuvem — processamento do painel de dados | B16: =IFERROR(CHOOSE(Premissas!$B$6,INDEX(Cenários!$B$19:$BI$19,B$6),INDEX(Cenários!$B$65:$BI$65,B$6),INDEX(Cenários!$B$111:$BI$111,B$6))*Premissas!$B$69/B$9,0) -> 0 | C16: =IFERROR(CHOOSE(Premissas!$B$6,INDEX(Cenários!$B$19:$BI$19,C$6),INDEX(Cenários!$B$65:$BI$65,C$6),INDEX(Cenários!$B$111:$BI$111,C$6))*Premissas!$B$69/C$9,0) -> 1.6180804 | D16: =IFERROR(CHOOSE(Premissas!$B$6,INDEX(Cenários!$B$19:$BI$19,D$6),INDEX(Cenários!$B$65:$BI$65,D$6),INDEX(Cenários!$B$111:$BI$111,D$6))*Premissas!$B$69/D$9,0) -> 1.6181053 | E16: =IFERROR(CHOOSE(Premissas!$B$6,INDEX(Cenários!$B$19:$BI$19,E$6),INDEX(Cenários!$B$65:$BI$65,E$6),INDEX(Cenários!$B$111:$BI$111,E$6))*Premissas!$B$69/E$9,0) -> 1.4808242
A17: Suporte ao cliente | B17: =INDEX(Premissas!$C$95:$G$95,INDEX(Cenários!$B$7:$BI$7,B$6)) -> 0.35 | C17: =INDEX(Premissas!$C$95:$G$95,INDEX(Cenários!$B$7:$BI$7,C$6)) -> 0.35 | D17: =INDEX(Premissas!$C$95:$G$95,INDEX(Cenários!$B$7:$BI$7,D$6)) -> 0.35 | E17: =INDEX(Premissas!$C$95:$G$95,INDEX(Cenários!$B$7:$BI$7,E$6)) -> 0.25
A18: Marketing — custo de conquistar um assinante (CAC) | B18: =IFERROR((1-INDEX(Premissas!$C$59:$G$59,INDEX(Cenários!$B$7:$BI$7,B$6)))*CHOOSE(Premissas!$B$6,INDEX(Premissas!$C$56:$G$56,INDEX(Cenários!$B$7:$BI$7,B$6)),INDEX(Premissas!$C$57:$G$57,INDEX(Cenários!$B$7:$BI$7,B$6)),INDEX(Premissas!$C$58:$G$58,INDEX(Cenários!$B$7:$BI$7,B$6)))/CHOOSE(Premissas!$B$6,INDEX(Premissas!$C$52:$G$52,INDEX(Cenários!$B$7:$BI$7,B$6)),INDEX(Premissas!$C$53:$G$53,INDEX(Cenários!$B$7:$BI$7,B$6)),INDEX(Premissas!$C$54:$G$54,INDEX(Cenários!$B$7:$BI$7,B$6))),0) -> 58.333333 | C18: =IFERROR((1-INDEX(Premissas!$C$59:$G$59,INDEX(Cenários!$B$7:$BI$7,C$6)))*CHOOSE(Premissas!$B$6,INDEX(Premissas!$C$56:$G$56,INDEX(Cenários!$B$7:$BI$7,C$6)),INDEX(Premissas!$C$57:$G$57,INDEX(Cenários!$B$7:$BI$7,C$6)),INDEX(Premissas!$C$58:$G$58,INDEX(Cenários!$B$7:$BI$7,C$6)))/CHOOSE(Premissas!$B$6,INDEX(Premissas!$C$52:$G$52,INDEX(Cenários!$B$7:$BI$7,C$6)),INDEX(Premissas!$C$53:$G$53,INDEX(Cenários!$B$7:$BI$7,C$6)),INDEX(Premissas!$C$54:$G$54,INDEX(Cenários!$B$7:$BI$7,C$6))),0) -> 63.268608 | D18: =IFERROR((1-INDEX(Premissas!$C$59:$G$59,INDEX(Cenários!$B$7:$BI$7,D$6)))*CHOOSE(Premissas!$B$6,INDEX(Premissas!$C$56:$G$56,INDEX(Cenários!$B$7:$BI$7,D$6)),INDEX(Premissas!$C$57:$G$57,INDEX(Cenários!$B$7:$BI$7,D$6)),INDEX(Premissas!$C$58:$G$58,INDEX(Cenários!$B$7:$BI$7,D$6)))/CHOOSE(Premissas!$B$6,INDEX(Premissas!$C$52:$G$52,INDEX(Cenários!$B$7:$BI$7,D$6)),INDEX(Premissas!$C$53:$G$53,INDEX(Cenários!$B$7:$BI$7,D$6)),INDEX(Premissas!$C$54:$G$54,INDEX(Cenários!$B$7:$BI$7,D$6))),0) -> 63.268608 | E18: =IFERROR((1-INDEX(Premissas!$C$59:$G$59,INDEX(Cenários!$B$7:$BI$7,E$6)))*CHOOSE(Premissas!$B$6,INDEX(Premissas!$C$56:$G$56,INDEX(Cenários!$B$7:$BI$7,E$6)),INDEX(Premissas!$C$57:$G$57,INDEX(Cenários!$B$7:$BI$7,E$6)),INDEX(Premissas!$C$58:$G$58,INDEX(Cenários!$B$7:$BI$7,E$6)))/CHOOSE(Premissas!$B$6,INDEX(Premissas!$C$52:$G$52,INDEX(Cenários!$B$7:$BI$7,E$6)),INDEX(Premissas!$C$53:$G$53,INDEX(Cenários!$B$7:$BI$7,E$6)),INDEX(Premissas!$C$54:$G$54,INDEX(Cenários!$B$7:$BI$7,E$6))),0) -> 77.69847 | G18: Gasto para trazer um ASSINANTE: o CAC por usuário captado, dividido pela taxa de conversão do ano. Não é custo mensal — é de uma vez só, na entrada.
A19: Marketing — o CAC diluído na vida do assinante | B19: =B18*CHOOSE(Premissas!$B$6,INDEX(Premissas!$C$48:$G$48,INDEX(Cenários!$B$7:$BI$7,B$6)),INDEX(Premissas!$C$49:$G$49,INDEX(Cenários!$B$7:$BI$7,B$6)),INDEX(Premissas!$C$50:$G$50,INDEX(Cenários!$B$7:$BI$7,B$6))) -> 4.6666667 | C19: =C18*CHOOSE(Premissas!$B$6,INDEX(Premissas!$C$48:$G$48,INDEX(Cenários!$B$7:$BI$7,C$6)),INDEX(Premissas!$C$49:$G$49,INDEX(Cenários!$B$7:$BI$7,C$6)),INDEX(Premissas!$C$50:$G$50,INDEX(Cenários!$B$7:$BI$7,C$6))) -> 4.7577994 | D19: =D18*CHOOSE(Premissas!$B$6,INDEX(Premissas!$C$48:$G$48,INDEX(Cenários!$B$7:$BI$7,D$6)),INDEX(Premissas!$C$49:$G$49,INDEX(Cenários!$B$7:$BI$7,D$6)),INDEX(Premissas!$C$50:$G$50,INDEX(Cenários!$B$7:$BI$7,D$6))) -> 4.7577994 | E19: =E18*CHOOSE(Premissas!$B$6,INDEX(Premissas!$C$48:$G$48,INDEX(Cenários!$B$7:$BI$7,E$6)),INDEX(Premissas!$C$49:$G$49,INDEX(Cenários!$B$7:$BI$7,E$6)),INDEX(Premissas!$C$50:$G$50,INDEX(Cenários!$B$7:$BI$7,E$6))) -> 4.85304 | G19: Vida esperada do assinante = 1 ÷ churn. Multiplicar o CAC pelo churn é espalhá-lo por essa vida — é assim que ele entra num preço mensal.
A20: (=) CUSTO VARIÁVEL POR ASSINANTE | B20: =B14+B15+B16+B17+B19 -> 41.018889 | C20: =C14+C15+C16+C17+C19 -> 39.25311 | D20: =D14+D15+D16+D17+D19 -> 39.253147 | E20: =E14+E15+E16+E17+E19 -> 38.913111
A22: 3. CUSTO FIXO — o que a empresa gasta mesmo sem um assinante a mais (R$ no mês)
A23: Pessoas — equipe PJ, CLT e pró-labore | B23: =-(INDEX('Análise Fluxo'!$B$18:$BI$18,B$6)+INDEX('Análise Fluxo'!$B$19:$BI$19,B$6)+INDEX('Análise Fluxo'!$B$20:$BI$20,B$6)) -> 0 | C23: =-(INDEX('Análise Fluxo'!$B$18:$BI$18,C$6)+INDEX('Análise Fluxo'!$B$19:$BI$19,C$6)+INDEX('Análise Fluxo'!$B$20:$BI$20,C$6)) -> 42500 | D23: =-(INDEX('Análise Fluxo'!$B$18:$BI$18,D$6)+INDEX('Análise Fluxo'!$B$19:$BI$19,D$6)+INDEX('Análise Fluxo'!$B$20:$BI$20,D$6)) -> 42500 | E23: =-(INDEX('Análise Fluxo'!$B$18:$BI$18,E$6)+INDEX('Análise Fluxo'!$B$19:$BI$19,E$6)+INDEX('Análise Fluxo'!$B$20:$BI$20,E$6)) -> 374300 | G23: Da aba Pessoas, linha a linha. É o maior custo fixo em todos os meses.
A24: Nuvem — parcela fixa (ambiente, licenças, banco de dados) | B24: =IF(B7>=Premissas!$B$91,INDEX(Premissas!$C$92:$G$92,INDEX(Cenários!$B$7:$BI$7,B$6)),0) -> 600 | C24: =IF(C7>=Premissas!$B$91,INDEX(Premissas!$C$92:$G$92,INDEX(Cenários!$B$7:$BI$7,C$6)),0) -> 2500 | D24: =IF(D7>=Premissas!$B$91,INDEX(Premissas!$C$92:$G$92,INDEX(Cenários!$B$7:$BI$7,D$6)),0) -> 2500 | E24: =IF(E7>=Premissas!$B$91,INDEX(Premissas!$C$92:$G$92,INDEX(Cenários!$B$7:$BI$7,E$6)),0) -> 30000
A25: Marketing recorrente e propaganda de lançamento | B25: =-(INDEX('Análise Fluxo'!$B$22:$BI$22,B$6)+INDEX('Análise Fluxo'!$B$23:$BI$23,B$6)) -> 500 | C25: =-(INDEX('Análise Fluxo'!$B$22:$BI$22,C$6)+INDEX('Análise Fluxo'!$B$23:$BI$23,C$6)) -> 5000 | D25: =-(INDEX('Análise Fluxo'!$B$22:$BI$22,D$6)+INDEX('Análise Fluxo'!$B$23:$BI$23,D$6)) -> 5000 | E25: =-(INDEX('Análise Fluxo'!$B$22:$BI$22,E$6)+INDEX('Análise Fluxo'!$B$23:$BI$23,E$6)) -> 15000
A26: Administrativo — contabilidade, jurídico, ferramentas | B26: =-INDEX('Análise Fluxo'!$B$27:$BI$27,B$6) -> 0 | C26: =-INDEX('Análise Fluxo'!$B$27:$BI$27,C$6) -> 166.66667 | D26: =-INDEX('Análise Fluxo'!$B$27:$BI$27,D$6) -> 166.66667 | E26: =-INDEX('Análise Fluxo'!$B$27:$BI$27,E$6) -> 1666.6667 | G26: Premissas, seção 6. A célula é MENSAL. Hoje está como 2000/12, 5000/12 e assim por diante, o que dá R$ 167 por mês em 2027 — para contabilidade, jurídico e ferramentas de uma empresa no Simples isso é baixo. Vale conferir: só o contador costuma custar entre R$ 300 e R$ 800 por mês.
A27: (=) CUSTO FIXO DO MÊS | B27: =B23+B24+B25+B26 -> 1100 | C27: =C23+C24+C25+C26 -> 50166.667 | D27: =D23+D24+D25+D26 -> 50166.667 | E27: =E23+E24+E25+E26 -> 420966.67
A28: Custo fixo dividido pelos assinantes | B28: =IFERROR(B27/B$9,0) -> 12.222222 | C28: =IFERROR(C27/C$9,0) -> 11.081658 | D28: =IFERROR(D27/D$9,0) -> 7.1574642 | E28: =IFERROR(E27/E$9,0) -> 11.173634 | G28: É esta linha que faz o preço parecer impossível no lançamento e razoável depois. Não é o custo que muda — é o número de pessoas dividindo a conta.
A30: (=) CUSTO TOTAL POR ASSINANTE · variável + fixo rateado | B30: =B20+B28 -> 53.241111 | C30: =C20+C28 -> 50.334768 | D30: =D20+D28 -> 46.410611 | E30: =E20+E28 -> 50.086745
A31: ✔ Conferência do custo contra a DRE, sem o marketing (deve ser zero) | B31: =(B14+B15+B16+B17)*B$9+B27+(INDEX('Análise Fluxo'!$B$16:$BI$16,B$6)+INDEX('Análise Fluxo'!$B$17:$BI$17,B$6)+INDEX('Análise Fluxo'!$B$18:$BI$18,B$6)+INDEX('Análise Fluxo'!$B$19:$BI$19,B$6)+INDEX('Análise Fluxo'!$B$20:$BI$20,B$6)+INDEX('Análise Fluxo'!$B$22:$BI$22,B$6)+INDEX('Análise Fluxo'!$B$23:$BI$23,B$6)+INDEX('Análise Fluxo'!$B$27:$BI$27,B$6)) -> 0 | C31: =(C14+C15+C16+C17)*C$9+C27+(INDEX('Análise Fluxo'!$B$16:$BI$16,C$6)+INDEX('Análise Fluxo'!$B$17:$BI$17,C$6)+INDEX('Análise Fluxo'!$B$18:$BI$18,C$6)+INDEX('Análise Fluxo'!$B$19:$BI$19,C$6)+INDEX('Análise Fluxo'!$B$20:$BI$20,C$6)+INDEX('Análise Fluxo'!$B$22:$BI$22,C$6)+INDEX('Análise Fluxo'!$B$23:$BI$23,C$6)+INDEX('Análise Fluxo'!$B$27:$BI$27,C$6)) -> 0 | D31: =(D14+D15+D16+D17)*D$9+D27+(INDEX('Análise Fluxo'!$B$16:$BI$16,D$6)+INDEX('Análise Fluxo'!$B$17:$BI$17,D$6)+INDEX('Análise Fluxo'!$B$18:$BI$18,D$6)+INDEX('Análise Fluxo'!$B$19:$BI$19,D$6)+INDEX('Análise Fluxo'!$B$20:$BI$20,D$6)+INDEX('Análise Fluxo'!$B$22:$BI$22,D$6)+INDEX('Análise Fluxo'!$B$23:$BI$23,D$6)+INDEX('Análise Fluxo'!$B$27:$BI$27,D$6)) -> 0 | E31: =(E14+E15+E16+E17)*E$9+E27+(INDEX('Análise Fluxo'!$B$16:$BI$16,E$6)+INDEX('Análise Fluxo'!$B$17:$BI$17,E$6)+INDEX('Análise Fluxo'!$B$18:$BI$18,E$6)+INDEX('Análise Fluxo'!$B$19:$BI$19,E$6)+INDEX('Análise Fluxo'!$B$20:$BI$20,E$6)+INDEX('Análise Fluxo'!$B$22:$BI$22,E$6)+INDEX('Análise Fluxo'!$B$23:$BI$23,E$6)+INDEX('Análise Fluxo'!$B$27:$BI$27,E$6)) -> 0 | G31: Compara nuvem, suporte, pessoas, marketing recorrente e administrativo com o que a DRE gasta nos mesmos itens. O marketing de AQUISIÇÃO fica fora de propósito: aqui ele entra diluído na vida do assinante, na DRE entra no mês do desembolso.
A32: ✔ Conferência da nuvem: esta aba × assinantes − nuvem da DRE (deve ser zero) | B32: =(B14+B15+B16)*B$9+B24+INDEX('Análise Fluxo'!$B$16:$BI$16,B$6) -> 0 | C32: =(C14+C15+C16)*C$9+C24+INDEX('Análise Fluxo'!$B$16:$BI$16,C$6) -> 0 | D32: =(D14+D15+D16)*D$9+D24+INDEX('Análise Fluxo'!$B$16:$BI$16,D$6) -> 0 | E32: =(E14+E15+E16)*E$9+E24+INDEX('Análise Fluxo'!$B$16:$BI$16,E$6) -> 0 | G32: Prova que a decomposição da nuvem nesta aba é a mesma conta que a DRE usa. Se der diferente de zero, não confie no preço desta aba.
A34: 4. O QUE SAI DE CADA REAL COBRADO — antes de sobrar para pagar o custo
A35: (−) Imposto sobre a receita (Simples / Lucro Presumido) | B35: =CHOOSE(Premissas!$B$6,INDEX(Cenários!$B$30:$BI$30,B$6),INDEX(Cenários!$B$76:$BI$76,B$6),INDEX(Cenários!$B$122:$BI$122,B$6)) -> 0.155 | C35: =CHOOSE(Premissas!$B$6,INDEX(Cenários!$B$30:$BI$30,C$6),INDEX(Cenários!$B$76:$BI$76,C$6),INDEX(Cenários!$B$122:$BI$122,C$6)) -> 0.18524785 | D35: =CHOOSE(Premissas!$B$6,INDEX(Cenários!$B$30:$BI$30,D$6),INDEX(Cenários!$B$76:$BI$76,D$6),INDEX(Cenários!$B$122:$BI$122,D$6)) -> 0.15869359 | E35: =CHOOSE(Premissas!$B$6,INDEX(Cenários!$B$30:$BI$30,E$6),INDEX(Cenários!$B$76:$BI$76,E$6),INDEX(Cenários!$B$122:$BI$122,E$6)) -> 0.1633 | G35: Alíquota efetiva do mês, da tabela do Simples. Sobe conforme o faturamento dos últimos 12 meses.
A36: (−) Comissão da loja de aplicativos (Apple / Google) | B36: =Premissas!$B$62*INDEX(Premissas!$C$63:$G$63,INDEX(Cenários!$B$7:$BI$7,B$6)) -> 0.1275 | C36: =Premissas!$B$62*INDEX(Premissas!$C$63:$G$63,INDEX(Cenários!$B$7:$BI$7,C$6)) -> 0.12 | D36: =Premissas!$B$62*INDEX(Premissas!$C$63:$G$63,INDEX(Cenários!$B$7:$BI$7,D$6)) -> 0.12 | E36: =Premissas!$B$62*INDEX(Premissas!$C$63:$G$63,INDEX(Cenários!$B$7:$BI$7,E$6)) -> 0.105 | G36: 15% sobre a parte cobrada dentro do app. Cobrar fora do app evita a comissão, mas o aplicativo precisa estar nas lojas para existir.
A37: (−) Taxa do meio de pagamento (cartão, PIX, boleto) | B37: =Premissas!$B$64*(1-INDEX(Premissas!$C$63:$G$63,INDEX(Cenários!$B$7:$BI$7,B$6))) -> 0.00675 | C37: =Premissas!$B$64*(1-INDEX(Premissas!$C$63:$G$63,INDEX(Cenários!$B$7:$BI$7,C$6))) -> 0.009 | D37: =Premissas!$B$64*(1-INDEX(Premissas!$C$63:$G$63,INDEX(Cenários!$B$7:$BI$7,D$6))) -> 0.009 | E37: =Premissas!$B$64*(1-INDEX(Premissas!$C$63:$G$63,INDEX(Cenários!$B$7:$BI$7,E$6))) -> 0.0135
A38: (=) Total que sai do preço | B38: =B35+B36+B37 -> 0.28925 | C38: =C35+C36+C37 -> 0.31424785 | D38: =D35+D36+D37 -> 0.28769359 | E38: =E35+E36+E37 -> 0.2818
A39: (=) FICA PARA A EMPRESA, de cada R$ 1 cobrado | B39: =1-B38 -> 0.71075 | C39: =1-C38 -> 0.68575215 | D39: =1-D38 -> 0.71230641 | E39: =1-E38 -> 0.7182 | G39: Cobrar R$ 1 não é receber R$ 1. Todo preço desta aba é o custo dividido por esta porcentagem — é o que faz o preço subir mais do que o custo.
A41: 5. O PREÇO QUE O CUSTO EXIGE
A42: Margem EBITDA desejada | B42: =0.2 -> 0.2 | C42: =$B$42 -> 0.2 | D42: =$B$42 -> 0.2 | E42: =$B$42 -> 0.2 | G42: Digite a margem que você quer que sobre depois de pagar tudo. Com 0%, o preço apenas empata.
A43: Preço médio por assinante que apenas EMPATA (margem zero) | B43: =IFERROR(B30/B39,0) -> 74.908352 | C43: =IFERROR(C30/C39,0) -> 73.400818 | D43: =IFERROR(D30/D39,0) -> 65.155403 | E43: =IFERROR(E30/E39,0) -> 69.739272
A44: Preço médio por assinante COM a margem desejada | B44: =IFERROR(B30/(B39*(1-B42)),0) -> 93.63544 | C44: =IFERROR(C30/(C39*(1-C42)),0) -> 91.751022 | D44: =IFERROR(D30/(D39*(1-D42)),0) -> 81.444254 | E44: =IFERROR(E30/(E39*(1-E42)),0) -> 87.17409 | G44: É a ARPPU necessária: a média ponderada dos três planos. Abaixo, traduzida para o preço de cada plano.
A45: Receita média por assinante hoje (para comparar) | B45: =B11 -> 79.9 | C45: =C11 -> 79.9 | D45: =D11 -> 79.9 | E45: =E11 -> 86.192
A46: Margem EBITDA que o preço de hoje entrega | B46: =IFERROR((B11*B39-B30)/(B11*B39),0) -> 0.062473693 | C46: =IFERROR((C11*C39-C30)/(C11*C39),0) -> 0.081341457 | D46: =IFERROR((D11*D39-D30)/(D11*D39),0) -> 0.18453813 | E46: =IFERROR((E11*E39-E30)/(E11*E39),0) -> 0.19088463 | G46: Difere da margem EBITDA da DRE de propósito: aqui o marketing de aquisição entra diluído na vida do assinante, e marketplace e B2B não entram. É a margem da ASSINATURA, não a da empresa.
...

Sheet Premissas
A2: AZUL = você digita · fundo AMARELO = premissa-chave · PRETO = calculado pelo modelo. Células com marca vermelha no canto têm a fonte do número em comentário. O quadro de pessoas fica na aba Pessoas.
A4: 1. CONTROLES DO MODELO
A5: Ano → | B5: Evolução a.a. | C5: 2026 | D5: 2027 | E5: 2028 | F5: 2029 | G5: 2030
A6: Cenário ativo (1 = Conservador · 2 = Provável · 3 = Agressivo) | B6: 2 | D6: Troque este número e a planilha inteira recalcula no cenário escolhido.
A7: Cenário ativo — nome | B7: =CHOOSE($B$6,"CONSERVADOR","PROVÁVEL","AGRESSIVO") -> PROVÁVEL
A8: Considerar o plano de contratações? (1 = Sim · 0 = Não) | B8: 1 | D8: Com 0, o modelo considera só quem já está contratado (equipe do MVP).
A10: LANÇAMENTO DO APP
A11: Ano de lançamento | B11: 2026
A12: Mês de lançamento (1 = janeiro … 12 = dezembro) | B12: 12 | D12: Brief: app majoritariamente pronto em outubro.
A13: Data de lançamento (calculada) | B13: =DATE($B$11,$B$12,1) -> 46357
A14: Mês nº do lançamento na linha do tempo | B14: =($B$11-2026)*12+$B$12 -> 12
A15: Rampa de maturação da conversão (meses) | B15: 6 | D15: É isto que torna 2026 mais tímido. Coloque 1 para converter no patamar cheio desde o primeiro mês.
A17: PARÂMETROS FINANCEIROS
A18: TMA — taxa mínima de atratividade (a.a.) | B18: 0.25 | D18: Original usava 16% a.a.; 25% reflete risco de startup pré-receita.
A19: TMA equivalente mensal | B19: =(1+$B$18)^(1/12)-1 -> 0.018769265
A20: Payback desejado (meses) — critério de decisão | B20: 36 | D20: Critério Go/No-Go.
A22: 2. TRIBUTAÇÃO
A23: Regime (1 = Simples Anexo III · 2 = Simples Anexo V · 3 = Lucro Presumido) | B23: 2 | D23: ⚠ Padrão = 2 (Anexo V). O Fator R do quadro atual fica muito abaixo de 28%, então o Anexo III não está disponível. Veja a conferência na aba Pessoas.
A24: Alíquota Lucro Presumido / acima do teto do Simples | B24: 0.1633 | D24: PIS 0,65 + COFINS 3,00 + ISS 5,00 + IRPJ 4,80 + CSLL 2,88 = 16,33%
A25: Teto do Simples Nacional (RBT12) | B25: 4800000 | D25: LC 123/2006. Acima disso o modelo passa sozinho ao Lucro Presumido.
A27: 3. PREÇOS E MIX DE PLANOS
A28: • São quatro planos, conforme o backlog do produto: Free (gratuito, entra na base de usuários mas não gera receita de assinatura), Essencial, Premium e Família. Os três pagos estão abaixo; o Free é a diferença entre a base ativa e os pagantes, na aba Usuários.
A29: Plano Essencial (R$/mês) · 1 familiar, até 3 cuidadores | B29: 79.9
A30: Plano Premium (R$/mês) · 1 familiar, cuidadores ilimitados | B30: 89.9
A31: Plano Família (R$/mês) · até 4 familiares, cuidadores ilimitados | B31: 109
A32: Reajuste anual de preços (a.a.) | D32: Aplicado a partir de 2027 (IPCA projetado ~4,5%).
A33: Mix de pagantes por plano (% dos assinantes)
A34: Plano Essencial | C34: 1 | D34: 1 | E34: 0.68 | F34: 0.64 | G34: 0.6 | I34: Efeito compromisso (Simonson & Tversky, 1992) + padrão de assinatura B2C de ticket baixo.
A35: Plano Premium | C35: 0 | D35: 0 | E35: 0.24 | F35: 0.26 | G35: 0.28 | I35: Plano-ponte: cresce conforme o Premium ganha valor percebido.
A36: Plano Família | C36: 0 | D36: 0 | E36: 0.08 | F36: 0.1 | G36: 0.12 | I36: Fatia menor mas crescente — ancoragem de preço que sustenta o Intermediário.
A37: Verificação do mix (deve somar 100%) | C37: =SUM(C34:C36) -> 1 | D37: =SUM(D34:D36) -> 1 | E37: =SUM(E34:E36) -> 1 | F37: =SUM(F34:F36) -> 1 | G37: =SUM(G34:G36) -> 1
A38: ARPPU implícita (receita média por assinante pagante) | C38: =(C34*$B$29+C35*$B$30+C36*$B$31)*(1+$B$32)^(C$5-2026) -> 79.9 | D38: =(D34*$B$29+D35*$B$30+D36*$B$31)*(1+$B$32)^(D$5-2026) -> 79.9 | E38: =(E34*$B$29+E35*$B$30+E36*$B$31)*(1+$B$32)^(E$5-2026) -> 84.628 | F38: =(F34*$B$29+F35*$B$30+F36*$B$31)*(1+$B$32)^(F$5-2026) -> 85.41 | G38: =(G34*$B$29+G35*$B$30+G36*$B$31)*(1+$B$32)^(G$5-2026) -> 86.192
A40: 4. DRIVERS POR CENÁRIO
A41: • Cada driver tem 3 linhas — Conservador, Provável e Agressivo. O modelo usa a do cenário ativo.
A42: • Digite o patamar de 2026 na coluna C e a taxa de evolução anual na coluna B: 2027 a 2030 são calculados sozinhos. Quer um ano específico fora da curva? Digite por cima — a célula vira entrada manual e os anos seguintes continuam a partir dela.
A43: Novos usuários captados por mês (média do ano)
A44: Conservador | B44: 0.4 | C44: 10860 | D44: =C44*(1+$B44) -> 15204 | E44: =D44*(1+$B44) -> 21285.6 | F44: =E44*(1+$B44) -> 29799.84 | G44: =F44*(1+$B44) -> 41719.776
A45: Provável | B45: 0.5 | C45: 18100 | D45: =C45*(1+$B45) -> 27150 | E45: =D45*(1+$B45) -> 40725 | F45: =E45*(1+$B45) -> 61087.5 | G45: =F45*(1+$B45) -> 91631.25 | I45: Calibrado para a meta de ~50.000 usuários em dez/2026.
A46: Agressivo | B46: 0.6 | C46: 25340 | D46: =C46*(1+$B46) -> 40544 | E46: =D46*(1+$B46) -> 64870.4 | F46: =E46*(1+$B46) -> 103792.64 | G46: =F46*(1+$B46) -> 166068.22
A47: Churn mensal da base de usuários
...

Sheet DRE Projetada
A1: DRE PROJETADA — DEMONSTRAÇÃO DO RESULTADO DO EXERCÍCIO
A2: =" Cenário ativo: "&Premissas!B7 -> Cenário ativo: PROVÁVEL
A4: Linha do tempo | B4: 46023 | C4: 46054 | D4: 46082 | E4: 46113 | F4: 46143 | G4: 46174 | H4: 46204 | I4: 46235 | J4: 46266 | K4: 46296 | L4: 46327 | M4: 46357 | N4: 46388 | O4: 46419 | P4: 46447 | Q4: 46478 | R4: 46508 | S4: 46539 | T4: 46569 | U4: 46600 | V4: 46631 | W4: 46661 | X4: 46692 | Y4: 46722 | Z4: 46753 | AA4: 46784 | AB4: 46813 | AC4: 46844 | AD4: 46874 | AE4: 46905 | AF4: 46935 | AG4: 46966 | AH4: 46997 | AI4: 47027 | AJ4: 47058 | AK4: 47088 | AL4: 47119 | AM4: 47150 | AN4: 47178 | AO4: 47209 | AP4: 47239 | AQ4: 47270 | AR4: 47300 | AS4: 47331 | AT4: 47362 | AU4: 47392 | AV4: 47423 | AW4: 47453 | AX4: 47484 | AY4: 47515 | AZ4: 47543 | BA4: 47574 | BB4: 47604 | BC4: 47635 | BD4: 47665 | BE4: 47696 | BF4: 47727 | BG4: 47757 | BH4: 47788 | BI4: 47818 | BJ4: TOTAL | BK4: % / Nota
A5: Mês nº | B5: 1 | C5: 2 | D5: 3 | E5: 4 | F5: 5 | G5: 6 | H5: 7 | I5: 8 | J5: 9 | K5: 10 | L5: 11 | M5: 12 | N5: 13 | O5: 14 | P5: 15 | Q5: 16 | R5: 17 | S5: 18 | T5: 19 | U5: 20 | V5: 21 | W5: 22 | X5: 23 | Y5: 24 | Z5: 25 | AA5: 26 | AB5: 27 | AC5: 28 | AD5: 29 | AE5: 30 | AF5: 31 | AG5: 32 | AH5: 33 | AI5: 34 | AJ5: 35 | AK5: 36 | AL5: 37 | AM5: 38 | AN5: 39 | AO5: 40 | AP5: 41 | AQ5: 42 | AR5: 43 | AS5: 44 | AT5: 45 | AU5: 46 | AV5: 47 | AW5: 48 | AX5: 49 | AY5: 50 | AZ5: 51 | BA5: 52 | BB5: 53 | BC5: 54 | BD5: 55 | BE5: 56 | BF5: 57 | BG5: 58 | BH5: 59 | BI5: 60
A6: Ano | B6: =YEAR(B4) -> 2026 | C6: =YEAR(C4) -> 2026 | D6: =YEAR(D4) -> 2026 | E6: =YEAR(E4) -> 2026 | F6: =YEAR(F4) -> 2026 | G6: =YEAR(G4) -> 2026 | H6: =YEAR(H4) -> 2026 | I6: =YEAR(I4) -> 2026 | ... BI6: =YEAR(BI4) -> 2030
A7: Índice do ano (auxiliar) | B7: =MATCH(B6,Premissas!$C$5:$G$5,0) -> 1 | C7: =MATCH(C6,Premissas!$C$5:$G$5,0) -> 1 | D7: =MATCH(D6,Premissas!$C$5:$G$5,0) -> 1 | E7: =MATCH(E6,Premissas!$C$5:$G$5,0) -> 1 | F7: =MATCH(F6,Premissas!$C$5:$G$5,0) -> 1 | G7: =MATCH(G6,Premissas!$C$5:$G$5,0) -> 1 | H7: =MATCH(H6,Premissas!$C$5:$G$5,0) -> 1 | I7: =MATCH(I6,Premissas!$C$5:$G$5,0) -> 1 | ... BI7: =MATCH(BI6,Premissas!$C$5:$G$5,0) -> 5
A8: RECEITA OPERACIONAL BRUTA
A9: Assinaturas — Plano Essencial | B9: =CHOOSE(Premissas!$B$6,Cenários!B20,Cenários!B66,Cenários!B112) -> 0 | C9: =CHOOSE(Premissas!$B$6,Cenários!C20,Cenários!C66,Cenários!C112) -> 0 | D9: =CHOOSE(Premissas!$B$6,Cenários!D20,Cenários!D66,Cenários!D112) -> 0 | E9: =CHOOSE(Premissas!$B$6,Cenários!E20,Cenários!E66,Cenários!E112) -> 0 | F9: =CHOOSE(Premissas!$B$6,Cenários!F20,Cenários!F66,Cenários!F112) -> 0 | G9: =CHOOSE(Premissas!$B$6,Cenários!G20,Cenários!G66,Cenários!G112) -> 0 | H9: =CHOOSE(Premissas!$B$6,Cenários!H20,Cenários!H66,Cenários!H112) -> 0 | I9: =CHOOSE(Premissas!$B$6,Cenários!I20,Cenários!I66,Cenários!I112) -> 0 | ... BI9: =CHOOSE(Premissas!$B$6,Cenários!BI20,Cenários!BI66,Cenários!BI112) -> 1806139.5 | BJ9: =SUM(B9:BI9) -> 41960684
A10: Assinaturas — Plano Premium | B10: =CHOOSE(Premissas!$B$6,Cenários!B21,Cenários!B67,Cenários!B113) -> 0 | C10: =CHOOSE(Premissas!$B$6,Cenários!C21,Cenários!C67,Cenários!C113) -> 0 | D10: =CHOOSE(Premissas!$B$6,Cenários!D21,Cenários!D67,Cenários!D113) -> 0 | E10: =CHOOSE(Premissas!$B$6,Cenários!E21,Cenários!E67,Cenários!E113) -> 0 | F10: =CHOOSE(Premissas!$B$6,Cenários!F21,Cenários!F67,Cenários!F113) -> 0 | G10: =CHOOSE(Premissas!$B$6,Cenários!G21,Cenários!G67,Cenários!G113) -> 0 | H10: =CHOOSE(Premissas!$B$6,Cenários!H21,Cenários!H67,Cenários!H113) -> 0 | I10: =CHOOSE(Premissas!$B$6,Cenários!I21,Cenários!I67,Cenários!I113) -> 0 | ... BI10: =CHOOSE(Premissas!$B$6,Cenários!BI21,Cenários!BI67,Cenários!BI113) -> 948355.1 | BJ10: =SUM(B10:BI10) -> 18131032
A11: Assinaturas — Plano Família | B11: =CHOOSE(Premissas!$B$6,Cenários!B22,Cenários!B68,Cenários!B114) -> 0 | C11: =CHOOSE(Premissas!$B$6,Cenários!C22,Cenários!C68,Cenários!C114) -> 0 | D11: =CHOOSE(Premissas!$B$6,Cenários!D22,Cenários!D68,Cenários!D114) -> 0 | E11: =CHOOSE(Premissas!$B$6,Cenários!E22,Cenários!E68,Cenários!E114) -> 0 | F11: =CHOOSE(Premissas!$B$6,Cenários!F22,Cenários!F68,Cenários!F114) -> 0 | G11: =CHOOSE(Premissas!$B$6,Cenários!G22,Cenários!G68,Cenários!G114) -> 0 | H11: =CHOOSE(Premissas!$B$6,Cenários!H22,Cenários!H68,Cenários!H114) -> 0 | I11: =CHOOSE(Premissas!$B$6,Cenários!I22,Cenários!I68,Cenários!I114) -> 0 | ... BI11: =CHOOSE(Premissas!$B$6,Cenários!BI22,Cenários!BI68,Cenários!BI114) -> 492789 | BJ11: =SUM(B11:BI11) -> 8792594
A12: Marketplace — comissões | B12: =CHOOSE(Premissas!$B$6,Cenários!B24,Cenários!B70,Cenários!B116) -> 0 | C12: =CHOOSE(Premissas!$B$6,Cenários!C24,Cenários!C70,Cenários!C116) -> 0 | D12: =CHOOSE(Premissas!$B$6,Cenários!D24,Cenários!D70,Cenários!D116) -> 0 | E12: =CHOOSE(Premissas!$B$6,Cenários!E24,Cenários!E70,Cenários!E116) -> 0 | F12: =CHOOSE(Premissas!$B$6,Cenários!F24,Cenários!F70,Cenários!F116) -> 0 | G12: =CHOOSE(Premissas!$B$6,Cenários!G24,Cenários!G70,Cenários!G116) -> 0 | H12: =CHOOSE(Premissas!$B$6,Cenários!H24,Cenários!H70,Cenários!H116) -> 0 | I12: =CHOOSE(Premissas!$B$6,Cenários!I24,Cenários!I70,Cenários!I116) -> 0 | ... BI12: =CHOOSE(Premissas!$B$6,Cenários!BI24,Cenários!BI70,Cenários!BI116) -> 195265.12 | BJ12: =SUM(B12:BI12) -> 3470461.5
A13: B2B — parcerias estratégicas | B13: =CHOOSE(Premissas!$B$6,Cenários!B25,Cenários!B71,Cenários!B117) -> 0 | C13: =CHOOSE(Premissas!$B$6,Cenários!C25,Cenários!C71,Cenários!C117) -> 0 | D13: =CHOOSE(Premissas!$B$6,Cenários!D25,Cenários!D71,Cenários!D117) -> 0 | E13: =CHOOSE(Premissas!$B$6,Cenários!E25,Cenários!E71,Cenários!E117) -> 0 | F13: =CHOOSE(Premissas!$B$6,Cenários!F25,Cenários!F71,Cenários!F117) -> 0 | G13: =CHOOSE(Premissas!$B$6,Cenários!G25,Cenários!G71,Cenários!G117) -> 0 | H13: =CHOOSE(Premissas!$B$6,Cenários!H25,Cenários!H71,Cenários!H117) -> 0 | I13: =CHOOSE(Premissas!$B$6,Cenários!I25,Cenários!I71,Cenários!I117) -> 0 | ... BI13: =CHOOSE(Premissas!$B$6,Cenários!BI25,Cenários!BI71,Cenários!BI117) -> 5000 | BJ13: =SUM(B13:BI13) -> 230000
A14: B2B — venda de dados | B14: =CHOOSE(Premissas!$B$6,Cenários!B26,Cenários!B72,Cenários!B118) -> 0 | C14: =CHOOSE(Premissas!$B$6,Cenários!C26,Cenários!C72,Cenários!C118) -> 0 | D14: =CHOOSE(Premissas!$B$6,Cenários!D26,Cenários!D72,Cenários!D118) -> 0 | E14: =CHOOSE(Premissas!$B$6,Cenários!E26,Cenários!E72,Cenários!E118) -> 0 | F14: =CHOOSE(Premissas!$B$6,Cenários!F26,Cenários!F72,Cenários!F118) -> 0 | G14: =CHOOSE(Premissas!$B$6,Cenários!G26,Cenários!G72,Cenários!G118) -> 0 | H14: =CHOOSE(Premissas!$B$6,Cenários!H26,Cenários!H72,Cenários!H118) -> 0 | I14: =CHOOSE(Premissas!$B$6,Cenários!I26,Cenários!I72,Cenários!I118) -> 0 | ... BI14: =CHOOSE(Premissas!$B$6,Cenários!BI26,Cenários!BI72,Cenários!BI118) -> 5750 | BJ14: =SUM(B14:BI14) -> 246750 | BK14: Contratos da tabela de iniciativas B2B em Premissas, categoria Dados.
A15: B2B — outras iniciativas | B15: =CHOOSE(Premissas!$B$6,Cenários!B27,Cenários!B73,Cenários!B119) -> 0 | C15: =CHOOSE(Premissas!$B$6,Cenários!C27,Cenários!C73,Cenários!C119) -> 0 | D15: =CHOOSE(Premissas!$B$6,Cenários!D27,Cenários!D73,Cenários!D119) -> 0 | E15: =CHOOSE(Premissas!$B$6,Cenários!E27,Cenários!E73,Cenários!E119) -> 0 | F15: =CHOOSE(Premissas!$B$6,Cenários!F27,Cenários!F73,Cenários!F119) -> 0 | G15: =CHOOSE(Premissas!$B$6,Cenários!G27,Cenários!G73,Cenários!G119) -> 0 | H15: =CHOOSE(Premissas!$B$6,Cenários!H27,Cenários!H73,Cenários!H119) -> 0 | I15: =CHOOSE(Premissas!$B$6,Cenários!I27,Cenários!I73,Cenários!I119) -> 0 | ... BI15: =CHOOSE(Premissas!$B$6,Cenários!BI27,Cenários!BI73,Cenários!BI119) -> 0 | BJ15: =SUM(B15:BI15) -> 0
A16: (=) RECEITA BRUTA | B16: =SUM(B9:B15) -> 0 | C16: =SUM(C9:C15) -> 0 | D16: =SUM(D9:D15) -> 0 | E16: =SUM(E9:E15) -> 0 | F16: =SUM(F9:F15) -> 0 | G16: =SUM(G9:G15) -> 0 | H16: =SUM(H9:H15) -> 0 | I16: =SUM(I9:I15) -> 0 | ... BI16: =SUM(BI9:BI15) -> 3453298.7 | BJ16: =SUM(B16:BI16) -> 72831521
A18: DEDUÇÕES DA RECEITA BRUTA
A19: (−) Impostos sobre a receita (Simples / Lucro Presumido) | B19: =CHOOSE(Premissas!$B$6,Cenários!B31,Cenários!B77,Cenários!B123) -> 0 | C19: =CHOOSE(Premissas!$B$6,Cenários!C31,Cenários!C77,Cenários!C123) -> 0 | D19: =CHOOSE(Premissas!$B$6,Cenários!D31,Cenários!D77,Cenários!D123) -> 0 | E19: =CHOOSE(Premissas!$B$6,Cenários!E31,Cenários!E77,Cenários!E123) -> 0 | F19: =CHOOSE(Premissas!$B$6,Cenários!F31,Cenários!F77,Cenários!F123) -> 0 | G19: =CHOOSE(Premissas!$B$6,Cenários!G31,Cenários!G77,Cenários!G123) -> 0 | H19: =CHOOSE(Premissas!$B$6,Cenários!H31,Cenários!H77,Cenários!H123) -> 0 | I19: =CHOOSE(Premissas!$B$6,Cenários!I31,Cenários!I77,Cenários!I123) -> 0 | ... BI19: =CHOOSE(Premissas!$B$6,Cenários!BI31,Cenários!BI77,Cenários!BI123) -> -563923.68 | BJ19: =SUM(B19:BI19) -> -12004991 | BK19: =IFERROR(BJ19/BJ$16,0) -> -0.16483236
A20: (−) Comissão das lojas de aplicativos | B20: =CHOOSE(Premissas!$B$6,Cenários!B32,Cenários!B78,Cenários!B124) -> 0 | C20: =CHOOSE(Premissas!$B$6,Cenários!C32,Cenários!C78,Cenários!C124) -> 0 | D20: =CHOOSE(Premissas!$B$6,Cenários!D32,Cenários!D78,Cenários!D124) -> 0 | E20: =CHOOSE(Premissas!$B$6,Cenários!E32,Cenários!E78,Cenários!E124) -> 0 | F20: =CHOOSE(Premissas!$B$6,Cenários!F32,Cenários!F78,Cenários!F124) -> 0 | G20: =CHOOSE(Premissas!$B$6,Cenários!G32,Cenários!G78,Cenários!G124) -> 0 | H20: =CHOOSE(Premissas!$B$6,Cenários!H32,Cenários!H78,Cenários!H124) -> 0 | I20: =CHOOSE(Premissas!$B$6,Cenários!I32,Cenários!I78,Cenários!I124) -> 0 | ... BI20: =CHOOSE(Premissas!$B$6,Cenários!BI32,Cenários!BI78,Cenários!BI124) -> -340964.78 | BJ20: =SUM(B20:BI20) -> -7439957.6 | BK20: Apple/Google. A maior dedução isolada da receita de assinatura.
A21: (−) Taxas de meios de pagamento | B21: =CHOOSE(Premissas!$B$6,Cenários!B33,Cenários!B79,Cenários!B125) -> 0 | C21: =CHOOSE(Premissas!$B$6,Cenários!C33,Cenários!C79,Cenários!C125) -> 0 | D21: =CHOOSE(Premissas!$B$6,Cenários!D33,Cenários!D79,Cenários!D125) -> 0 | E21: =CHOOSE(Premissas!$B$6,Cenários!E33,Cenários!E79,Cenários!E125) -> 0 | F21: =CHOOSE(Premissas!$B$6,Cenários!F33,Cenários!F79,Cenários!F125) -> 0 | G21: =CHOOSE(Premissas!$B$6,Cenários!G33,Cenários!G79,Cenários!G125) -> 0 | H21: =CHOOSE(Premissas!$B$6,Cenários!H33,Cenários!H79,Cenários!H125) -> 0 | I21: =CHOOSE(Premissas!$B$6,Cenários!I33,Cenários!I79,Cenários!I125) -> 0 | ... BI21: =CHOOSE(Premissas!$B$6,Cenários!BI33,Cenários!BI79,Cenários!BI125) -> -52625.259 | BJ21: =SUM(B21:BI21) -> -1023977.4 | BK21: =IFERROR(BJ21/BJ$16,0) -> -0.014059536
A22: (=) RECEITA OPERACIONAL LÍQUIDA | B22: =B16+SUM(B19:B21) -> 0 | C22: =C16+SUM(C19:C21) -> 0 | D22: =D16+SUM(D19:D21) -> 0 | E22: =E16+SUM(E19:E21) -> 0 | F22: =F16+SUM(F19:F21) -> 0 | G22: =G16+SUM(G19:G21) -> 0 | H22: =H16+SUM(H19:H21) -> 0 | I22: =I16+SUM(I19:I21) -> 0 | ... BI22: =BI16+SUM(BI19:BI21) -> 2495785 | BJ22: =SUM(B22:BI22) -> 52362595 | BK22: =IFERROR(BJ22/BJ$16,0) -> 0.71895512
A24: CUSTO DOS SERVIÇOS PRESTADOS
A25: (−) Infraestrutura e nuvem | B25: =CHOOSE(Premissas!$B$6,Cenários!B35,Cenários!B81,Cenários!B127) -> 0 | C25: =CHOOSE(Premissas!$B$6,Cenários!C35,Cenários!C81,Cenários!C127) -> 0 | D25: =CHOOSE(Premissas!$B$6,Cenários!D35,Cenários!D81,Cenários!D127) -> 0 | E25: =CHOOSE(Premissas!$B$6,Cenários!E35,Cenários!E81,Cenários!E127) -> 0 | F25: =CHOOSE(Premissas!$B$6,Cenários!F35,Cenários!F81,Cenários!F127) -> -600 | G25: =CHOOSE(Premissas!$B$6,Cenários!G35,Cenários!G81,Cenários!G127) -> -600 | H25: =CHOOSE(Premissas!$B$6,Cenários!H35,Cenários!H81,Cenários!H127) -> -600 | I25: =CHOOSE(Premissas!$B$6,Cenários!I35,Cenários!I81,Cenários!I127) -> -600 | ... BI25: =CHOOSE(Premissas!$B$6,Cenários!BI35,Cenários!BI81,Cenários!BI127) -> -1303794.4 | BJ25: =SUM(B25:BI25) -> -28065492 | BK25: =IFERROR(BJ25/BJ$16,0) -> -0.38534816
A26: (−) Suporte ao cliente | B26: =CHOOSE(Premissas!$B$6,Cenários!B36,Cenários!B82,Cenários!B128) -> 0 | C26: =CHOOSE(Premissas!$B$6,Cenários!C36,Cenários!C82,Cenários!C128) -> 0 | D26: =CHOOSE(Premissas!$B$6,Cenários!D36,Cenários!D82,Cenários!D128) -> 0 | E26: =CHOOSE(Premissas!$B$6,Cenários!E36,Cenários!E82,Cenários!E128) -> 0 | F26: =CHOOSE(Premissas!$B$6,Cenários!F36,Cenários!F82,Cenários!F128) -> 0 | G26: =CHOOSE(Premissas!$B$6,Cenários!G36,Cenários!G82,Cenários!G128) -> 0 | H26: =CHOOSE(Premissas!$B$6,Cenários!H36,Cenários!H82,Cenários!H128) -> 0 | I26: =CHOOSE(Premissas!$B$6,Cenários!I36,Cenários!I82,Cenários!I128) -> 0 | ... BI26: =CHOOSE(Premissas!$B$6,Cenários!BI36,Cenários!BI82,Cenários!BI128) -> -9418.75 | BJ26: =SUM(B26:BI26) -> -220784.51 | BK26: =IFERROR(BJ26/BJ$16,0) -> -0.0030314417
A27: (=) LUCRO BRUTO | B27: =B22+B25+B26 -> 0 | C27: =C22+C25+C26 -> 0 | D27: =D22+D25+D26 -> 0 | E27: =E22+E25+E26 -> 0 | F27: =F22+F25+F26 -> -600 | G27: =G22+G25+G26 -> -600 | H27: =H22+H25+H26 -> -600 | I27: =I22+I25+I26 -> -600 | ... BI27: =BI22+BI25+BI26 -> 1182571.8 | BJ27: =SUM(B27:BI27) -> 24076318
A28: Margem bruta (% da receita líquida) | B28: =IFERROR(B27/B22,0) -> 0 | C28: =IFERROR(C27/C22,0) -> 0 | D28: =IFERROR(D27/D22,0) -> 0 | E28: =IFERROR(E27/E22,0) -> 0 | F28: =IFERROR(F27/F22,0) -> 0 | G28: =IFERROR(G27/G22,0) -> 0 | H28: =IFERROR(H27/H22,0) -> 0 | I28: =IFERROR(I27/I22,0) -> 0 | ... BJ28: =IFERROR(BJ27/BJ22,0) -> 0.45979994
A30: DESPESAS OPERACIONAIS
A31: (−) Pessoal — equipe PJ, CLT e pró-labore | B31: ='Análise Fluxo'!B18+'Análise Fluxo'!B19+'Análise Fluxo'!B20 -> 0 | C31: ='Análise Fluxo'!C18+'Análise Fluxo'!C19+'Análise Fluxo'!C20 -> 0 | D31: ='Análise Fluxo'!D18+'Análise Fluxo'!D19+'Análise Fluxo'!D20 -> 0 | E31: ='Análise Fluxo'!E18+'Análise Fluxo'!E19+'Análise Fluxo'!E20 -> 0 | F31: ='Análise Fluxo'!F18+'Análise Fluxo'!F19+'Análise Fluxo'!F20 -> 0 | G31: ='Análise Fluxo'!G18+'Análise Fluxo'!G19+'Análise Fluxo'!G20 -> 0 | H31: ='Análise Fluxo'!H18+'Análise Fluxo'!H19+'Análise Fluxo'!H20 -> 0 | I31: ='Análise Fluxo'!I18+'Análise Fluxo'!I19+'Análise Fluxo'!I20 -> 0 | ... BI31: ='Análise Fluxo'!BI18+'Análise Fluxo'!BI19+'Análise Fluxo'!BI20 -> -374300 | BJ31: =SUM(B31:BI31) -> -9451200 | BK31: =IFERROR(BJ31/BJ$16,0) -> -0.12976799
A32: (−) Marketing e aquisição | B32: ='Análise Fluxo'!B21+'Análise Fluxo'!B22+'Análise Fluxo'!B23 -> 0 | C32: ='Análise Fluxo'!C21+'Análise Fluxo'!C22+'Análise Fluxo'!C23 -> 0 | D32: ='Análise Fluxo'!D21+'Análise Fluxo'!D22+'Análise Fluxo'!D23 -> 0 | E32: ='Análise Fluxo'!E21+'Análise Fluxo'!E22+'Análise Fluxo'!E23 -> 0 | F32: ='Análise Fluxo'!F21+'Análise Fluxo'!F22+'Análise Fluxo'!F23 -> 0 | G32: ='Análise Fluxo'!G21+'Análise Fluxo'!G22+'Análise Fluxo'!G23 -> 0 | H32: ='Análise Fluxo'!H21+'Análise Fluxo'!H22+'Análise Fluxo'!H23 -> 0 | I32: ='Análise Fluxo'!I21+'Análise Fluxo'!I22+'Análise Fluxo'!I23 -> 0 | ... BI32: ='Análise Fluxo'!BI21+'Análise Fluxo'!BI22+'Análise Fluxo'!BI23 -> -255395.44 | BJ32: =SUM(B32:BI32) -> -6813666.2 | BK32: Inclui a propaganda de lançamento, tratada como despesa e não como investimento.
A33: (−) Despesas administrativas | B33: ='Análise Fluxo'!B27 -> 0 | C33: ='Análise Fluxo'!C27 -> 0 | D33: ='Análise Fluxo'!D27 -> 0 | E33: ='Análise Fluxo'!E27 -> 0 | F33: ='Análise Fluxo'!F27 -> 0 | G33: ='Análise Fluxo'!G27 -> 0 | H33: ='Análise Fluxo'!H27 -> 0 | I33: ='Análise Fluxo'!I27 -> 0 | ... BI33: ='Análise Fluxo'!BI27 -> -1666.6667 | BJ33: =SUM(B33:BI33) -> -37000 | BK33: =IFERROR(BJ33/BJ$16,0) -> -0.00050802179
A34: (=) EBITDA | B34: =B27+SUM(B31:B33) -> 0 | C34: =C27+SUM(C31:C33) -> 0 | D34: =D27+SUM(D31:D33) -> 0 | E34: =E27+SUM(E31:E33) -> 0 | F34: =F27+SUM(F31:F33) -> -600 | G34: =G27+SUM(G31:G33) -> -600 | H34: =H27+SUM(H31:H33) -> -600 | I34: =I27+SUM(I31:I33) -> -600 | ... BI34: =BI27+SUM(BI31:BI33) -> 551209.7 | BJ34: =SUM(B34:BI34) -> 7774451.7
A35: Margem EBITDA (% da receita líquida) | B35: =IFERROR(B34/B22,0) -> 0 | C35: =IFERROR(C34/C22,0) -> 0 | D35: =IFERROR(D34/D22,0) -> 0 | E35: =IFERROR(E34/E22,0) -> 0 | F35: =IFERROR(F34/F22,0) -> 0 | G35: =IFERROR(G34/G22,0) -> 0 | H35: =IFERROR(H34/H22,0) -> 0 | I35: =IFERROR(I34/I22,0) -> 0 | ... BJ35: =IFERROR(BJ34/BJ22,0) -> 0.14847339
A37: RESULTADO
A38: (−) Depreciação e amortização | B38: =-Investimentos!B30 -> 0 | C38: =-Investimentos!C30 -> 0 | D38: =-Investimentos!D30 -> 0 | E38: =-Investimentos!E30 -> 0 | F38: =-Investimentos!F30 -> 0 | G38: =-Investimentos!G30 -> -100 | H38: =-Investimentos!H30 -> -100 | I38: =-Investimentos!I30 -> -100 | ... BI38: =-Investimentos!BI30 -> -2068.797 | BJ38: =SUM(B38:BI38) -> -62285.777 | BK38: Investimentos amortizados linearmente em 60 meses.
A39: (=) EBIT — resultado operacional | B39: =B34+B38 -> 0 | C39: =C34+C38 -> 0 | D39: =D34+D38 -> 0 | E39: =E34+E38 -> 0 | F39: =F34+F38 -> -600 | G39: =G34+G38 -> -700 | H39: =H34+H38 -> -700 | I39: =I34+I38 -> -700 | ... BI39: =BI34+BI38 -> 549140.91 | BJ39: =SUM(B39:BI39) -> 7712166
A40: (+/−) Resultado financeiro | B40: =0 -> 0 | C40: =0 -> 0 | D40: =0 -> 0 | E40: =0 -> 0 | F40: =0 -> 0 | G40: =0 -> 0 | H40: =0 -> 0 | I40: =0 -> 0 | ... BI40: =0 -> 0 | BJ40: =SUM(B40:BI40) -> 0 | BK40: Rendimento do caixa não considerado (premissa conservadora).
A41: (=) RESULTADO ANTES DO IR | B41: =B39+B40 -> 0 | C41: =C39+C40 -> 0 | D41: =D39+D40 -> 0 | E41: =E39+E40 -> 0 | F41: =F39+F40 -> -600 | G41: =G39+G40 -> -700 | H41: =H39+H40 -> -700 | I41: =I39+I40 -> -700 | ... BI41: =BI39+BI40 -> 549140.91 | BJ41: =SUM(B41:BI41) -> 7712166
A42: (−) IRPJ e CSLL | B42: =0 -> 0 | C42: =0 -> 0 | D42: =0 -> 0 | E42: =0 -> 0 | F42: =0 -> 0 | G42: =0 -> 0 | H42: =0 -> 0 | I42: =0 -> 0 | ... BI42: =0 -> 0 | BJ42: =SUM(B42:BI42) -> 0 | BK42: Já incluídos na linha de impostos sobre a receita (DAS do Simples ou Lucro Presumido).
A43: (=) LUCRO LÍQUIDO DO EXERCÍCIO | B43: =B41+B42 -> 0 | C43: =C41+C42 -> 0 | D43: =D41+D42 -> 0 | E43: =E41+E42 -> 0 | F43: =F41+F42 -> -600 | G43: =G41+G42 -> -700 | H43: =H41+H42 -> -700 | I43: =I41+I42 -> -700 | ... BI43: =BI41+BI42 -> 549140.91 | BJ43: =SUM(B43:BI43) -> 7712166
A44: Margem líquida (% da receita líquida) | B44: =IFERROR(B43/B22,0) -> 0 | C44: =IFERROR(C43/C22,0) -> 0 | D44: =IFERROR(D43/D22,0) -> 0 | E44: =IFERROR(E43/E22,0) -> 0 | F44: =IFERROR(F43/F22,0) -> 0 | G44: =IFERROR(G43/G22,0) -> 0 | H44: =IFERROR(H43/H22,0) -> 0 | I44: =IFERROR(I43/I22,0) -> 0 | ... BJ44: =IFERROR(BJ43/BJ22,0) -> 0.14728388
A45: Lucro líquido acumulado | B45: =B43 -> 0 | C45: =B45+C43 -> 0 | D45: =C45+D43 -> 0 | E45: =D45+E43 -> 0 | F45: =E45+F43 -> -600 | G45: =F45+G43 -> -1300 | H45: =G45+H43 -> -2000 | I45: =H45+I43 -> -2700 | J45: =I45+J43 -> -3552.1303 | ... BI45: =BH45+BI43 -> 7712166
...

Sheet Análise Fluxo
A1: ANÁLISE DE FLUXO DE CAIXA E VIABILIDADE
A2: =" Cenário ativo: "&Premissas!B7 -> Cenário ativo: PROVÁVEL
A4: Linha do tempo | B4: 46023 | C4: 46054 | D4: 46082 | E4: 46113 | F4: 46143 | G4: 46174 | H4: 46204 | I4: 46235 | J4: 46266 | K4: 46296 | L4: 46327 | M4: 46357 | N4: 46388 | O4: 46419 | P4: 46447 | Q4: 46478 | R4: 46508 | S4: 46539 | T4: 46569 | U4: 46600 | V4: 46631 | W4: 46661 | X4: 46692 | Y4: 46722 | Z4: 46753 | AA4: 46784 | AB4: 46813 | AC4: 46844 | AD4: 46874 | AE4: 46905 | AF4: 46935 | AG4: 46966 | AH4: 46997 | AI4: 47027 | AJ4: 47058 | AK4: 47088 | AL4: 47119 | AM4: 47150 | AN4: 47178 | AO4: 47209 | AP4: 47239 | AQ4: 47270 | AR4: 47300 | AS4: 47331 | AT4: 47362 | AU4: 47392 | AV4: 47423 | AW4: 47453 | AX4: 47484 | AY4: 47515 | AZ4: 47543 | BA4: 47574 | BB4: 47604 | BC4: 47635 | BD4: 47665 | BE4: 47696 | BF4: 47727 | BG4: 47757 | BH4: 47788 | BI4: 47818 | BJ4: TOTAL | BK4: % / Nota
A5: Mês nº | B5: 1 | C5: 2 | D5: 3 | E5: 4 | F5: 5 | G5: 6 | H5: 7 | I5: 8 | J5: 9 | K5: 10 | L5: 11 | M5: 12 | N5: 13 | O5: 14 | P5: 15 | Q5: 16 | R5: 17 | S5: 18 | T5: 19 | U5: 20 | V5: 21 | W5: 22 | X5: 23 | Y5: 24 | Z5: 25 | AA5: 26 | AB5: 27 | AC5: 28 | AD5: 29 | AE5: 30 | AF5: 31 | AG5: 32 | AH5: 33 | AI5: 34 | AJ5: 35 | AK5: 36 | AL5: 37 | AM5: 38 | AN5: 39 | AO5: 40 | AP5: 41 | AQ5: 42 | AR5: 43 | AS5: 44 | AT5: 45 | AU5: 46 | AV5: 47 | AW5: 48 | AX5: 49 | AY5: 50 | AZ5: 51 | BA5: 52 | BB5: 53 | BC5: 54 | BD5: 55 | BE5: 56 | BF5: 57 | BG5: 58 | BH5: 59 | BI5: 60
A6: Ano | B6: =YEAR(B4) -> 2026 | C6: =YEAR(C4) -> 2026 | D6: =YEAR(D4) -> 2026 | E6: =YEAR(E4) -> 2026 | F6: =YEAR(F4) -> 2026 | G6: =YEAR(G4) -> 2026 | H6: =YEAR(H4) -> 2026 | I6: =YEAR(I4) -> 2026 | ... BI6: =YEAR(BI4) -> 2030
A7: Índice do ano (auxiliar) | B7: =MATCH(B6,Premissas!$C$5:$G$5,0) -> 1 | C7: =MATCH(C6,Premissas!$C$5:$G$5,0) -> 1 | D7: =MATCH(D6,Premissas!$C$5:$G$5,0) -> 1 | E7: =MATCH(E6,Premissas!$C$5:$G$5,0) -> 1 | F7: =MATCH(F6,Premissas!$C$5:$G$5,0) -> 1 | G7: =MATCH(G6,Premissas!$C$5:$G$5,0) -> 1 | H7: =MATCH(H6,Premissas!$C$5:$G$5,0) -> 1 | I7: =MATCH(I6,Premissas!$C$5:$G$5,0) -> 1 | ... BI7: =MATCH(BI6,Premissas!$C$5:$G$5,0) -> 5
A8: PROJETO — INVESTIMENTOS
A9: Desenvolvimento do app (pessoal capitalizado) | B9: =-Investimentos!B24 -> 0 | C9: =-Investimentos!C24 -> 0 | D9: =-Investimentos!D24 -> 0 | E9: =-Investimentos!E24 -> 0 | F9: =-Investimentos!F24 -> 0 | G9: =-Investimentos!G24 -> 0 | H9: =-Investimentos!H24 -> 0 | I9: =-Investimentos!I24 -> 0 | ... BI9: =-Investimentos!BI24 -> 0 | BJ9: =SUM(B9:BI9) -> -21000 | BK9: =IFERROR(BJ9/BJ$13,0) -> 0.16918045
A10: Equipamentos | B10: =-Investimentos!B21 -> 0 | C10: =-Investimentos!C21 -> 0 | D10: =-Investimentos!D21 -> 0 | E10: =-Investimentos!E21 -> 0 | F10: =-Investimentos!F21 -> 0 | G10: =-Investimentos!G21 -> 0 | H10: =-Investimentos!H21 -> 0 | I10: =-Investimentos!I21 -> -9127.82 | ... BI10: =-Investimentos!BI21 -> 0 | BJ10: =SUM(B10:BI10) -> -85127.82 | BK10: =IFERROR(BJ10/BJ$13,0) -> 0.68580774
A11: Constituição, marca e jurídico | B11: =-Investimentos!B22 -> 0 | C11: =-Investimentos!C22 -> 0 | D11: =-Investimentos!D22 -> 0 | E11: =-Investimentos!E22 -> 0 | F11: =-Investimentos!F22 -> -6000 | G11: =-Investimentos!G22 -> 0 | H11: =-Investimentos!H22 -> 0 | I11: =-Investimentos!I22 -> 0 | ... BI11: =-Investimentos!BI22 -> 0 | BJ11: =SUM(B11:BI11) -> -6000 | BK11: =IFERROR(BJ11/BJ$13,0) -> 0.04833727
A12: Certificações e conformidade | B12: =-Investimentos!B23 -> 0 | C12: =-Investimentos!C23 -> 0 | D12: =-Investimentos!D23 -> 0 | E12: =-Investimentos!E23 -> 0 | F12: =-Investimentos!F23 -> 0 | G12: =-Investimentos!G23 -> 0 | H12: =-Investimentos!H23 -> 0 | I12: =-Investimentos!I23 -> 0 | ... BI12: =-Investimentos!BI23 -> 0 | BJ12: =SUM(B12:BI12) -> -12000 | BK12: =IFERROR(BJ12/BJ$13,0) -> 0.096674541
A13: TOTAL PROJETO | B13: =SUM(B9:B12) -> 0 | C13: =SUM(C9:C12) -> 0 | D13: =SUM(D9:D12) -> 0 | E13: =SUM(E9:E12) -> 0 | F13: =SUM(F9:F12) -> -6000 | G13: =SUM(G9:G12) -> 0 | H13: =SUM(H9:H12) -> 0 | I13: =SUM(I9:I12) -> -9127.82 | ... BI13: =SUM(BI9:BI12) -> 0 | BJ13: =SUM(B13:BI13) -> -124127.82
A15: OPERACIONAIS
A16: Infraestrutura e nuvem | B16: =CHOOSE(Premissas!$B$6,Cenários!B35,Cenários!B81,Cenários!B127) -> 0 | C16: =CHOOSE(Premissas!$B$6,Cenários!C35,Cenários!C81,Cenários!C127) -> 0 | D16: =CHOOSE(Premissas!$B$6,Cenários!D35,Cenários!D81,Cenários!D127) -> 0 | E16: =CHOOSE(Premissas!$B$6,Cenários!E35,Cenários!E81,Cenários!E127) -> 0 | F16: =CHOOSE(Premissas!$B$6,Cenários!F35,Cenários!F81,Cenários!F127) -> -600 | G16: =CHOOSE(Premissas!$B$6,Cenários!G35,Cenários!G81,Cenários!G127) -> -600 | H16: =CHOOSE(Premissas!$B$6,Cenários!H35,Cenários!H81,Cenários!H127) -> -600 | I16: =CHOOSE(Premissas!$B$6,Cenários!I35,Cenários!I81,Cenários!I127) -> -600 | ... BI16: =CHOOSE(Premissas!$B$6,Cenários!BI35,Cenários!BI81,Cenários!BI127) -> -1303794.4 | BJ16: =SUM(B16:BI16) -> -28065492 | BK16: =IFERROR(BJ16/BJ$28,0) -> 0.43139804
