Workbook

Sheet Como usar
A1: COMO USAR ESTA PLANILHA
A2: Leia uma vez. Depois é só mexer nas células azuis e ver tudo recalcular.
B5: EM 30 SEGUNDOS
B6: Só existem dois lugares onde você digita: a aba PREMISSAS (todos os números do negócio) e a aba PESSOAS (o quadro de pessoal). Todo o resto da planilha é calculado a partir dessas duas. Comece olhando o RESUMO, volte, ajuste, olhe de novo.
B7: 1. Abra o Resumo | C7: Painel executivo com os três cenários lado a lado e o diagnóstico Go / No-Go. É a foto do modelo.
B8: 2. Mude o cenário | C8: Premissas, controle 1.1: digite 1 (Conservador), 2 (Provável) ou 3 (Agressivo). As abas de detalhe passam todas a mostrar o cenário escolhido. O Resumo mostra os três sempre.
B9: 3. Ajuste o que quiser | C9: Qualquer célula azul. O modelo inteiro recalcula na hora — não há nada para rodar ou atualizar.
B10: 4. Confira | C10: Na Análise Fluxo há uma linha de verificação que compara o detalhamento com o motor de cenários. Ela tem que ficar zerada. Se aparecer um número diferente de zero, alguma fórmula foi sobrescrita por engano.
B12: AS CORES DIZEM O QUE É CADA CÉLULA
B13: Azul | C13: Você digita. É uma premissa sua.
B14: Fundo amarelo | C14: Premissa-chave: mexer nela desloca bastante o resultado. Comece por essas.
B15: Preto | C15: Fórmula calculada dentro da própria aba. Não mexa.
B16: Verde | C16: Valor que vem de outra aba. Não mexa — mude na origem.
B17: Marca vermelha no canto | C17: Passe o mouse: há um comentário com a fonte ou a justificativa do número.
B19: AS PERGUNTAS MAIS COMUNS E ONDE MEXER
B20: “E se lançarmos mais tarde?” | C20: Premissas → Ano de lançamento e Mês de lançamento. São dois campos separados; a data e o mês nº da linha do tempo se ajustam sozinhos, e com eles receita, marketing e conversão.
B21: “Achamos que 5% de pagantes é otimista.” | C21: Premissas → seção 4 → Taxa de conversão. Digite o patamar de 2026 na coluna C e a evolução anual na coluna B. Lembre que este é o patamar DE REGIME: nos primeiros meses a conversão sobe pela rampa, então 2026 sai naturalmente mais tímido.
B22: “Quanto tempo até converter no patamar cheio?” | C22: Premissas → Rampa de maturação da conversão (meses). Com 6, o app leva 6 meses após o lançamento para atingir o patamar do ano. Coloque 1 se quiser conversão cheia desde o primeiro mês.
B23: “Vamos contratar mais gente / menos gente.” | C23: Aba PESSOAS. Uma linha por papel: quantidade, custo por pessoa, mês de início e mês de fim. Adicione linhas nos espaços em branco no fim da tabela. O custo total do mês é calculado sozinho e desce para a DRE e para o fluxo de caixa.
B24: “Quero ver o modelo só com o que já está contratado.” | C24: Premissas → controle “Considerar o plano de contratações?” → digite 0. Some do modelo tudo que está marcado como Plano na aba Pessoas, sobrando apenas a equipe do MVP.
B25: “E se os aportes atrasarem?” | C25: Aba APORTES: mude a data de qualquer linha. Veja o efeito na linha Caixa Acumulado da Análise Fluxo e no indicador “Caixa mínimo” do Resumo.
B26: “Quero incluir um investidor novo.” | C26: Aba APORTES. Se ele só coloca dinheiro, preencha uma linha em branco da tabela 1: data, nome, valor, status e tipo. Se ele também traz receita — uma parceria como a da Boston Scientific — use a tabela 2, que tem campos para o aporte e para a receita mensal recorrente, com início e fim. Não é preciso mexer em nenhuma fórmula.
B27: “E se a Boston fechar?” | C27: Aba Aportes, tabela 2: mude o status da linha da Boston para Confirmado, ou ligue o interruptor “Considerar acordos em negociação” na seção 7 de Premissas para ver todos os acordos em negociação de uma vez.
B28: “Quanto cada sócio tem do capital?” | C28: Aba Aportes, seção 5. É a proporção do dinheiro aportado — ponto de partida da conversa societária, não percentual de equity, que depende do valuation de cada rodada. Ao incluir um investidor novo, lembre de acrescentar o nome dele também nesta tabela: a linha “Capital não atribuído” avisa se você esquecer.
B29: “Queremos incluir uma nova frente de receita B2B.” | C29: Premissas, seção 5, tabela “Iniciativas de receita B2B”. Uma linha por frente: nome, categoria (Dados ou Outras), status, modelo de cobrança (valor fixo mensal ou por usuário do painel), valor e período. As duas primeiras linhas são a venda de dados, já planejada; as demais estão em branco para vocês preencherem.
B30: “Por que a receita de dados só aparece em 2028?” | C30: Porque o painel precisa de escala. O modelo zera essa receita enquanto a base que consentiu compartilhar dados não passa do mínimo definido em Premissas — mesmo que a data do contrato já tenha chegado. Mexa na taxa de consentimento e no mínimo do painel para ver o efeito.
B31: “Vamos mudar os preços dos planos.” | C31: Premissas → seção 3. Preços e mix por plano. A ARPPU implícita aparece logo abaixo do mix, para você conferir o efeito antes de olhar o resultado.
... B37: “O número de um mês específico é diferente do número do ano.” | C37: Aba AJUSTE MENSAL. Digite o valor naquele mês e ele passa a valer só ali. Em branco, o modelo usa a premissa anual. Serve também para fechar o passado: conforme os meses acontecem, digite o realizado e o modelo projeta só o que falta.
B39: AS ABAS, UMA A UMA
B40: Como usar | C40: Este guia.
B41: Resumo | C41: Painel executivo. Três cenários lado a lado, teste Go/No-Go em quatro perguntas objetivas, métricas de unidade e a lista de pontos de atenção que apareceram na modelagem. É a aba para mostrar a um investidor.
B42: Necessidade de Capital | C42: Quanto a empresa precisa de investimento e de quem. Mês a mês, com um bloco por cenário: o que a operação queima, o capital já na mesa por status, a reserva mínima desejada e a lacuna que sobra. Fecha com a resposta por cenário e o rateio entre os sócios. Há duas respostas para 'quanto falta captar' — uma ignorando as datas de entrada do capital e outra respeitando. A segunda é a que manda.
B43: Preço Mínimo | C43: A conta de trás pra frente: do custo para o preço. Quanto sobra de cada real cobrado depois de imposto, loja e meio de pagamento; o custo variável por assinante; e os pisos de preço de cada plano, mês a mês. A seção 6 responde se a assinatura cobre os primeiros meses do lançamento. Esta aba não altera a projeção — é régua, não motor.
B44: Premissas | C44: Todos os números do negócio, em oito seções: controles, tributação, preços e mix, drivers por cenário, monetização, custos operacionais, Boston Scientific e notas metodológicas. É aqui que você passa a maior parte do tempo.
B45: Ajuste Mensal | C45: Sobrepõe a premissa anual em um mês específico: captação, churn, conversão, CAC, nuvem fixa, marketing recorrente e administrativas. Em branco, nada muda. A coluna TOTAL conta quantos meses estão sobrepostos, e o bloco final avisa se alguma célula caiu fora da janela do driver e vai ser ignorada.
B46: Pessoas | C46: O quadro de pessoal, linha a linha. Separa o que está contratado do que é plano, calcula o headcount mês a mês e o Fator R — o índice que decide se a empresa fica no Anexo III ou no Anexo V do Simples.
B47: Sócios | C47: O lucro distribuível e o rateio por participação. Os percentuais estão provisórios — fundadores majoritários, investidores com cotas menores — porque os valores definitivos dependem do valuation de cada rodada. Troque os percentuais e o rateio responde.
B48: DRE Projetada | C48: A demonstração de resultado em regime de competência, mês a mês e consolidada por ano. Receita bruta → deduções → receita líquida → lucro bruto → EBITDA → lucro líquido, com as margens em cada etapa.
B49: Análise Fluxo | C49: O fluxo de caixa, na mesma estrutura da sua planilha de Análise de Investimento: Projeto (investimentos) → Operacionais → Fluxo de Caixa Livre → VPL, TIR e Payback. Traz também a linha de verificação e o caixa acumulado.
B50: Faturamento | C50: A receita aberta por linha de negócio — cada plano, marketplace, B2B — com as deduções e um resumo anual.
...

Sheet Resumo
A1: OPPA — VIABILIDADE FINANCEIRA · PAINEL EXECUTIVO
A2: Projeção de 60 meses (jan/2026 – dez/2030). Os três cenários são calculados simultaneamente. Todos os números vêm de fórmulas — nada está digitado à mão.
B4: INDICADOR | C4: CONSERVADOR | D4: PROVÁVEL | E4: AGRESSIVO
B5: Cenário em uso nas abas de detalhe | C5: =IF(Premissas!$B$6=1,"◀ ATIVO","") | D5: =IF(Premissas!$B$6=2,"◀ ATIVO","") -> ◀ ATIVO | E5: =IF(Premissas!$B$6=3,"◀ ATIVO","")
A7: TRAÇÃO — USUÁRIOS E RECEITA
B8: Usuários na base em dez/2026 | C8: =Cenários!$M$13 -> 29430.6 | D8: =Cenários!$M$59 -> 50071.84 | E8: =Cenários!$M$105 -> 71550.024 | G8: Meta do brief: 50 mil usuários ao final de 2026.
B9: Usuários na base em dez/2030 | C9: =Cenários!$BI$13 -> 422036.02 | D9: =Cenários!$BI$59 -> 1116849.8 | E9: =Cenários!$BI$105 -> 2424300.5
B10: Assinantes pagantes em dez/2026 | C10: =Cenários!$M$15 -> 441 | D10: =Cenários!$M$61 -> 1252 | E10: =Cenários!$M$107 -> 2504 | G10: Meta do brief: 5% da base pagante.
B11: Assinantes pagantes em dez/2030 | C11: =Cenários!$BI$15 -> 17225 | D11: =Cenários!$BI$61 -> 75973 | E11: =Cenários!$BI$107 -> 248459
B12: Receita bruta de 2026 | C12: =SUMIFS(Cenários!$B$28:$BI$28,Cenários!$B$6:$BI$6,2026) -> 13949.9 | D12: =SUMIFS(Cenários!$B$74:$BI$74,Cenários!$B$6:$BI$6,2026) -> 39441.8 | E12: =SUMIFS(Cenários!$B$120:$BI$120,Cenários!$B$6:$BI$6,2026) -> 78545.3
B13: Receita bruta de 2030 | C13: =SUMIFS(Cenários!$B$28:$BI$28,Cenários!$B$6:$BI$6,2030) -> 8750338.7 | D13: =SUMIFS(Cenários!$B$74:$BI$74,Cenários!$B$6:$BI$6,2030) -> 33253920 | E13: =SUMIFS(Cenários!$B$120:$BI$120,Cenários!$B$6:$BI$6,2030) -> 1.0144467e+08
B14: Receita bruta acumulada em 5 anos | C14: =SUM(Cenários!$B$28:$BI$28) -> 17316442 | D14: =SUM(Cenários!$B$74:$BI$74) -> 62932363 | E14: =SUM(Cenários!$B$120:$BI$120) -> 1.7927006e+08
A16: RESULTADO OPERACIONAL
B17: EBITDA de 2026 | C17: =SUMIFS(Cenários!$B$40:$BI$40,Cenários!$B$6:$BI$6,2026) -> -136110.43 | D17: =SUMIFS(Cenários!$B$86:$BI$86,Cenários!$B$6:$BI$6,2026) -> -124977.28 | E17: =SUMIFS(Cenários!$B$132:$BI$132,Cenários!$B$6:$BI$6,2026) -> -86438.931
B18: EBITDA de 2030 | C18: =SUMIFS(Cenários!$B$40:$BI$40,Cenários!$B$6:$BI$6,2030) -> -5412426.2 | D18: =SUMIFS(Cenários!$B$86:$BI$86,Cenários!$B$6:$BI$6,2030) -> 10815995 | E18: =SUMIFS(Cenários!$B$132:$BI$132,Cenários!$B$6:$BI$6,2030) -> 57369637
B19: EBITDA acumulado em 5 anos | C19: =SUM(Cenários!$B$40:$BI$40) -> -11914397 | D19: =SUM(Cenários!$B$86:$BI$86) -> 18055035 | E19: =SUM(Cenários!$B$132:$BI$132) -> 96972482
B20: Margem EBITDA em 2030 (% da receita bruta) | C20: =IFERROR(C18/C13,0) -> -0.61853905 | D20: =IFERROR(D18/D13,0) -> 0.32525473 | E20: =IFERROR(E18/E13,0) -> 0.56552635
B21: Break-even do EBITDA | C21: =IF(SUM(Cenários!$B$46:$BI$46)=0,"não atinge",CHOOSE(MOD(60-SUM(Cenários!$B$46:$BI$46),12)+1,"jan","fev","mar","abr","mai","jun","jul","ago","set","out","nov","dez")&"/"&(2026+INT((60-SUM(Cenários!$B$46:$BI$46))/12))) -> não atinge | D21: =IF(SUM(Cenários!$B$92:$BI$92)=0,"não atinge",CHOOSE(MOD(60-SUM(Cenários!$B$92:$BI$92),12)+1,"jan","fev","mar","abr","mai","jun","jul","ago","set","out","nov","dez")&"/"&(2026+INT((60-SUM(Cenários!$B$92:$BI$92))/12))) -> abr/2027 | E21: =IF(SUM(Cenários!$B$138:$BI$138)=0,"não atinge",CHOOSE(MOD(60-SUM(Cenários!$B$138:$BI$138),12)+1,"jan","fev","mar","abr","mai","jun","jul","ago","set","out","nov","dez")&"/"&(2026+INT((60-SUM(Cenários!$B$138:$BI$138))/12))) -> fev/2027 | G21: Primeiro mês com EBITDA positivo — quando a operação passa a se pagar.
A23: CAPITAL E CAIXA
B24: Investimento total (CAPEX) | C24: =-SUM(Cenários!$B$41:$BI$41) -> 149127.82 | D24: =-SUM(Cenários!$B$87:$BI$87) -> 149127.82 | E24: =-SUM(Cenários!$B$133:$BI$133) -> 149127.82
B25: Capital requerido (pico de caixa negativo do FCL) | C25: =-MIN(Cenários!$B$45:$BI$45) -> 12063525 | D25: =-MIN(Cenários!$B$91:$BI$91) -> 350781.55 | E25: =-MIN(Cenários!$B$137:$BI$137) -> 160419.32 | G25: Quanto a operação precisa de capital antes de se sustentar sozinha.
B26: Capital total considerado | C26: =SUM(Aportes!$B$98:$BI$98) -> 200000 | D26: =SUM(Aportes!$B$98:$BI$98) -> 200000 | E26: =SUM(Aportes!$B$98:$BI$98) -> 200000
B27: Caixa mínimo ao longo do período | C27: =MIN(Cenários!$B$49:$BI$49) -> -11863525 | D27: =MIN(Cenários!$B$95:$BI$95) -> -180781.55 | E27: =MIN(Cenários!$B$141:$BI$141) -> -4627.82 | G27: Se ficar negativo, o capital planejado não é suficiente — falta captar a diferença.
B28: Mês do caixa mínimo | C28: =CHOOSE(MOD(MATCH(MIN(Cenários!$B$49:$BI$49),Cenários!$B$49:$BI$49,0)-1,12)+1,"jan","fev","mar","abr","mai","jun","jul","ago","set","out","nov","dez")&"/"&(2026+INT((MATCH(MIN(Cenários!$B$49:$BI$49),Cenários!$B$49:$BI$49,0)-1)/12)) -> dez/2030 | D28: =CHOOSE(MOD(MATCH(MIN(Cenários!$B$95:$BI$95),Cenários!$B$95:$BI$95,0)-1,12)+1,"jan","fev","mar","abr","mai","jun","jul","ago","set","out","nov","dez")&"/"&(2026+INT((MATCH(MIN(Cenários!$B$95:$BI$95),Cenários!$B$95:$BI$95,0)-1)/12)) -> mar/2027 | E28: =CHOOSE(MOD(MATCH(MIN(Cenários!$B$141:$BI$141),Cenários!$B$141:$BI$141,0)-1,12)+1,"jan","fev","mar","abr","mai","jun","jul","ago","set","out","nov","dez")&"/"&(2026+INT((MATCH(MIN(Cenários!$B$141:$BI$141),Cenários!$B$141:$BI$141,0)-1)/12)) -> set/2026 | G28: Quando o caixa chega no fundo do poço — é o mês para o qual o aporte precisa chegar antes.
B29: Caixa em dez/2030 | C29: =Cenários!$BI$49 -> -11863525 | D29: =Cenários!$BI$95 -> 18105908 | E29: =Cenários!$BI$141 -> 97023354
B30: FALTA CAPTAR — respeitando as datas de entrada | C30: ='Necessidade de Capital'!B71 -> 14243306 | D30: ='Necessidade de Capital'!C71 -> 423788.68 | E30: ='Necessidade de Capital'!D71 -> 253883.27 | G30: Inclui a reserva mínima de caixa. Detalhe mês a mês na aba Necessidade de Capital.
B31: Primeiro mês com caixa negativo | C31: ='Necessidade de Capital'!B75 -> jun/2026 | D31: ='Necessidade de Capital'!C75 -> jun/2026 | E31: ='Necessidade de Capital'!D75 -> jun/2026 | G31: O prazo da captação. Pode ser bem antes do mês do fundo do poço.
B32: Por fundador, se os quatro cobrissem a lacuna | C32: ='Necessidade de Capital'!B82 -> 3560826.5 | D32: ='Necessidade de Capital'!C82 -> 105947.17 | E32: ='Necessidade de Capital'!D82 -> 63470.818 | G32: Além dos R$ 20 mil já comprometidos por cada um.
A34: PREÇO vs CUSTO — A CONTA DE TRÁS PRA FRENTE
B35: Primeiro mês em que a assinatura cobre o custo | C35: ='Preço Mínimo'!B86 -> não atinge | D35: ='Preço Mínimo'!C86 -> abr/2027 | E35: ='Preço Mínimo'!D86 -> fev/2027 | G35: Ao preço de tabela. É o mesmo mês do break-even acima — as duas contas são a mesma, lidas de lados opostos.
B36: EBITDA acumulado até o fim da janela de cobertura | C36: ='Preço Mínimo'!B85 -> -419187.63 | D36: ='Preço Mínimo'!C85 -> -302653.73 | E36: ='Preço Mínimo'!D85 -> -49907.888 | G36: Negativo significa que os primeiros meses não se pagam: a diferença vem de capital.
B37: Preço do Essencial que zeraria a janela inicial (cenário ativo) | C37: ='Preço Mínimo'!$B$68 -> 48.689548 | G37: Um preço único, cobrado em todos os meses da janela definida em Premissas.
B38: Quantas vezes o preço de hoje (cenário ativo) | C38: ='Preço Mínimo'!$B$72 -> 2.4467109 | G38: Acima de ~1,5x o preço deixa de ser vendável: o problema passa a ser de escala, não de preço.
B39: Assinantes necessários na janela, ao preço de hoje (cenário ativo) | C39: ='Preço Mínimo'!$B$73 -> 6178.6813 | G39: Contra a média projetada na mesma janela.
B40: Veredicto da janela inicial (cenário ativo) | C40: ='Preço Mínimo'!$B$77 -> Nenhum preço de mercado cobre: a janela é financiada por capital
A42: INDICADORES DE VIABILIDADE (sobre o Fluxo de Caixa Livre)
B43: VPL — Valor Presente Líquido | C43: =NPV(Premissas!$B$19,Cenários!$B$42:$BI$42) -> -5535282.7 | D43: =NPV(Premissas!$B$19,Cenários!$B$88:$BI$88) -> 7237765.1 | E43: =NPV(Premissas!$B$19,Cenários!$B$134:$BI$134) -> 40123778 | G43: Descontado à TMA definida em Premissas. Positivo = o projeto cria valor.
B44: TIR mensal | C44: =IFERROR(IRR(Cenários!$B$42:$BI$42),"n/d") -> n/d | D44: =IFERROR(IRR(Cenários!$B$88:$BI$88),"n/d") -> 0.1468989 | E44: =IFERROR(IRR(Cenários!$B$134:$BI$134),"n/d") -> 0.34011628
B45: TIR anual | C45: =IFERROR((1+C44)^12-1,"n/d") -> n/d | D45: =IFERROR((1+D44)^12-1,"n/d") -> 4.1796645 | E45: =IFERROR((1+E44)^12-1,"n/d") -> 32.551336 | G45: Compare com a TMA. Atenção: quando o investimento inicial é pequeno diante do caixa gerado, a TIR fica muito alta e perde poder de comparação — olhe o VPL junto.
B46: Payback simples (meses) | C46: =IF(Cenários!$BI$45<0,"> 60",MAX(Cenários!$B$50:$BI$50)+1) -> > 60 | D46: =IF(Cenários!$BI$91<0,"> 60",MAX(Cenários!$B$96:$BI$96)+1) -> 23 | E46: =IF(Cenários!$BI$137<0,"> 60",MAX(Cenários!$B$142:$BI$142)+1) -> 16 | G46: Mês em que o FCL acumulado passa a positivo e não volta mais.
...

Sheet Necessidade de Capital
A1: NECESSIDADE DE CAPITAL — QUANTO A EMPRESA PRECISA E DE QUEM
A2: Mês a mês, porque no começo é o mês que decide. O ano fecha positivo e a empresa quebra em março: é isso que a visão anual esconde.
A4: Linha do tempo | B4: 46023 | C4: 46054 | D4: 46082 | E4: 46113 | F4: 46143 | G4: 46174 | H4: 46204 | I4: 46235 | J4: 46266 | K4: 46296 | L4: 46327 | M4: 46357 | N4: 46388 | O4: 46419 | P4: 46447 | Q4: 46478 | R4: 46508 | S4: 46539 | T4: 46569 | U4: 46600 | V4: 46631 | W4: 46661 | X4: 46692 | Y4: 46722 | Z4: 46753 | AA4: 46784 | AB4: 46813 | AC4: 46844 | AD4: 46874 | AE4: 46905 | AF4: 46935 | AG4: 46966 | AH4: 46997 | AI4: 47027 | AJ4: 47058 | AK4: 47088 | AL4: 47119 | AM4: 47150 | AN4: 47178 | AO4: 47209 | AP4: 47239 | AQ4: 47270 | AR4: 47300 | AS4: 47331 | AT4: 47362 | AU4: 47392 | AV4: 47423 | AW4: 47453 | AX4: 47484 | AY4: 47515 | AZ4: 47543 | BA4: 47574 | BB4: 47604 | BC4: 47635 | BD4: 47665 | BE4: 47696 | BF4: 47727 | BG4: 47757 | BH4: 47788 | BI4: 47818 | BJ4: TOTAL | BK4: % / Nota
A5: Mês nº | B5: 1 | C5: 2 | D5: 3 | E5: 4 | F5: 5 | G5: 6 | H5: 7 | I5: 8 | J5: 9 | K5: 10 | L5: 11 | M5: 12 | N5: 13 | O5: 14 | P5: 15 | Q5: 16 | R5: 17 | S5: 18 | T5: 19 | U5: 20 | V5: 21 | W5: 22 | X5: 23 | Y5: 24 | Z5: 25 | AA5: 26 | AB5: 27 | AC5: 28 | AD5: 29 | AE5: 30 | AF5: 31 | AG5: 32 | AH5: 33 | AI5: 34 | AJ5: 35 | AK5: 36 | AL5: 37 | AM5: 38 | AN5: 39 | AO5: 40 | AP5: 41 | AQ5: 42 | AR5: 43 | AS5: 44 | AT5: 45 | AU5: 46 | AV5: 47 | AW5: 48 | AX5: 49 | AY5: 50 | AZ5: 51 | BA5: 52 | BB5: 53 | BC5: 54 | BD5: 55 | BE5: 56 | BF5: 57 | BG5: 58 | BH5: 59 | BI5: 60
A6: Ano | B6: =YEAR(B4) -> 2026 | C6: =YEAR(C4) -> 2026 | D6: =YEAR(D4) -> 2026 | E6: =YEAR(E4) -> 2026 | F6: =YEAR(F4) -> 2026 | G6: =YEAR(G4) -> 2026 | H6: =YEAR(H4) -> 2026 | I6: =YEAR(I4) -> 2026 | ... BI6: =YEAR(BI4) -> 2030
A7: Índice do ano (auxiliar) | B7: =MATCH(B6,Premissas!$C$5:$G$5,0) -> 1 | C7: =MATCH(C6,Premissas!$C$5:$G$5,0) -> 1 | D7: =MATCH(D6,Premissas!$C$5:$G$5,0) -> 1 | E7: =MATCH(E6,Premissas!$C$5:$G$5,0) -> 1 | F7: =MATCH(F6,Premissas!$C$5:$G$5,0) -> 1 | G7: =MATCH(G6,Premissas!$C$5:$G$5,0) -> 1 | H7: =MATCH(H6,Premissas!$C$5:$G$5,0) -> 1 | I7: =MATCH(I6,Premissas!$C$5:$G$5,0) -> 1 | ... BI7: =MATCH(BI6,Premissas!$C$5:$G$5,0) -> 5
A8: 1. O CAPITAL QUE JÁ ESTÁ NA MESA, POR STATUS — vale para os três cenários
A9: Realizado | B9: =SUMPRODUCT((Aportes!$D$6:$D$37="Realizado")*(Aportes!$A$6:$A$37>=B$4)*(Aportes!$A$6:$A$37<=EOMONTH(B$4,0))*Aportes!$C$6:$C$37) -> 0 | C9: =SUMPRODUCT((Aportes!$D$6:$D$37="Realizado")*(Aportes!$A$6:$A$37>=C$4)*(Aportes!$A$6:$A$37<=EOMONTH(C$4,0))*Aportes!$C$6:$C$37) -> 0 | D9: =SUMPRODUCT((Aportes!$D$6:$D$37="Realizado")*(Aportes!$A$6:$A$37>=D$4)*(Aportes!$A$6:$A$37<=EOMONTH(D$4,0))*Aportes!$C$6:$C$37) -> 0 | E9: =SUMPRODUCT((Aportes!$D$6:$D$37="Realizado")*(Aportes!$A$6:$A$37>=E$4)*(Aportes!$A$6:$A$37<=EOMONTH(E$4,0))*Aportes!$C$6:$C$37) -> 10000 | F9: =SUMPRODUCT((Aportes!$D$6:$D$37="Realizado")*(Aportes!$A$6:$A$37>=F$4)*(Aportes!$A$6:$A$37<=EOMONTH(F$4,0))*Aportes!$C$6:$C$37) -> 0 | G9: =SUMPRODUCT((Aportes!$D$6:$D$37="Realizado")*(Aportes!$A$6:$A$37>=G$4)*(Aportes!$A$6:$A$37<=EOMONTH(G$4,0))*Aportes!$C$6:$C$37) -> 0 | H9: =SUMPRODUCT((Aportes!$D$6:$D$37="Realizado")*(Aportes!$A$6:$A$37>=H$4)*(Aportes!$A$6:$A$37<=EOMONTH(H$4,0))*Aportes!$C$6:$C$37) -> 5000 | I9: =SUMPRODUCT((Aportes!$D$6:$D$37="Realizado")*(Aportes!$A$6:$A$37>=I$4)*(Aportes!$A$6:$A$37<=EOMONTH(I$4,0))*Aportes!$C$6:$C$37) -> 18000 | ... BI9: =SUMPRODUCT((Aportes!$D$6:$D$37="Realizado")*(Aportes!$A$6:$A$37>=BI$4)*(Aportes!$A$6:$A$37<=EOMONTH(BI$4,0))*Aportes!$C$6:$C$37) -> 0 | BJ9: =SUM(B9:BI9) -> 33000 | BK9: Dinheiro que já entrou na conta da empresa.
A10: Compromisso | B10: =SUMPRODUCT((Aportes!$D$6:$D$37="Compromisso")*(Aportes!$A$6:$A$37>=B$4)*(Aportes!$A$6:$A$37<=EOMONTH(B$4,0))*Aportes!$C$6:$C$37) -> 0 | C10: =SUMPRODUCT((Aportes!$D$6:$D$37="Compromisso")*(Aportes!$A$6:$A$37>=C$4)*(Aportes!$A$6:$A$37<=EOMONTH(C$4,0))*Aportes!$C$6:$C$37) -> 0 | D10: =SUMPRODUCT((Aportes!$D$6:$D$37="Compromisso")*(Aportes!$A$6:$A$37>=D$4)*(Aportes!$A$6:$A$37<=EOMONTH(D$4,0))*Aportes!$C$6:$C$37) -> 0 | E10: =SUMPRODUCT((Aportes!$D$6:$D$37="Compromisso")*(Aportes!$A$6:$A$37>=E$4)*(Aportes!$A$6:$A$37<=EOMONTH(E$4,0))*Aportes!$C$6:$C$37) -> 0 | F10: =SUMPRODUCT((Aportes!$D$6:$D$37="Compromisso")*(Aportes!$A$6:$A$37>=F$4)*(Aportes!$A$6:$A$37<=EOMONTH(F$4,0))*Aportes!$C$6:$C$37) -> 0 | G10: =SUMPRODUCT((Aportes!$D$6:$D$37="Compromisso")*(Aportes!$A$6:$A$37>=G$4)*(Aportes!$A$6:$A$37<=EOMONTH(G$4,0))*Aportes!$C$6:$C$37) -> 0 | H10: =SUMPRODUCT((Aportes!$D$6:$D$37="Compromisso")*(Aportes!$A$6:$A$37>=H$4)*(Aportes!$A$6:$A$37<=EOMONTH(H$4,0))*Aportes!$C$6:$C$37) -> 0 | I10: =SUMPRODUCT((Aportes!$D$6:$D$37="Compromisso")*(Aportes!$A$6:$A$37>=I$4)*(Aportes!$A$6:$A$37<=EOMONTH(I$4,0))*Aportes!$C$6:$C$37) -> 0 | ... BI10: =SUMPRODUCT((Aportes!$D$6:$D$37="Compromisso")*(Aportes!$A$6:$A$37>=BI$4)*(Aportes!$A$6:$A$37<=EOMONTH(BI$4,0))*Aportes!$C$6:$C$37) -> 0 | BJ10: =SUM(B10:BI10) -> 47000 | BK10: Fundadores já se comprometeram; ainda não integralizaram.
A11: Previsto | B11: =SUMPRODUCT((Aportes!$D$6:$D$37="Previsto")*(Aportes!$A$6:$A$37>=B$4)*(Aportes!$A$6:$A$37<=EOMONTH(B$4,0))*Aportes!$C$6:$C$37) -> 0 | C11: =SUMPRODUCT((Aportes!$D$6:$D$37="Previsto")*(Aportes!$A$6:$A$37>=C$4)*(Aportes!$A$6:$A$37<=EOMONTH(C$4,0))*Aportes!$C$6:$C$37) -> 0 | D11: =SUMPRODUCT((Aportes!$D$6:$D$37="Previsto")*(Aportes!$A$6:$A$37>=D$4)*(Aportes!$A$6:$A$37<=EOMONTH(D$4,0))*Aportes!$C$6:$C$37) -> 0 | E11: =SUMPRODUCT((Aportes!$D$6:$D$37="Previsto")*(Aportes!$A$6:$A$37>=E$4)*(Aportes!$A$6:$A$37<=EOMONTH(E$4,0))*Aportes!$C$6:$C$37) -> 0 | F11: =SUMPRODUCT((Aportes!$D$6:$D$37="Previsto")*(Aportes!$A$6:$A$37>=F$4)*(Aportes!$A$6:$A$37<=EOMONTH(F$4,0))*Aportes!$C$6:$C$37) -> 0 | G11: =SUMPRODUCT((Aportes!$D$6:$D$37="Previsto")*(Aportes!$A$6:$A$37>=G$4)*(Aportes!$A$6:$A$37<=EOMONTH(G$4,0))*Aportes!$C$6:$C$37) -> 0 | H11: =SUMPRODUCT((Aportes!$D$6:$D$37="Previsto")*(Aportes!$A$6:$A$37>=H$4)*(Aportes!$A$6:$A$37<=EOMONTH(H$4,0))*Aportes!$C$6:$C$37) -> 0 | I11: =SUMPRODUCT((Aportes!$D$6:$D$37="Previsto")*(Aportes!$A$6:$A$37>=I$4)*(Aportes!$A$6:$A$37<=EOMONTH(I$4,0))*Aportes!$C$6:$C$37) -> 0 | ... BI11: =SUMPRODUCT((Aportes!$D$6:$D$37="Previsto")*(Aportes!$A$6:$A$37>=BI$4)*(Aportes!$A$6:$A$37<=EOMONTH(BI$4,0))*Aportes!$C$6:$C$37) -> 0 | BJ11: =SUM(B11:BI11) -> 120000 | BK11: Negociação em curso, sem assinatura. Ligado/desligado em Premissas.
A12: Em negociação | B12: =SUMPRODUCT((Aportes!$D$6:$D$37="Em negociação")*(Aportes!$A$6:$A$37>=B$4)*(Aportes!$A$6:$A$37<=EOMONTH(B$4,0))*Aportes!$C$6:$C$37) -> 0 | C12: =SUMPRODUCT((Aportes!$D$6:$D$37="Em negociação")*(Aportes!$A$6:$A$37>=C$4)*(Aportes!$A$6:$A$37<=EOMONTH(C$4,0))*Aportes!$C$6:$C$37) -> 0 | D12: =SUMPRODUCT((Aportes!$D$6:$D$37="Em negociação")*(Aportes!$A$6:$A$37>=D$4)*(Aportes!$A$6:$A$37<=EOMONTH(D$4,0))*Aportes!$C$6:$C$37) -> 0 | E12: =SUMPRODUCT((Aportes!$D$6:$D$37="Em negociação")*(Aportes!$A$6:$A$37>=E$4)*(Aportes!$A$6:$A$37<=EOMONTH(E$4,0))*Aportes!$C$6:$C$37) -> 0 | F12: =SUMPRODUCT((Aportes!$D$6:$D$37="Em negociação")*(Aportes!$A$6:$A$37>=F$4)*(Aportes!$A$6:$A$37<=EOMONTH(F$4,0))*Aportes!$C$6:$C$37) -> 0 | G12: =SUMPRODUCT((Aportes!$D$6:$D$37="Em negociação")*(Aportes!$A$6:$A$37>=G$4)*(Aportes!$A$6:$A$37<=EOMONTH(G$4,0))*Aportes!$C$6:$C$37) -> 0 | H12: =SUMPRODUCT((Aportes!$D$6:$D$37="Em negociação")*(Aportes!$A$6:$A$37>=H$4)*(Aportes!$A$6:$A$37<=EOMONTH(H$4,0))*Aportes!$C$6:$C$37) -> 0 | I12: =SUMPRODUCT((Aportes!$D$6:$D$37="Em negociação")*(Aportes!$A$6:$A$37>=I$4)*(Aportes!$A$6:$A$37<=EOMONTH(I$4,0))*Aportes!$C$6:$C$37) -> 0 | ... BI12: =SUMPRODUCT((Aportes!$D$6:$D$37="Em negociação")*(Aportes!$A$6:$A$37>=BI$4)*(Aportes!$A$6:$A$37<=EOMONTH(BI$4,0))*Aportes!$C$6:$C$37) -> 0 | BJ12: =SUM(B12:BI12) -> 0 | BK12: Sem compromisso nenhum. Desligado por padrão.
A13: Investidores estratégicos (tabela 2 da aba Aportes) | B13: =SUMPRODUCT((Aportes!$D$43:$D$50>=B$4)*(Aportes!$D$43:$D$50<=EOMONTH(B$4,0))*Aportes!$C$43:$C$50) -> 0 | C13: =SUMPRODUCT((Aportes!$D$43:$D$50>=C$4)*(Aportes!$D$43:$D$50<=EOMONTH(C$4,0))*Aportes!$C$43:$C$50) -> 0 | D13: =SUMPRODUCT((Aportes!$D$43:$D$50>=D$4)*(Aportes!$D$43:$D$50<=EOMONTH(D$4,0))*Aportes!$C$43:$C$50) -> 0 | E13: =SUMPRODUCT((Aportes!$D$43:$D$50>=E$4)*(Aportes!$D$43:$D$50<=EOMONTH(E$4,0))*Aportes!$C$43:$C$50) -> 0 | F13: =SUMPRODUCT((Aportes!$D$43:$D$50>=F$4)*(Aportes!$D$43:$D$50<=EOMONTH(F$4,0))*Aportes!$C$43:$C$50) -> 0 | G13: =SUMPRODUCT((Aportes!$D$43:$D$50>=G$4)*(Aportes!$D$43:$D$50<=EOMONTH(G$4,0))*Aportes!$C$43:$C$50) -> 0 | H13: =SUMPRODUCT((Aportes!$D$43:$D$50>=H$4)*(Aportes!$D$43:$D$50<=EOMONTH(H$4,0))*Aportes!$C$43:$C$50) -> 0 | I13: =SUMPRODUCT((Aportes!$D$43:$D$50>=I$4)*(Aportes!$D$43:$D$50<=EOMONTH(I$4,0))*Aportes!$C$43:$C$50) -> 0 | ... BI13: =SUMPRODUCT((Aportes!$D$43:$D$50>=BI$4)*(Aportes!$D$43:$D$50<=EOMONTH(BI$4,0))*Aportes!$C$43:$C$50) -> 0 | BJ13: =SUM(B13:BI13) -> 500000
A14: Capital de todos os status, somado | B14: =SUM(B9:B13) -> 0 | C14: =SUM(C9:C13) -> 0 | D14: =SUM(D9:D13) -> 0 | E14: =SUM(E9:E13) -> 10000 | F14: =SUM(F9:F13) -> 0 | G14: =SUM(G9:G13) -> 0 | H14: =SUM(H9:H13) -> 5000 | I14: =SUM(I9:I13) -> 18000 | ... BI14: =SUM(BI9:BI13) -> 0 | BJ14: =SUM(B14:BI14) -> 700000
A15: Capital que o modelo considera (depois dos interruptores) | B15: =Aportes!B98 -> 0 | C15: =Aportes!C98 -> 0 | D15: =Aportes!D98 -> 0 | E15: =Aportes!E98 -> 10000 | F15: =Aportes!F98 -> 0 | G15: =Aportes!G98 -> 0 | H15: =Aportes!H98 -> 5000 | I15: =Aportes!I98 -> 18000 | ... BI15: =Aportes!BI98 -> 0 | BJ15: =SUM(B15:BI15) -> 200000 | BK15: É este que entra no caixa. A diferença para a linha acima é o que está desligado.
A16: Capital considerado — acumulado | B16: =Aportes!B99 -> 0 | C16: =Aportes!C99 -> 0 | D16: =Aportes!D99 -> 0 | E16: =Aportes!E99 -> 10000 | F16: =Aportes!F99 -> 10000 | G16: =Aportes!G99 -> 10000 | H16: =Aportes!H99 -> 15000 | I16: =Aportes!I99 -> 33000 | ... BI16: =Aportes!BI99 -> 200000
A19: CENÁRIO 1 — CONSERVADOR
A20: Fluxo de caixa livre do mês (FCL) | B20: =Cenários!B42 -> 0 | C20: =Cenários!C42 -> 0 | D20: =Cenários!D42 -> 0 | E20: =Cenários!E42 -> -1500 | F20: =Cenários!F42 -> -8100 | G20: =Cenários!G42 -> -2100 | H20: =Cenários!H42 -> -2100 | I20: =Cenários!I42 -> -11227.82 | ... BI20: =Cenários!BI42 -> -392239.05 | BJ20: =SUM(B20:BI20) -> -12063525 | BK20: Não inclui aporte: aporte é financiamento, não geração de caixa.
A21: Buraco do mês (quanto a operação queimou) | B21: =IF(B20<0,-B20,0) -> 0 | C21: =IF(C20<0,-C20,0) -> 0 | D21: =IF(D20<0,-D20,0) -> 0 | E21: =IF(E20<0,-E20,0) -> 1500 | F21: =IF(F20<0,-F20,0) -> 8100 | G21: =IF(G20<0,-G20,0) -> 2100 | H21: =IF(H20<0,-H20,0) -> 2100 | I21: =IF(I20<0,-I20,0) -> 11227.82 | ... BI21: =IF(BI20<0,-BI20,0) -> 392239.05 | BJ21: =SUM(B21:BI21) -> 12063525
A22: Buraco acumulado | B22: =B21 -> 0 | C22: =B22+C21 -> 0 | D22: =C22+D21 -> 0 | E22: =D22+E21 -> 1500 | F22: =E22+F21 -> 9600 | G22: =F22+G21 -> 11700 | H22: =G22+H21 -> 13800 | I22: =H22+I21 -> 25027.82 | J22: =I22+J21 -> 37627.82 | ... BI22: =BH22+BI21 -> 12063525 | BK22: Soma de todos os meses negativos, sem compensar com os positivos.
A23: FCL acumulado (os positivos já abatendo os negativos) | B23: =Cenários!B45 -> 0 | C23: =Cenários!C45 -> 0 | D23: =Cenários!D45 -> 0 | E23: =Cenários!E45 -> -1500 | F23: =Cenários!F45 -> -9600 | G23: =Cenários!G45 -> -11700 | H23: =Cenários!H45 -> -13800 | I23: =Cenários!I45 -> -25027.82 | ... BI23: =Cenários!BI45 -> -12063525 | BK23: O fundo do poço desta linha é o capital requerido pela operação.
A24: Custo fixo do mês (nuvem, pessoas, marketing recorrente, administrativas) | B24: =-(Cenários!B35+'Análise Fluxo'!B18+'Análise Fluxo'!B19+'Análise Fluxo'!B20+'Análise Fluxo'!B22+'Análise Fluxo'!B27) -> 0 | C24: =-(Cenários!C35+'Análise Fluxo'!C18+'Análise Fluxo'!C19+'Análise Fluxo'!C20+'Análise Fluxo'!C22+'Análise Fluxo'!C27) -> 0 | D24: =-(Cenários!D35+'Análise Fluxo'!D18+'Análise Fluxo'!D19+'Análise Fluxo'!D20+'Análise Fluxo'!D22+'Análise Fluxo'!D27) -> 0 | E24: =-(Cenários!E35+'Análise Fluxo'!E18+'Análise Fluxo'!E19+'Análise Fluxo'!E20+'Análise Fluxo'!E22+'Análise Fluxo'!E27) -> 1500 | F24: =-(Cenários!F35+'Análise Fluxo'!F18+'Análise Fluxo'!F19+'Análise Fluxo'!F20+'Análise Fluxo'!F22+'Análise Fluxo'!F27) -> 2100 | G24: =-(Cenários!G35+'Análise Fluxo'!G18+'Análise Fluxo'!G19+'Análise Fluxo'!G20+'Análise Fluxo'!G22+'Análise Fluxo'!G27) -> 2100 | H24: =-(Cenários!H35+'Análise Fluxo'!H18+'Análise Fluxo'!H19+'Análise Fluxo'!H20+'Análise Fluxo'!H22+'Análise Fluxo'!H27) -> 2100 | I24: =-(Cenários!I35+'Análise Fluxo'!I18+'Análise Fluxo'!I19+'Análise Fluxo'!I20+'Análise Fluxo'!I22+'Análise Fluxo'!I27) -> 2100 | ... BI24: =-(Cenários!BI35+'Análise Fluxo'!BI18+'Análise Fluxo'!BI19+'Análise Fluxo'!BI20+'Análise Fluxo'!BI22+'Análise Fluxo'!BI27) -> 793260.32 | BJ24: =SUM(B24:BI24) -> 18862462 | BK24: Sem aquisição paga, imposto, loja e meio de pagamento: esses variam com a operação, não com a existência dela.
A25: Reserva mínima desejada | B25: =MAX(SUMPRODUCT((B$5:BI$5>B$5)*(B$5:BI$5<=B$5+Premissas!$B$118)*B$24:BI$24),Premissas!$B$118*B24) -> 1500 | C25: =MAX(SUMPRODUCT((B$5:BI$5>C$5)*(B$5:BI$5<=C$5+Premissas!$B$118)*B$24:BI$24),Premissas!$B$118*C24) -> 3600 | D25: =MAX(SUMPRODUCT((B$5:BI$5>D$5)*(B$5:BI$5<=D$5+Premissas!$B$118)*B$24:BI$24),Premissas!$B$118*D24) -> 5700 | E25: =MAX(SUMPRODUCT((B$5:BI$5>E$5)*(B$5:BI$5<=E$5+Premissas!$B$118)*B$24:BI$24),Premissas!$B$118*E24) -> 6300 | F25: =MAX(SUMPRODUCT((B$5:BI$5>F$5)*(B$5:BI$5<=F$5+Premissas!$B$118)*B$24:BI$24),Premissas!$B$118*F24) -> 6300 | G25: =MAX(SUMPRODUCT((B$5:BI$5>G$5)*(B$5:BI$5<=G$5+Premissas!$B$118)*B$24:BI$24),Premissas!$B$118*G24) -> 6300 | H25: =MAX(SUMPRODUCT((B$5:BI$5>H$5)*(B$5:BI$5<=H$5+Premissas!$B$118)*B$24:BI$24),Premissas!$B$118*H24) -> 9597.12 | I25: =MAX(SUMPRODUCT((B$5:BI$5>I$5)*(B$5:BI$5<=I$5+Premissas!$B$118)*B$24:BI$24),Premissas!$B$118*I24) -> 13314.68 | J25: =MAX(SUMPRODUCT((B$5:BI$5>J$5)*(B$5:BI$5<=J$5+Premissas!$B$118)*B$24:BI$24),Premissas!$B$118*J24) -> 17555.972 | K25: =MAX(SUMPRODUCT((B$5:BI$5>K$5)*(B$5:BI$5<=K$5+Premissas!$B$118)*B$24:BI$24),Premissas!$B$118*K24) -> 80196.027 | L25: =MAX(SUMPRODUCT((B$5:BI$5>L$5)*(B$5:BI$5<=L$5+Premissas!$B$118)*B$24:BI$24),Premissas!$B$118*L24) -> 143341.69 | M25: =MAX(SUMPRODUCT((B$5:BI$5>M$5)*(B$5:BI$5<=M$5+Premissas!$B$118)*B$24:BI$24),Premissas!$B$118*M24) -> 206982.56 | N25: =MAX(SUMPRODUCT((B$5:BI$5>N$5)*(B$5:BI$5<=N$5+Premissas!$B$118)*B$24:BI$24),Premissas!$B$118*N24) -> 209504.12 | O25: =MAX(SUMPRODUCT((B$5:BI$5>O$5)*(B$5:BI$5<=O$5+Premissas!$B$118)*B$24:BI$24),Premissas!$B$118*O24) -> 211621.42 | P25: =MAX(SUMPRODUCT((B$5:BI$5>P$5)*(B$5:BI$5<=P$5+Premissas!$B$118)*B$24:BI$24),Premissas!$B$118*P24) -> 213191.11 | Q25: =MAX(SUMPRODUCT((B$5:BI$5>Q$5)*(B$5:BI$5<=Q$5+Premissas!$B$118)*B$24:BI$24),Premissas!$B$118*Q24) -> 214610.6 | R25: =MAX(SUMPRODUCT((B$5:BI$5>R$5)*(B$5:BI$5<=R$5+Premissas!$B$118)*B$24:BI$24),Premissas!$B$118*R24) -> 215893.81 | S25: =MAX(SUMPRODUCT((B$5:BI$5>S$5)*(B$5:BI$5<=S$5+Premissas!$B$118)*B$24:BI$24),Premissas!$B$118*S24) -> 217054.17 | T25: =MAX(SUMPRODUCT((B$5:BI$5>T$5)*(B$5:BI$5<=T$5+Premissas!$B$118)*B$24:BI$24),Premissas!$B$118*T24) -> 218103.43 | U25: =MAX(SUMPRODUCT((B$5:BI$5>U$5)*(B$5:BI$5<=U$5+Premissas!$B$118)*B$24:BI$24),Premissas!$B$118*U24) -> 219051.62 | V25: =MAX(SUMPRODUCT((B$5:BI$5>V$5)*(B$5:BI$5<=V$5+Premissas!$B$118)*B$24:BI$24),Premissas!$B$118*V24) -> 219908.45 | W25: =MAX(SUMPRODUCT((B$5:BI$5>W$5)*(B$5:BI$5<=W$5+Premissas!$B$118)*B$24:BI$24),Premissas!$B$118*W24) -> 364881.88 | X25: =MAX(SUMPRODUCT((B$5:BI$5>X$5)*(B$5:BI$5<=X$5+Premissas!$B$118)*B$24:BI$24),Premissas!$B$118*X24) -> 510105.96 | Y25: =MAX(SUMPRODUCT((B$5:BI$5>Y$5)*(B$5:BI$5<=Y$5+Premissas!$B$118)*B$24:BI$24),Premissas!$B$118*Y24) -> 655558.59 | Z25: =MAX(SUMPRODUCT((B$5:BI$5>Z$5)*(B$5:BI$5<=Z$5+Premissas!$B$118)*B$24:BI$24),Premissas!$B$118*Z24) -> 657020.49 | AA25: =MAX(SUMPRODUCT((B$5:BI$5>AA$5)*(B$5:BI$5<=AA$5+Premissas!$B$118)*B$24:BI$24),Premissas!$B$118*AA24) -> 658347.48 | AB25: =MAX(SUMPRODUCT((B$5:BI$5>AB$5)*(B$5:BI$5<=AB$5+Premissas!$B$118)*B$24:BI$24),Premissas!$B$118*AB24) -> 659551.36 | AC25: =MAX(SUMPRODUCT((B$5:BI$5>AC$5)*(B$5:BI$5<=AC$5+Premissas!$B$118)*B$24:BI$24),Premissas!$B$118*AC24) -> 660644.71 | AD25: =MAX(SUMPRODUCT((B$5:BI$5>AD$5)*(B$5:BI$5<=AD$5+Premissas!$B$118)*B$24:BI$24),Premissas!$B$118*AD24) -> 661637.52 | AE25: =MAX(SUMPRODUCT((B$5:BI$5>AE$5)*(B$5:BI$5<=AE$5+Premissas!$B$118)*B$24:BI$24),Premissas!$B$118*AE24) -> 662539.47 | AF25: =MAX(SUMPRODUCT((B$5:BI$5>AF$5)*(B$5:BI$5<=AF$5+Premissas!$B$118)*B$24:BI$24),Premissas!$B$118*AF24) -> 663357.74 | AG25: =MAX(SUMPRODUCT((B$5:BI$5>AG$5)*(B$5:BI$5<=AG$5+Premissas!$B$118)*B$24:BI$24),Premissas!$B$118*AG24) -> 664100.38 | AH25: =MAX(SUMPRODUCT((B$5:BI$5>AH$5)*(B$5:BI$5<=AH$5+Premissas!$B$118)*B$24:BI$24),Premissas!$B$118*AH24) -> 664775.21 | AI25: =MAX(SUMPRODUCT((B$5:BI$5>AI$5)*(B$5:BI$5<=AI$5+Premissas!$B$118)*B$24:BI$24),Premissas!$B$118*AI24) -> 925595.8 | AJ25: =MAX(SUMPRODUCT((B$5:BI$5>AJ$5)*(B$5:BI$5<=AJ$5+Premissas!$B$118)*B$24:BI$24),Premissas!$B$118*AJ24) -> 1186785.1 | AK25: =MAX(SUMPRODUCT((B$5:BI$5>AK$5)*(B$5:BI$5<=AK$5+Premissas!$B$118)*B$24:BI$24),Premissas!$B$118*AK24) -> 1448309.7 | AL25: =MAX(SUMPRODUCT((B$5:BI$5>AL$5)*(B$5:BI$5<=AL$5+Premissas!$B$118)*B$24:BI$24),Premissas!$B$118*AL24) -> 1453770.3 | AM25: =MAX(SUMPRODUCT((B$5:BI$5>AM$5)*(B$5:BI$5<=AM$5+Premissas!$B$118)*B$24:BI$24),Premissas!$B$118*AM24) -> 1459223.6 | AN25: =MAX(SUMPRODUCT((B$5:BI$5>AN$5)*(B$5:BI$5<=AN$5+Premissas!$B$118)*B$24:BI$24),Premissas!$B$118*AN24) -> 1464672 | AO25: =MAX(SUMPRODUCT((B$5:BI$5>AO$5)*(B$5:BI$5<=AO$5+Premissas!$B$118)*B$24:BI$24),Premissas!$B$118*AO24) -> 1466278.9 | AP25: =MAX(SUMPRODUCT((B$5:BI$5>AP$5)*(B$5:BI$5<=AP$5+Premissas!$B$118)*B$24:BI$24),Premissas!$B$118*AP24) -> 1467744.5 | AQ25: =MAX(SUMPRODUCT((B$5:BI$5>AQ$5)*(B$5:BI$5<=AQ$5+Premissas!$B$118)*B$24:BI$24),Premissas!$B$118*AQ24) -> 1469080.2 | AR25: =MAX(SUMPRODUCT((B$5:BI$5>AR$5)*(B$5:BI$5<=AR$5+Premissas!$B$118)*B$24:BI$24),Premissas!$B$118*AR24) -> 1470297.2 | AS25: =MAX(SUMPRODUCT((B$5:BI$5>AS$5)*(B$5:BI$5<=AS$5+Premissas!$B$118)*B$24:BI$24),Premissas!$B$118*AS24) -> 1471406.1 | AT25: =MAX(SUMPRODUCT((B$5:BI$5>AT$5)*(B$5:BI$5<=AT$5+Premissas!$B$118)*B$24:BI$24),Premissas!$B$118*AT24) -> 1472417.3 | AU25: =MAX(SUMPRODUCT((B$5:BI$5>AU$5)*(B$5:BI$5<=AU$5+Premissas!$B$118)*B$24:BI$24),Premissas!$B$118*AU24) -> 1767344.7 | AV25: =MAX(SUMPRODUCT((B$5:BI$5>AV$5)*(B$5:BI$5<=AV$5+Premissas!$B$118)*B$24:BI$24),Premissas!$B$118*AV24) -> 2063006.6 | AW25: =MAX(SUMPRODUCT((B$5:BI$5>AW$5)*(B$5:BI$5<=AW$5+Premissas!$B$118)*B$24:BI$24),Premissas!$B$118*AW24) -> 2359340.7 | AX25: =MAX(SUMPRODUCT((B$5:BI$5>AX$5)*(B$5:BI$5<=AX$5+Premissas!$B$118)*B$24:BI$24),Premissas!$B$118*AX24) -> 2362286.3 | AY25: =MAX(SUMPRODUCT((B$5:BI$5>AY$5)*(B$5:BI$5<=AY$5+Premissas!$B$118)*B$24:BI$24),Premissas!$B$118*AY24) -> 2364981.4 | AZ25: =MAX(SUMPRODUCT((B$5:BI$5>AZ$5)*(B$5:BI$5<=AZ$5+Premissas!$B$118)*B$24:BI$24),Premissas!$B$118*AZ24) -> 2367447.8 | BA25: =MAX(SUMPRODUCT((B$5:BI$5>BA$5)*(B$5:BI$5<=BA$5+Premissas!$B$118)*B$24:BI$24),Premissas!$B$118*BA24) -> 2369704.4 | BB25: =MAX(SUMPRODUCT((B$5:BI$5>BB$5)*(B$5:BI$5<=BB$5+Premissas!$B$118)*B$24:BI$24),Premissas!$B$118*BB24) -> 2371769.3 | BC25: =MAX(SUMPRODUCT((B$5:BI$5>BC$5)*(B$5:BI$5<=BC$5+Premissas!$B$118)*B$24:BI$24),Premissas!$B$118*BC24) -> 2373659.1 | BD25: =MAX(SUMPRODUCT((B$5:BI$5>BD$5)*(B$5:BI$5<=BD$5+Premissas!$B$118)*B$24:BI$24),Premissas!$B$118*BD24) -> 2375388.7 | BE25: =MAX(SUMPRODUCT((B$5:BI$5>BE$5)*(B$5:BI$5<=BE$5+Premissas!$B$118)*B$24:BI$24),Premissas!$B$118*BE24) -> 2376971 | BF25: =MAX(SUMPRODUCT((B$5:BI$5>BF$5)*(B$5:BI$5<=BF$5+Premissas!$B$118)*B$24:BI$24),Premissas!$B$118*BF24) -> 2378418.8 | BG25: =MAX(SUMPRODUCT((B$5:BI$5>BG$5)*(B$5:BI$5<=BG$5+Premissas!$B$118)*B$24:BI$24),Premissas!$B$118*BG24) -> 2377016 | BH25: =MAX(SUMPRODUCT((B$5:BI$5>BH$5)*(B$5:BI$5<=BH$5+Premissas!$B$118)*B$24:BI$24),Premissas!$B$118*BH24) -> 2378459.4 | BI25: =MAX(SUMPRODUCT((B$5:BI$5>BI$5)*(B$5:BI$5<=BI$5+Premissas!$B$118)*B$24:BI$24),Premissas!$B$118*BI24) -> 2379780.9 | BK25: Custo fixo dos próximos meses. Nos últimos meses do horizonte não há 'próximos', então cai para o custo fixo do mês vezes o número de meses — senão a reserva sumiria justamente onde a empresa é maior.
A26: Caixa projetado no fim do mês | B26: =Cenários!B49 -> 0 | C26: =Cenários!C49 -> 0 | D26: =Cenários!D49 -> 0 | E26: =Cenários!E49 -> 8500 | F26: =Cenários!F49 -> 400 | G26: =Cenários!G49 -> -1700 | H26: =Cenários!H49 -> 1200 | I26: =Cenários!I49 -> 7972.18 | ... BI26: =Cenários!BI49 -> -11863525
A27: Caixa acima (ou abaixo) da reserva | B27: =B26-B25 -> -1500 | C27: =C26-C25 -> -3600 | D27: =D26-D25 -> -5700 | E27: =E26-E25 -> 2200 | F27: =F26-F25 -> -5900 | G27: =G26-G25 -> -8000 | H27: =H26-H25 -> -8397.12 | I27: =I26-I25 -> -5342.5 | ... BI27: =BI26-BI25 -> -14243306 | BK27: Negativo aqui já é sinal amarelo, mesmo com o caixa no positivo.
A28: FALTA CAPTAR neste mês | B28: =MAX(0,B25-B26) -> 1500 | C28: =MAX(0,C25-C26) -> 3600 | D28: =MAX(0,D25-D26) -> 5700 | E28: =MAX(0,E25-E26) -> 0 | F28: =MAX(0,F25-F26) -> 5900 | G28: =MAX(0,G25-G26) -> 8000 | H28: =MAX(0,H25-H26) -> 8397.12 | I28: =MAX(0,I25-I26) -> 5342.5 | ... BI28: =MAX(0,BI25-BI26) -> 14243306 | BK28: Quanto teria de estar em caixa neste mês e não está.
A29: FALTA CAPTAR — pior caso até aqui (cronograma de captação) | B29: =MAX($B28:B28) -> 1500 | C29: =MAX($B28:C28) -> 3600 | D29: =MAX($B28:D28) -> 5700 | E29: =MAX($B28:E28) -> 5700 | F29: =MAX($B28:F28) -> 5900 | G29: =MAX($B28:G28) -> 8000 | H29: =MAX($B28:H28) -> 8397.12 | I29: =MAX($B28:I28) -> 8397.12 | ... BI29: =MAX($B28:BI28) -> 14243306 | BK29: Só sobe. É a meta de captação que precisa estar fechada até este mês.
A30: Marcador — mês com caixa negativo | B30: =IF(B26<0,B$5,9999) -> 9999 | C30: =IF(C26<0,C$5,9999) -> 9999 | D30: =IF(D26<0,D$5,9999) -> 9999 | E30: =IF(E26<0,E$5,9999) -> 9999 | F30: =IF(F26<0,F$5,9999) -> 9999 | G30: =IF(G26<0,G$5,9999) -> 6 | H30: =IF(H26<0,H$5,9999) -> 9999 | I30: =IF(I26<0,I$5,9999) -> 9999 | ... BI30: =IF(BI26<0,BI$5,9999) -> 60 | BK30: Auxiliar: guarda o nº do mês quando o caixa fica negativo. O menor valor é o primeiro mês sem fundo.
A31: Meses de caixa restantes (runway) | B31: =IFERROR(IF(B24<=0,"",MAX(0,B26)/B24),"") | C31: =IFERROR(IF(C24<=0,"",MAX(0,C26)/C24),"") | D31: =IFERROR(IF(D24<=0,"",MAX(0,D26)/D24),"") | E31: =IFERROR(IF(E24<=0,"",MAX(0,E26)/E24),"") -> 5.6666667 | F31: =IFERROR(IF(F24<=0,"",MAX(0,F26)/F24),"") -> 0.19047619 | G31: =IFERROR(IF(G24<=0,"",MAX(0,G26)/G24),"") -> 0 | H31: =IFERROR(IF(H24<=0,"",MAX(0,H26)/H24),"") -> 0.57142857 | I31: =IFERROR(IF(I24<=0,"",MAX(0,I26)/I24),"") -> 3.7962762 | ... BI31: =IFERROR(IF(BI24<=0,"",MAX(0,BI26)/BI24),"") -> 0 | BK31: Caixa dividido pelo custo fixo do mês. Abaixo de 3 é zona de risco.
A33: CENÁRIO 2 — PROVÁVEL
A34: Fluxo de caixa livre do mês (FCL) | B34: =Cenários!B88 -> 0 | C34: =Cenários!C88 -> 0 | D34: =Cenários!D88 -> 0 | E34: =Cenários!E88 -> -1500 | F34: =Cenários!F88 -> -8100 | G34: =Cenários!G88 -> -2100 | H34: =Cenários!H88 -> -2100 | I34: =Cenários!I88 -> -11227.82 | ... BI34: =Cenários!BI88 -> 1213823.4 | BJ34: =SUM(B34:BI34) -> 17905908 | BK34: Não inclui aporte: aporte é financiamento, não geração de caixa.
A35: Buraco do mês (quanto a operação queimou) | B35: =IF(B34<0,-B34,0) -> 0 | C35: =IF(C34<0,-C34,0) -> 0 | D35: =IF(D34<0,-D34,0) -> 0 | E35: =IF(E34<0,-E34,0) -> 1500 | F35: =IF(F34<0,-F34,0) -> 8100 | G35: =IF(G34<0,-G34,0) -> 2100 | H35: =IF(H34<0,-H34,0) -> 2100 | I35: =IF(I34<0,-I34,0) -> 11227.82 | ... BI35: =IF(BI34<0,-BI34,0) -> 0 | BJ35: =SUM(B35:BI35) -> 350781.55
A36: Buraco acumulado | B36: =B35 -> 0 | C36: =B36+C35 -> 0 | D36: =C36+D35 -> 0 | E36: =D36+E35 -> 1500 | F36: =E36+F35 -> 9600 | G36: =F36+G35 -> 11700 | H36: =G36+H35 -> 13800 | I36: =H36+I35 -> 25027.82 | J36: =I36+J35 -> 37627.82 | ... BI36: =BH36+BI35 -> 350781.55 | BK36: Soma de todos os meses negativos, sem compensar com os positivos.
A37: FCL acumulado (os positivos já abatendo os negativos) | B37: =Cenários!B91 -> 0 | C37: =Cenários!C91 -> 0 | D37: =Cenários!D91 -> 0 | E37: =Cenários!E91 -> -1500 | F37: =Cenários!F91 -> -9600 | G37: =Cenários!G91 -> -11700 | H37: =Cenários!H91 -> -13800 | I37: =Cenários!I91 -> -25027.82 | ... BI37: =Cenários!BI91 -> 17905908 | BK37: O fundo do poço desta linha é o capital requerido pela operação.
A38: Custo fixo do mês (nuvem, pessoas, marketing recorrente, administrativas) | B38: =-(Cenários!B81+'Análise Fluxo'!B18+'Análise Fluxo'!B19+'Análise Fluxo'!B20+'Análise Fluxo'!B22+'Análise Fluxo'!B27) -> 0 | C38: =-(Cenários!C81+'Análise Fluxo'!C18+'Análise Fluxo'!C19+'Análise Fluxo'!C20+'Análise Fluxo'!C22+'Análise Fluxo'!C27) -> 0 | D38: =-(Cenários!D81+'Análise Fluxo'!D18+'Análise Fluxo'!D19+'Análise Fluxo'!D20+'Análise Fluxo'!D22+'Análise Fluxo'!D27) -> 0 | E38: =-(Cenários!E81+'Análise Fluxo'!E18+'Análise Fluxo'!E19+'Análise Fluxo'!E20+'Análise Fluxo'!E22+'Análise Fluxo'!E27) -> 1500 | F38: =-(Cenários!F81+'Análise Fluxo'!F18+'Análise Fluxo'!F19+'Análise Fluxo'!F20+'Análise Fluxo'!F22+'Análise Fluxo'!F27) -> 2100 | G38: =-(Cenários!G81+'Análise Fluxo'!G18+'Análise Fluxo'!G19+'Análise Fluxo'!G20+'Análise Fluxo'!G22+'Análise Fluxo'!G27) -> 2100 | H38: =-(Cenários!H81+'Análise Fluxo'!H18+'Análise Fluxo'!H19+'Análise Fluxo'!H20+'Análise Fluxo'!H22+'Análise Fluxo'!H27) -> 2100 | I38: =-(Cenários!I81+'Análise Fluxo'!I18+'Análise Fluxo'!I19+'Análise Fluxo'!I20+'Análise Fluxo'!I22+'Análise Fluxo'!I27) -> 2100 | ... BI38: =-(Cenários!BI81+'Análise Fluxo'!BI18+'Análise Fluxo'!BI19+'Análise Fluxo'!BI20+'Análise Fluxo'!BI22+'Análise Fluxo'!BI27) -> 867833.7 | BJ38: =SUM(B38:BI38) -> 20521157 | BK38: Sem aquisição paga, imposto, loja e meio de pagamento: esses variam com a operação, não com a existência dela.
A39: Reserva mínima desejada | B39: =MAX(SUMPRODUCT((B$5:BI$5>B$5)*(B$5:BI$5<=B$5+Premissas!$B$118)*B$38:BI$38),Premissas!$B$118*B38) -> 1500 | C39: =MAX(SUMPRODUCT((B$5:BI$5>C$5)*(B$5:BI$5<=C$5+Premissas!$B$118)*B$38:BI$38),Premissas!$B$118*C38) -> 3600 | D39: =MAX(SUMPRODUCT((B$5:BI$5>D$5)*(B$5:BI$5<=D$5+Premissas!$B$118)*B$38:BI$38),Premissas!$B$118*D38) -> 5700 | E39: =MAX(SUMPRODUCT((B$5:BI$5>E$5)*(B$5:BI$5<=E$5+Premissas!$B$118)*B$38:BI$38),Premissas!$B$118*E38) -> 6300 | F39: =MAX(SUMPRODUCT((B$5:BI$5>F$5)*(B$5:BI$5<=F$5+Premissas!$B$118)*B$38:BI$38),Premissas!$B$118*F38) -> 6300 | G39: =MAX(SUMPRODUCT((B$5:BI$5>G$5)*(B$5:BI$5<=G$5+Premissas!$B$118)*B$38:BI$38),Premissas!$B$118*G38) -> 6300 | H39: =MAX(SUMPRODUCT((B$5:BI$5>H$5)*(B$5:BI$5<=H$5+Premissas!$B$118)*B$38:BI$38),Premissas!$B$118*H38) -> 9885.48 | I39: =MAX(SUMPRODUCT((B$5:BI$5>I$5)*(B$5:BI$5<=I$5+Premissas!$B$118)*B$38:BI$38),Premissas!$B$118*I38) -> 14437.44 | J39: =MAX(SUMPRODUCT((B$5:BI$5>J$5)*(B$5:BI$5<=J$5+Premissas!$B$118)*B$38:BI$38),Premissas!$B$118*J38) -> 20291.837 | K39: =MAX(SUMPRODUCT((B$5:BI$5>K$5)*(B$5:BI$5<=K$5+Premissas!$B$118)*B$38:BI$38),Premissas!$B$118*K38) -> 85592.006 | L39: =MAX(SUMPRODUCT((B$5:BI$5>L$5)*(B$5:BI$5<=L$5+Premissas!$B$118)*B$38:BI$38),Premissas!$B$118*L38) -> 152532.77 | M39: =MAX(SUMPRODUCT((B$5:BI$5>M$5)*(B$5:BI$5<=M$5+Premissas!$B$118)*B$38:BI$38),Premissas!$B$118*M38) -> 221144.64 | N39: =MAX(SUMPRODUCT((B$5:BI$5>N$5)*(B$5:BI$5<=N$5+Premissas!$B$118)*B$38:BI$38),Premissas!$B$118*N38) -> 228423.84 | O39: =MAX(SUMPRODUCT((B$5:BI$5>O$5)*(B$5:BI$5<=O$5+Premissas!$B$118)*B$38:BI$38),Premissas!$B$118*O38) -> 234666.99 | P39: =MAX(SUMPRODUCT((B$5:BI$5>P$5)*(B$5:BI$5<=P$5+Premissas!$B$118)*B$38:BI$38),Premissas!$B$118*P38) -> 239388.79 | Q39: =MAX(SUMPRODUCT((B$5:BI$5>Q$5)*(B$5:BI$5<=Q$5+Premissas!$B$118)*B$38:BI$38),Premissas!$B$118*Q38) -> 243755.28 | R39: =MAX(SUMPRODUCT((B$5:BI$5>R$5)*(B$5:BI$5<=R$5+Premissas!$B$118)*B$38:BI$38),Premissas!$B$118*R38) -> 247793.56 | S39: =MAX(SUMPRODUCT((B$5:BI$5>S$5)*(B$5:BI$5<=S$5+Premissas!$B$118)*B$38:BI$38),Premissas!$B$118*S38) -> 251527.64 | T39: =MAX(SUMPRODUCT((B$5:BI$5>T$5)*(B$5:BI$5<=T$5+Premissas!$B$118)*B$38:BI$38),Premissas!$B$118*T38) -> 254981.09 | U39: =MAX(SUMPRODUCT((B$5:BI$5>U$5)*(B$5:BI$5<=U$5+Premissas!$B$118)*B$38:BI$38),Premissas!$B$118*U38) -> 258174.49 | V39: =MAX(SUMPRODUCT((B$5:BI$5>V$5)*(B$5:BI$5<=V$5+Premissas!$B$118)*B$38:BI$38),Premissas!$B$118*V38) -> 261128.04 | W39: =MAX(SUMPRODUCT((B$5:BI$5>W$5)*(B$5:BI$5<=W$5+Premissas!$B$118)*B$38:BI$38),Premissas!$B$118*W38) -> 411599.86 | X39: =MAX(SUMPRODUCT((B$5:BI$5>X$5)*(B$5:BI$5<=X$5+Premissas!$B$118)*B$38:BI$38),Premissas!$B$118*X38) -> 563279.28 | Y39: =MAX(SUMPRODUCT((B$5:BI$5>Y$5)*(B$5:BI$5<=Y$5+Premissas!$B$118)*B$38:BI$38),Premissas!$B$118*Y38) -> 716086.31 | Z39: =MAX(SUMPRODUCT((B$5:BI$5>Z$5)*(B$5:BI$5<=Z$5+Premissas!$B$118)*B$38:BI$38),Premissas!$B$118*Z38) -> 722203.99 | AA39: =MAX(SUMPRODUCT((B$5:BI$5>AA$5)*(B$5:BI$5<=AA$5+Premissas!$B$118)*B$38:BI$38),Premissas!$B$118*AA38) -> 727889.96 | AB39: =MAX(SUMPRODUCT((B$5:BI$5>AB$5)*(B$5:BI$5<=AB$5+Premissas!$B$118)*B$38:BI$38),Premissas!$B$118*AB38) -> 733173.73 | AC39: =MAX(SUMPRODUCT((B$5:BI$5>AC$5)*(B$5:BI$5<=AC$5+Premissas!$B$118)*B$38:BI$38),Premissas!$B$118*AC38) -> 738083.97 | AD39: =MAX(SUMPRODUCT((B$5:BI$5>AD$5)*(B$5:BI$5<=AD$5+Premissas!$B$118)*B$38:BI$38),Premissas!$B$118*AD38) -> 742646.49 | AE39: =MAX(SUMPRODUCT((B$5:BI$5>AE$5)*(B$5:BI$5<=AE$5+Premissas!$B$118)*B$38:BI$38),Premissas!$B$118*AE38) -> 746887.53 | AF39: =MAX(SUMPRODUCT((B$5:BI$5>AF$5)*(B$5:BI$5<=AF$5+Premissas!$B$118)*B$38:BI$38),Premissas!$B$118*AF38) -> 750829.45 | AG39: =MAX(SUMPRODUCT((B$5:BI$5>AG$5)*(B$5:BI$5<=AG$5+Premissas!$B$118)*B$38:BI$38),Premissas!$B$118*AG38) -> 754492.87 | AH39: =MAX(SUMPRODUCT((B$5:BI$5>AH$5)*(B$5:BI$5<=AH$5+Premissas!$B$118)*B$38:BI$38),Premissas!$B$118*AH38) -> 757895.71 | AI39: =MAX(SUMPRODUCT((B$5:BI$5>AI$5)*(B$5:BI$5<=AI$5+Premissas!$B$118)*B$38:BI$38),Premissas!$B$118*AI38) -> 1021257.7 | AJ39: =MAX(SUMPRODUCT((B$5:BI$5>AJ$5)*(B$5:BI$5<=AJ$5+Premissas!$B$118)*B$38:BI$38),Premissas!$B$118*AJ38) -> 1286274.5 | AK39: =MAX(SUMPRODUCT((B$5:BI$5>AK$5)*(B$5:BI$5<=AK$5+Premissas!$B$118)*B$38:BI$38),Premissas!$B$118*AK38) -> 1552841.5 | AL39: =MAX(SUMPRODUCT((B$5:BI$5>AL$5)*(B$5:BI$5<=AL$5+Premissas!$B$118)*B$38:BI$38),Premissas!$B$118*AL38) -> 1560660.2 | AM39: =MAX(SUMPRODUCT((B$5:BI$5>AM$5)*(B$5:BI$5<=AM$5+Premissas!$B$118)*B$38:BI$38),Premissas!$B$118*AM38) -> 1567959.1 | AN39: =MAX(SUMPRODUCT((B$5:BI$5>AN$5)*(B$5:BI$5<=AN$5+Premissas!$B$118)*B$38:BI$38),Premissas!$B$118*AN38) -> 1574773.3 | AO39: =MAX(SUMPRODUCT((B$5:BI$5>AO$5)*(B$5:BI$5<=AO$5+Premissas!$B$118)*B$38:BI$38),Premissas!$B$118*AO38) -> 1581134.2 | AP39: =MAX(SUMPRODUCT((B$5:BI$5>AP$5)*(B$5:BI$5<=AP$5+Premissas!$B$118)*B$38:BI$38),Premissas!$B$118*AP38) -> 1587072.6 | AQ39: =MAX(SUMPRODUCT((B$5:BI$5>AQ$5)*(B$5:BI$5<=AQ$5+Premissas!$B$118)*B$38:BI$38),Premissas!$B$118*AQ38) -> 1592616.5 | AR39: =MAX(SUMPRODUCT((B$5:BI$5>AR$5)*(B$5:BI$5<=AR$5+Premissas!$B$118)*B$38:BI$38),Premissas!$B$118*AR38) -> 1597792.4 | AS39: =MAX(SUMPRODUCT((B$5:BI$5>AS$5)*(B$5:BI$5<=AS$5+Premissas!$B$118)*B$38:BI$38),Premissas!$B$118*AS38) -> 1602624.2 | AT39: =MAX(SUMPRODUCT((B$5:BI$5>AT$5)*(B$5:BI$5<=AT$5+Premissas!$B$118)*B$38:BI$38),Premissas!$B$118*AT38) -> 1607135.4 | AU39: =MAX(SUMPRODUCT((B$5:BI$5>AU$5)*(B$5:BI$5<=AU$5+Premissas!$B$118)*B$38:BI$38),Premissas!$B$118*AU38) -> 1907194.4 | AV39: =MAX(SUMPRODUCT((B$5:BI$5>AV$5)*(B$5:BI$5<=AV$5+Premissas!$B$118)*B$38:BI$38),Premissas!$B$118*AV38) -> 2209874.6 | AW39: =MAX(SUMPRODUCT((B$5:BI$5>AW$5)*(B$5:BI$5<=AW$5+Premissas!$B$118)*B$38:BI$38),Premissas!$B$118*AW38) -> 2515017.8 | AX39: =MAX(SUMPRODUCT((B$5:BI$5>AX$5)*(B$5:BI$5<=AX$5+Premissas!$B$118)*B$38:BI$38),Premissas!$B$118*AX38) -> 2526627.3 | AY39: =MAX(SUMPRODUCT((B$5:BI$5>AY$5)*(B$5:BI$5<=AY$5+Premissas!$B$118)*B$38:BI$38),Premissas!$B$118*AY38) -> 2537511.7 | AZ39: =MAX(SUMPRODUCT((B$5:BI$5>AZ$5)*(B$5:BI$5<=AZ$5+Premissas!$B$118)*B$38:BI$38),Premissas!$B$118*AZ38) -> 2547716.2 | BA39: =MAX(SUMPRODUCT((B$5:BI$5>BA$5)*(B$5:BI$5<=BA$5+Premissas!$B$118)*B$38:BI$38),Premissas!$B$118*BA38) -> 2557284 | BB39: =MAX(SUMPRODUCT((B$5:BI$5>BB$5)*(B$5:BI$5<=BB$5+Premissas!$B$118)*B$38:BI$38),Premissas!$B$118*BB38) -> 2566253.7 | BC39: =MAX(SUMPRODUCT((B$5:BI$5>BC$5)*(B$5:BI$5<=BC$5+Premissas!$B$118)*B$38:BI$38),Premissas!$B$118*BC38) -> 2574663.4 | BD39: =MAX(SUMPRODUCT((B$5:BI$5>BD$5)*(B$5:BI$5<=BD$5+Premissas!$B$118)*B$38:BI$38),Premissas!$B$118*BD38) -> 2582547.2 | BE39: =MAX(SUMPRODUCT((B$5:BI$5>BE$5)*(B$5:BI$5<=BE$5+Premissas!$B$118)*B$38:BI$38),Premissas!$B$118*BE38) -> 2589938.9 | BF39: =MAX(SUMPRODUCT((B$5:BI$5>BF$5)*(B$5:BI$5<=BF$5+Premissas!$B$118)*B$38:BI$38),Premissas!$B$118*BF38) -> 2596868.6 | BG39: =MAX(SUMPRODUCT((B$5:BI$5>BG$5)*(B$5:BI$5<=BG$5+Premissas!$B$118)*B$38:BI$38),Premissas!$B$118*BG38) -> 2590091.8 | BH39: =MAX(SUMPRODUCT((B$5:BI$5>BH$5)*(B$5:BI$5<=BH$5+Premissas!$B$118)*B$38:BI$38),Premissas!$B$118*BH38) -> 2597013 | BI39: =MAX(SUMPRODUCT((B$5:BI$5>BI$5)*(B$5:BI$5<=BI$5+Premissas!$B$118)*B$38:BI$38),Premissas!$B$118*BI38) -> 2603501.1 | BK39: Custo fixo dos próximos meses. Nos últimos meses do horizonte não há 'próximos', então cai para o custo fixo do mês vezes o número de meses — senão a reserva sumiria justamente onde a empresa é maior.
A40: Caixa projetado no fim do mês | B40: =Cenários!B95 -> 0 | C40: =Cenários!C95 -> 0 | D40: =Cenários!D95 -> 0 | E40: =Cenários!E95 -> 8500 | F40: =Cenários!F95 -> 400 | G40: =Cenários!G95 -> -1700 | H40: =Cenários!H95 -> 1200 | I40: =Cenários!I95 -> 7972.18 | ... BI40: =Cenários!BI95 -> 18105908
A41: Caixa acima (ou abaixo) da reserva | B41: =B40-B39 -> -1500 | C41: =C40-C39 -> -3600 | D41: =D40-D39 -> -5700 | E41: =E40-E39 -> 2200 | F41: =F40-F39 -> -5900 | G41: =G40-G39 -> -8000 | H41: =H40-H39 -> -8685.48 | I41: =I40-I39 -> -6465.26 | ... BI41: =BI40-BI39 -> 15502406 | BK41: Negativo aqui já é sinal amarelo, mesmo com o caixa no positivo.
A42: FALTA CAPTAR neste mês | B42: =MAX(0,B39-B40) -> 1500 | C42: =MAX(0,C39-C40) -> 3600 | D42: =MAX(0,D39-D40) -> 5700 | E42: =MAX(0,E39-E40) -> 0 | F42: =MAX(0,F39-F40) -> 5900 | G42: =MAX(0,G39-G40) -> 8000 | H42: =MAX(0,H39-H40) -> 8685.48 | I42: =MAX(0,I39-I40) -> 6465.26 | ... BI42: =MAX(0,BI39-BI40) -> 0 | BK42: Quanto teria de estar em caixa neste mês e não está.
A43: FALTA CAPTAR — pior caso até aqui (cronograma de captação) | B43: =MAX($B42:B42) -> 1500 | C43: =MAX($B42:C42) -> 3600 | D43: =MAX($B42:D42) -> 5700 | E43: =MAX($B42:E42) -> 5700 | F43: =MAX($B42:F42) -> 5900 | G43: =MAX($B42:G42) -> 8000 | H43: =MAX($B42:H42) -> 8685.48 | I43: =MAX($B42:I42) -> 8685.48 | ... BI43: =MAX($B42:BI42) -> 423788.68 | BK43: Só sobe. É a meta de captação que precisa estar fechada até este mês.
A44: Marcador — mês com caixa negativo | B44: =IF(B40<0,B$5,9999) -> 9999 | C44: =IF(C40<0,C$5,9999) -> 9999 | D44: =IF(D40<0,D$5,9999) -> 9999 | E44: =IF(E40<0,E$5,9999) -> 9999 | F44: =IF(F40<0,F$5,9999) -> 9999 | G44: =IF(G40<0,G$5,9999) -> 6 | H44: =IF(H40<0,H$5,9999) -> 9999 | I44: =IF(I40<0,I$5,9999) -> 9999 | ... BI44: =IF(BI40<0,BI$5,9999) -> 9999 | BK44: Auxiliar: guarda o nº do mês quando o caixa fica negativo. O menor valor é o primeiro mês sem fundo.
...

Sheet Preço Mínimo
A1: PREÇO MÍNIMO — DO CUSTO PARA O PREÇO
A2: =" Cenário ativo: "&Premissas!B7 -> Cenário ativo: PROVÁVEL
A4: Linha do tempo | B4: 46023 | C4: 46054 | D4: 46082 | E4: 46113 | F4: 46143 | G4: 46174 | H4: 46204 | I4: 46235 | J4: 46266 | K4: 46296 | L4: 46327 | M4: 46357 | N4: 46388 | O4: 46419 | P4: 46447 | Q4: 46478 | R4: 46508 | S4: 46539 | T4: 46569 | U4: 46600 | V4: 46631 | W4: 46661 | X4: 46692 | Y4: 46722 | Z4: 46753 | AA4: 46784 | AB4: 46813 | AC4: 46844 | AD4: 46874 | AE4: 46905 | AF4: 46935 | AG4: 46966 | AH4: 46997 | AI4: 47027 | AJ4: 47058 | AK4: 47088 | AL4: 47119 | AM4: 47150 | AN4: 47178 | AO4: 47209 | AP4: 47239 | AQ4: 47270 | AR4: 47300 | AS4: 47331 | AT4: 47362 | AU4: 47392 | AV4: 47423 | AW4: 47453 | AX4: 47484 | AY4: 47515 | AZ4: 47543 | BA4: 47574 | BB4: 47604 | BC4: 47635 | BD4: 47665 | BE4: 47696 | BF4: 47727 | BG4: 47757 | BH4: 47788 | BI4: 47818 | BJ4: TOTAL | BK4: % / Nota
A5: Mês nº | B5: 1 | C5: 2 | D5: 3 | E5: 4 | F5: 5 | G5: 6 | H5: 7 | I5: 8 | J5: 9 | K5: 10 | L5: 11 | M5: 12 | N5: 13 | O5: 14 | P5: 15 | Q5: 16 | R5: 17 | S5: 18 | T5: 19 | U5: 20 | V5: 21 | W5: 22 | X5: 23 | Y5: 24 | Z5: 25 | AA5: 26 | AB5: 27 | AC5: 28 | AD5: 29 | AE5: 30 | AF5: 31 | AG5: 32 | AH5: 33 | AI5: 34 | AJ5: 35 | AK5: 36 | AL5: 37 | AM5: 38 | AN5: 39 | AO5: 40 | AP5: 41 | AQ5: 42 | AR5: 43 | AS5: 44 | AT5: 45 | AU5: 46 | AV5: 47 | AW5: 48 | AX5: 49 | AY5: 50 | AZ5: 51 | BA5: 52 | BB5: 53 | BC5: 54 | BD5: 55 | BE5: 56 | BF5: 57 | BG5: 58 | BH5: 59 | BI5: 60
A6: Ano | B6: =YEAR(B4) -> 2026 | C6: =YEAR(C4) -> 2026 | D6: =YEAR(D4) -> 2026 | E6: =YEAR(E4) -> 2026 | F6: =YEAR(F4) -> 2026 | G6: =YEAR(G4) -> 2026 | H6: =YEAR(H4) -> 2026 | I6: =YEAR(I4) -> 2026 | ... BI6: =YEAR(BI4) -> 2030
A7: Índice do ano (auxiliar) | B7: =MATCH(B6,Premissas!$C$5:$G$5,0) -> 1 | C7: =MATCH(C6,Premissas!$C$5:$G$5,0) -> 1 | D7: =MATCH(D6,Premissas!$C$5:$G$5,0) -> 1 | E7: =MATCH(E6,Premissas!$C$5:$G$5,0) -> 1 | F7: =MATCH(F6,Premissas!$C$5:$G$5,0) -> 1 | G7: =MATCH(G6,Premissas!$C$5:$G$5,0) -> 1 | H7: =MATCH(H6,Premissas!$C$5:$G$5,0) -> 1 | I7: =MATCH(I6,Premissas!$C$5:$G$5,0) -> 1 | ... BI7: =MATCH(BI6,Premissas!$C$5:$G$5,0) -> 5
A8: 1. QUEM PAGA, E QUANTO PAGA HOJE
A9: Assinantes pagantes | B9: =CHOOSE(Premissas!$B$6,Cenários!B15,Cenários!B61,Cenários!B107) -> 0 | C9: =CHOOSE(Premissas!$B$6,Cenários!C15,Cenários!C61,Cenários!C107) -> 0 | D9: =CHOOSE(Premissas!$B$6,Cenários!D15,Cenários!D61,Cenários!D107) -> 0 | E9: =CHOOSE(Premissas!$B$6,Cenários!E15,Cenários!E61,Cenários!E107) -> 0 | F9: =CHOOSE(Premissas!$B$6,Cenários!F15,Cenários!F61,Cenários!F107) -> 0 | G9: =CHOOSE(Premissas!$B$6,Cenários!G15,Cenários!G61,Cenários!G107) -> 0 | H9: =CHOOSE(Premissas!$B$6,Cenários!H15,Cenários!H61,Cenários!H107) -> 0 | I9: =CHOOSE(Premissas!$B$6,Cenários!I15,Cenários!I61,Cenários!I107) -> 0 | ... BI9: =CHOOSE(Premissas!$B$6,Cenários!BI15,Cenários!BI61,Cenários!BI107) -> 75973
A10: Pagantes — Essencial | B10: =CHOOSE(Premissas!$B$6,Cenários!B16,Cenários!B62,Cenários!B108) -> 0 | C10: =CHOOSE(Premissas!$B$6,Cenários!C16,Cenários!C62,Cenários!C108) -> 0 | D10: =CHOOSE(Premissas!$B$6,Cenários!D16,Cenários!D62,Cenários!D108) -> 0 | E10: =CHOOSE(Premissas!$B$6,Cenários!E16,Cenários!E62,Cenários!E108) -> 0 | F10: =CHOOSE(Premissas!$B$6,Cenários!F16,Cenários!F62,Cenários!F108) -> 0 | G10: =CHOOSE(Premissas!$B$6,Cenários!G16,Cenários!G62,Cenários!G108) -> 0 | H10: =CHOOSE(Premissas!$B$6,Cenários!H16,Cenários!H62,Cenários!H108) -> 0 | I10: =CHOOSE(Premissas!$B$6,Cenários!I16,Cenários!I62,Cenários!I108) -> 0 | ... BI10: =CHOOSE(Premissas!$B$6,Cenários!BI16,Cenários!BI62,Cenários!BI108) -> 45584
A11: Pagantes — Premium | B11: =CHOOSE(Premissas!$B$6,Cenários!B17,Cenários!B63,Cenários!B109) -> 0 | C11: =CHOOSE(Premissas!$B$6,Cenários!C17,Cenários!C63,Cenários!C109) -> 0 | D11: =CHOOSE(Premissas!$B$6,Cenários!D17,Cenários!D63,Cenários!D109) -> 0 | E11: =CHOOSE(Premissas!$B$6,Cenários!E17,Cenários!E63,Cenários!E109) -> 0 | F11: =CHOOSE(Premissas!$B$6,Cenários!F17,Cenários!F63,Cenários!F109) -> 0 | G11: =CHOOSE(Premissas!$B$6,Cenários!G17,Cenários!G63,Cenários!G109) -> 0 | H11: =CHOOSE(Premissas!$B$6,Cenários!H17,Cenários!H63,Cenários!H109) -> 0 | I11: =CHOOSE(Premissas!$B$6,Cenários!I17,Cenários!I63,Cenários!I109) -> 0 | ... BI11: =CHOOSE(Premissas!$B$6,Cenários!BI17,Cenários!BI63,Cenários!BI109) -> 21272 | BK11: Zero até o mês de entrada do plano, definido em Premissas.
A12: Pagantes — Família | B12: =CHOOSE(Premissas!$B$6,Cenários!B18,Cenários!B64,Cenários!B110) -> 0 | C12: =CHOOSE(Premissas!$B$6,Cenários!C18,Cenários!C64,Cenários!C110) -> 0 | D12: =CHOOSE(Premissas!$B$6,Cenários!D18,Cenários!D64,Cenários!D110) -> 0 | E12: =CHOOSE(Premissas!$B$6,Cenários!E18,Cenários!E64,Cenários!E110) -> 0 | F12: =CHOOSE(Premissas!$B$6,Cenários!F18,Cenários!F64,Cenários!F110) -> 0 | G12: =CHOOSE(Premissas!$B$6,Cenários!G18,Cenários!G64,Cenários!G110) -> 0 | H12: =CHOOSE(Premissas!$B$6,Cenários!H18,Cenários!H64,Cenários!H110) -> 0 | I12: =CHOOSE(Premissas!$B$6,Cenários!I18,Cenários!I64,Cenários!I110) -> 0 | ... BI12: =CHOOSE(Premissas!$B$6,Cenários!BI18,Cenários!BI64,Cenários!BI110) -> 9117
A13: Preço do Essencial vigente no mês | B13: =Premissas!$B$29*(1+Premissas!$B$32)^(B$6-2026) -> 19.9 | C13: =Premissas!$B$29*(1+Premissas!$B$32)^(C$6-2026) -> 19.9 | D13: =Premissas!$B$29*(1+Premissas!$B$32)^(D$6-2026) -> 19.9 | E13: =Premissas!$B$29*(1+Premissas!$B$32)^(E$6-2026) -> 19.9 | F13: =Premissas!$B$29*(1+Premissas!$B$32)^(F$6-2026) -> 19.9 | G13: =Premissas!$B$29*(1+Premissas!$B$32)^(G$6-2026) -> 19.9 | H13: =Premissas!$B$29*(1+Premissas!$B$32)^(H$6-2026) -> 19.9 | I13: =Premissas!$B$29*(1+Premissas!$B$32)^(I$6-2026) -> 19.9 | ... BI13: =Premissas!$B$29*(1+Premissas!$B$32)^(BI$6-2026) -> 23.73112
A14: Premium ÷ Essencial | B14: =IFERROR(Premissas!$B$30/Premissas!$B$29,0) -> 2.0050251 | C14: =IFERROR(Premissas!$B$30/Premissas!$B$29,0) -> 2.0050251 | D14: =IFERROR(Premissas!$B$30/Premissas!$B$29,0) -> 2.0050251 | E14: =IFERROR(Premissas!$B$30/Premissas!$B$29,0) -> 2.0050251 | F14: =IFERROR(Premissas!$B$30/Premissas!$B$29,0) -> 2.0050251 | G14: =IFERROR(Premissas!$B$30/Premissas!$B$29,0) -> 2.0050251 | H14: =IFERROR(Premissas!$B$30/Premissas!$B$29,0) -> 2.0050251 | I14: =IFERROR(Premissas!$B$30/Premissas!$B$29,0) -> 2.0050251 | ... BI14: =IFERROR(Premissas!$B$30/Premissas!$B$29,0) -> 2.0050251 | BK14: A razão entre os preços. É o que permite traduzir todo mundo em Essencial.
A15: Família ÷ Essencial | B15: =IFERROR(Premissas!$B$31/Premissas!$B$29,0) -> 4.0150754 | C15: =IFERROR(Premissas!$B$31/Premissas!$B$29,0) -> 4.0150754 | D15: =IFERROR(Premissas!$B$31/Premissas!$B$29,0) -> 4.0150754 | E15: =IFERROR(Premissas!$B$31/Premissas!$B$29,0) -> 4.0150754 | F15: =IFERROR(Premissas!$B$31/Premissas!$B$29,0) -> 4.0150754 | G15: =IFERROR(Premissas!$B$31/Premissas!$B$29,0) -> 4.0150754 | H15: =IFERROR(Premissas!$B$31/Premissas!$B$29,0) -> 4.0150754 | I15: =IFERROR(Premissas!$B$31/Premissas!$B$29,0) -> 4.0150754 | ... BI15: =IFERROR(Premissas!$B$31/Premissas!$B$29,0) -> 4.0150754
A16: Assinantes equivalentes a Essencial (unidades equivalentes) | B16: =B10+B11*B14+B12*B15 -> 0 | C16: =C10+C11*C14+C12*C15 -> 0 | D16: =D10+D11*D14+D12*D15 -> 0 | E16: =E10+E11*E14+E12*E15 -> 0 | F16: =F10+F11*F14+F12*F15 -> 0 | G16: =G10+G11*G14+G12*G15 -> 0 | H16: =H10+H11*H14+H12*H15 -> 0 | I16: =I10+I11*I14+I12*I15 -> 0 | ... BI16: =BI10+BI11*BI14+BI12*BI15 -> 124840.34 | BK16: Receita de assinatura = preço do Essencial × esta linha. É a unidade da conta.
