Workbook

Sheet Começar aqui
A1: OPPA — COMEÇAR AQUI
A2: Cinco abas. Você digita em três.
B4: O QUE MUDOU EM RELAÇÃO À VERSÃO ANTERIOR
B5: • Não existe mais premissa anual em lugar nenhum. Toda premissa é mensal: você dá o valor inicial, a evolução por mês e o mês em que a coisa começa.
B6: • O custo de nuvem deixou de ser um número por usuário e passou a ser uma CONTA mensal que você ancora em alguns tamanhos de base. O custo por usuário é consequência, e cai com a escala.
B7: • A DRE virou uma aba só, com os drivers dentro dela. Você não precisa mais ir e voltar entre abas para mudar uma premissa e ver o efeito.
B8: • Treze abas viraram cinco.
B10: AS CINCO ABAS
B11: ABA | C11: PARA QUE SERVE | D11: VOCÊ DIGITA?
B12: Resumo | C12: A resposta. Começa com quanto a empresa precisa de dinheiro. Troque o cenário aqui: um número, e o modelo inteiro responde. | D12: cenário e TMA
B13: DRE Mensal | C13: O modelo. Uma coluna por mês, de jan/2026 a dez/2030. Dos drivers ao EBITDA ao caixa, tudo em uma aba só. | D13: SIM — colunas B, C e D
B14: Nuvem e Escala | C14: A conta de nuvem. Você digita a conta mensal esperada em cada tamanho de base; o custo por usuário sai dividido e cai com a escala. | D14: SIM — coluna B
B15: Equipe | C15: Uma linha por papel, com mês de entrada e de saída. | D15: SIM
B16: Aportes | C16: Todo o capital, com o status de cada linha. | D16: SIM
B18: COMO FUNCIONA UMA LINHA DE PREMISSA, NA DRE MENSAL
B19: • Coluna B — valor inicial: quanto vale no primeiro mês em que a coisa existe.
B20: • Coluna C — evolução por mês: quanto cresce ou cai a cada mês. 3% é 3% ao mês, não ao ano.
B21: • Coluna D — mês de início: 1 é jan/2026, 12 é dez/2026, 60 é dez/2030. Antes disso a linha vale zero.
B22: • E o mais útil: digite um número POR CIMA de qualquer mês e a curva passa a contar dali. Cada mês lê o mês anterior, então mexer em março muda abril até dezembro de 2030 — e não mexe em janeiro e fevereiro.
B24: AS CORES DAS CÉLULAS
B25: Azul com fundo creme | C25: você digita.
B26: Azul com fundo amarelo | C26: você digita, e esta mexe muito no resultado.
B27: Preto | C27: calculado na própria aba.
B28: Verde | C28: vem de outra aba. Mude na origem.
B30: SE ALGUM NÚMERO PARECER ERRADO
B31: O Resumo tem um bloco de conferências no fim. As duas primeiras linhas têm de ser zero e a terceira tem de dizer 'monotônica'. Se saírem disso, alguma fórmula foi sobrescrita por um valor digitado — desfaça a última edição.
B32: A DRE Mensal traz as mesmas conferências na seção 7, mês a mês, para você achar em qual mês o problema está.

Sheet Resumo
A1: OPPA — VIABILIDADE FINANCEIRA
A2: Projeção mensal de jan/2026 a dez/2030. Tudo vem de fórmula — nenhum número desta aba é digitado à mão.
A4: CENÁRIO — troque o número e o modelo inteiro responde
B5: Cenário ativo 1 = Conservador · 2 = Provável · 3 = Agressivo | C5: 2 | D5: =CHOOSE($C$5,"CONSERVADOR","PROVÁVEL","AGRESSIVO") -> PROVÁVEL
B7: Como cada cenário mexe nos drivers | C7: Multiplicador aplicado ao driver | D7: CONSERVADOR | E7: PROVÁVEL | F7: AGRESSIVO
C8: captação de usuários | D8: 0.6 | E8: 1 | F8: 1.5
C9: conversão em pagante | D9: 0.6 | E9: 1 | F9: 1.5
C10: churn | D10: 1.3 | E10: 1 | F10: 0.8
B11: São multiplicadores, não valores: 0,60x significa captar 60% do que está na aba DRE Mensal. Edite à vontade — é só isto que separa os três cenários.
B13: 1. QUANTO A EMPRESA PRECISA DE DINHEIRO
B14: QUANTO AINDA FALTA CAPTAR | C14: ='DRE Mensal'!$BL$75 -> 9036466.9 | H14: A resposta curta. É o pior mês de toda a projeção: quanto teria de estar em caixa e não está, já contando a reserva mínima e já descontando os aportes que a aba Aportes considera. Detalhe mês a mês na DRE Mensal, seção 6.
B15: Até quando o dinheiro precisa estar na conta | C15: =IF(MIN('DRE Mensal'!$E$76:$BL$76)=9999,"o caixa nunca fica negativo",CHOOSE(MOD(MIN('DRE Mensal'!$E$76:$BL$76)-1,12)+1,"jan","fev","mar","abr","mai","jun","jul","ago","set","out","nov","dez")&"/"&(2026+INT((MIN('DRE Mensal'!$E$76:$BL$76)-1)/12))) -> jan/2027 | H15: Primeiro mês em que o caixa fica negativo. É o prazo que não se negocia.
B16: O que a operação consome antes de se sustentar | C16: =-MIN(0,MIN('DRE Mensal'!$E$67:$BL$67)) -> 7890553 | H16: Fundo do poço do fluxo de caixa livre acumulado. Independe de quando o dinheiro entra.
B17: (+) Reserva de caixa no mês mais apertado | C17: =INDEX('DRE Mensal'!$E$73:$BL$73,MATCH(MIN('DRE Mensal'!$E$70:$BL$70),'DRE Mensal'!$E$70:$BL$70,0)) -> 1452813.8
B18: (=) Necessidade total de capital | C18: =$C$16+$C$17 -> 9343366.8
B19: (−) Capital que a aba Aportes considera | C19: =-Aportes!$B$63 -> -317000
B20: do qual já entrou de verdade (Realizado) | C20: =Aportes!$B$58 -> 37000 | H20: O resto depende de assinatura. Desligue os interruptores na aba Aportes para ver a empresa só com o dinheiro que já está na conta.
B21: (=) Falta captar, ignorando as datas de entrada | C21: =MAX(0,$C$18+$C$19) -> 9026366.8 | H21: Serve para dimensionar a rodada. A linha grande lá em cima é maior quando parte do capital chega depois do mês em que o caixa aperta.
B22: Caixa mínimo projetado | C22: =MIN('DRE Mensal'!$E$70:$BL$70) -> -7573553
B23: Mês do caixa mínimo | C23: =CHOOSE(MOD(MATCH(MIN('DRE Mensal'!$E$70:$BL$70),'DRE Mensal'!$E$70:$BL$70,0)-1,12)+1,"jan","fev","mar","abr","mai","jun","jul","ago","set","out","nov","dez")&"/"&(2026+INT((MATCH(MIN('DRE Mensal'!$E$70:$BL$70),'DRE Mensal'!$E$70:$BL$70,0)-1)/12)) -> out/2030
B25: 2. O NEGÓCIO
B26: Base de usuários em dez/2030 | C26: ='DRE Mensal'!$BL$24 -> 928425
B27: Assinantes pagantes em dez/2030 | C27: ='DRE Mensal'!$BL$25 -> 30501
B28: % da base que paga em dez/2030 | C28: ='DRE Mensal'!$BL$27 -> 0.032852411
B29: Faturamento bruto de 2027 | C29: =SUMIFS('DRE Mensal'!$E$33:$BL$33,'DRE Mensal'!$E$6:$BL$6,2027) -> 438506.3
B30: Faturamento bruto de 2030 | C30: =SUMIFS('DRE Mensal'!$E$33:$BL$33,'DRE Mensal'!$E$6:$BL$6,2030) -> 9983409.3
B31: Faturamento bruto acumulado em 5 anos | C31: =SUM('DRE Mensal'!$E$33:$BL$33) -> 15911219
B32: EBITDA acumulado em 5 anos | C32: =SUM('DRE Mensal'!$E$59:$BL$59) -> -7821397.4
B33: Margem EBITDA em dez/2030 | C33: ='DRE Mensal'!$BL$60 -> 0.053245439
B34: Primeiro mês com EBITDA positivo | C34: =IF(MIN('DRE Mensal'!$E$77:$BL$77)=9999,"não atinge",CHOOSE(MOD(MIN('DRE Mensal'!$E$77:$BL$77)-1,12)+1,"jan","fev","mar","abr","mai","jun","jul","ago","set","out","nov","dez")&"/"&(2026+INT((MIN('DRE Mensal'!$E$77:$BL$77)-1)/12))) -> nov/2030 | H34: Quando a operação passa a se pagar. Antes disso, cada mês é financiado por capital.
B36: 3. PREÇO E CUSTO POR ASSINANTE — em dez/2030
B37: Preço médio por assinante | C37: ='DRE Mensal'!$BL$18 -> 39.9
B38: Fica para a empresa, de cada R$ 1 faturado | C38: ='DRE Mensal'!$BL$43 -> 0.73143137 | H38: O resto é imposto, comissão de loja e meio de pagamento.
B39: Custo de nuvem por assinante pagante | C39: ='DRE Mensal'!$BL$48 -> 3.2907766 | H39: A conta inteira de nuvem dividida pelos pagantes — inclui o que o plano gratuito consome. Cai com a escala: no lançamento é muito maior.
B40: do qual é subsídio do plano gratuito | C40: ='DRE Mensal'!$BL$49 -> 2.4563808 | H40: O que cada assinante paga, sem saber, para sustentar quem não paga. No mês do lançamento este número passa do próprio preço da assinatura.
B41: Custo variável por assinante (nuvem e suporte) | C41: ='DRE Mensal'!$BL$83 -> 3.5659307
B42: Sobra por assinante antes do custo fixo | C42: ='DRE Mensal'!$BL$84 -> 25.618181 | H42: Se for negativa, cada assinante novo dá prejuízo e nenhum volume resolve.
B43: CAC por assinante pagante conquistado | C43: ='DRE Mensal'!$BL$81 -> 116.98918
B44: Assinantes necessários para o mês fechar no zero | C44: ='DRE Mensal'!$BL$85 -> 32705
B45: Assinantes projetados | C45: ='DRE Mensal'!$BL$25 -> 30501
...

Sheet DRE Mensal
A1: DRE MENSAL — DOS DRIVERS AO RESULTADO, EM UMA ABA
A2: Uma coluna por mês, de jan/2026 a dez/2030. Você digita nas colunas B, C e D — e pode digitar por cima de qualquer mês. Nada aqui é anual.
A4: Linha do tempo | B4: valor inicial | C4: evolução/mês | D4: mês de início | E4: 46023 | F4: 46054 | G4: 46082 | H4: 46113 | I4: 46143 | J4: 46174 | K4: 46204 | L4: 46235 | M4: 46266 | N4: 46296 | O4: 46327 | P4: 46357 | Q4: 46388 | R4: 46419 | S4: 46447 | T4: 46478 | U4: 46508 | V4: 46539 | W4: 46569 | X4: 46600 | Y4: 46631 | Z4: 46661 | AA4: 46692 | AB4: 46722 | AC4: 46753 | AD4: 46784 | AE4: 46813 | AF4: 46844 | AG4: 46874 | AH4: 46905 | AI4: 46935 | AJ4: 46966 | AK4: 46997 | AL4: 47027 | AM4: 47058 | AN4: 47088 | AO4: 47119 | AP4: 47150 | AQ4: 47178 | AR4: 47209 | AS4: 47239 | AT4: 47270 | AU4: 47300 | AV4: 47331 | AW4: 47362 | AX4: 47392 | AY4: 47423 | AZ4: 47453 | BA4: 47484 | BB4: 47515 | BC4: 47543 | BD4: 47574 | BE4: 47604 | BF4: 47635 | BG4: 47665 | BH4: 47696 | BI4: 47727 | BJ4: 47757 | BK4: 47788 | BL4: 47818 | BM4: TOTAL | BN4: O que é / como mexer
A5: Mês nº | E5: 1 | F5: 2 | G5: 3 | H5: 4 | I5: 5 | J5: 6 | K5: 7 | L5: 8 | M5: 9 | N5: 10 | O5: 11 | P5: 12 | Q5: 13 | R5: 14 | S5: 15 | T5: 16 | U5: 17 | V5: 18 | W5: 19 | X5: 20 | Y5: 21 | Z5: 22 | AA5: 23 | AB5: 24 | AC5: 25 | AD5: 26 | AE5: 27 | AF5: 28 | AG5: 29 | AH5: 30 | AI5: 31 | AJ5: 32 | AK5: 33 | AL5: 34 | AM5: 35 | AN5: 36 | AO5: 37 | AP5: 38 | AQ5: 39 | AR5: 40 | AS5: 41 | AT5: 42 | AU5: 43 | AV5: 44 | AW5: 45 | AX5: 46 | AY5: 47 | AZ5: 48 | BA5: 49 | BB5: 50 | BC5: 51 | BD5: 52 | BE5: 53 | BF5: 54 | BG5: 55 | BH5: 56 | BI5: 57 | BJ5: 58 | BK5: 59 | BL5: 60
A6: Ano | E6: =YEAR(E4) -> 2026 | F6: =YEAR(F4) -> 2026 | G6: =YEAR(G4) -> 2026 | H6: =YEAR(H4) -> 2026 | I6: =YEAR(I4) -> 2026 | J6: =YEAR(J4) -> 2026 | K6: =YEAR(K4) -> 2026 | L6: =YEAR(L4) -> 2026 | ... BL6: =YEAR(BL4) -> 2030
A8: 1. CENÁRIO ATIVO — troque no Resumo e esta aba inteira responde
A9: Cenário em uso | B9: =Resumo!$C$5 -> 2 | C9: =CHOOSE($B9,"CONSERVADOR","PROVÁVEL","AGRESSIVO") -> PROVÁVEL | F9: O número e os três multiplicadores abaixo estão na aba Resumo, no alto. Trocar um número só muda o modelo inteiro.
A10: Multiplicador do cenário — captação de usuários | B10: =INDEX(Resumo!$D$8:$F$10,MATCH("captação de usuários",Resumo!$C$8:$C$10,0),$B$9) -> 1
A11: Multiplicador do cenário — conversão em pagante | B11: =INDEX(Resumo!$D$8:$F$10,MATCH("conversão em pagante",Resumo!$C$8:$C$10,0),$B$9) -> 1
A12: Multiplicador do cenário — churn | B12: =INDEX(Resumo!$D$8:$F$10,MATCH("churn",Resumo!$C$8:$C$10,0),$B$9) -> 1
A14: 2. DRIVERS DO NEGÓCIO — digite em B (valor inicial), C (evolução por mês) e D (mês de início)
A15: Novos usuários captados no mês | B15: 18100 | C15: 0.034 | D15: 12 | E15: =IF(E$5<$D15,0,$B15) -> 0 | F15: =IF(F$5<$D15,0,IF(E15=0,$B15,E15*(1+$C15))) -> 0 | G15: =IF(G$5<$D15,0,IF(F15=0,$B15,F15*(1+$C15))) -> 0 | H15: =IF(H$5<$D15,0,IF(G15=0,$B15,G15*(1+$C15))) -> 0 | I15: =IF(I$5<$D15,0,IF(H15=0,$B15,H15*(1+$C15))) -> 0 | J15: =IF(J$5<$D15,0,IF(I15=0,$B15,I15*(1+$C15))) -> 0 | K15: =IF(K$5<$D15,0,IF(J15=0,$B15,J15*(1+$C15))) -> 0 | L15: =IF(L$5<$D15,0,IF(K15=0,$B15,K15*(1+$C15))) -> 0 | M15: =IF(M$5<$D15,0,IF(L15=0,$B15,L15*(1+$C15))) -> 0 | ... BL15: =IF(BL$5<$D15,0,IF(BK15=0,$B15,BK15*(1+$C15))) -> 90087.479 | BM15: =BL15 -> 90087.479 | BN15: Mês 12 = dez/2026, o lançamento. 18.100 no primeiro mês crescendo 3,4% ao mês chega a ~89 mil/mês em dez/2030 — a mesma trajetória que você vinha usando. Digite por cima de qualquer mês para ancorar a curva ali.
A16: Churn mensal da base de usuários | B16: 0.08 | C16: -0.005 | D16: 12 | E16: =IF(E$5<$D16,0,$B16) -> 0 | F16: =IF(F$5<$D16,0,IF(E16=0,$B16,E16*(1+$C16))) -> 0 | G16: =IF(G$5<$D16,0,IF(F16=0,$B16,F16*(1+$C16))) -> 0 | H16: =IF(H$5<$D16,0,IF(G16=0,$B16,G16*(1+$C16))) -> 0 | I16: =IF(I$5<$D16,0,IF(H16=0,$B16,H16*(1+$C16))) -> 0 | J16: =IF(J$5<$D16,0,IF(I16=0,$B16,I16*(1+$C16))) -> 0 | K16: =IF(K$5<$D16,0,IF(J16=0,$B16,J16*(1+$C16))) -> 0 | L16: =IF(L$5<$D16,0,IF(K16=0,$B16,K16*(1+$C16))) -> 0 | M16: =IF(M$5<$D16,0,IF(L16=0,$B16,L16*(1+$C16))) -> 0 | ... BL16: =IF(BL$5<$D16,0,IF(BK16=0,$B16,BK16*(1+$C16))) -> 0.062892356 | BM16: =BL16 -> 0.062892356 | BN16: 8% no lançamento caindo 0,5% ao mês (relativo) chega a 6,3% em 2030. Health/fitness roda entre 7% e 10% ao mês no primeiro ano.
A17: Conversão da base em assinante pagante | B17: 0.005 | C17: 0.04 | D17: 12 | E17: =IF(E$5<$D17,0,MIN(0.5,$B17)) -> 0 | F17: =IF(F$5<$D17,0,MIN(0.5,IF(E17=0,$B17,E17*(1+$C17)))) -> 0 | G17: =IF(G$5<$D17,0,MIN(0.5,IF(F17=0,$B17,F17*(1+$C17)))) -> 0 | H17: =IF(H$5<$D17,0,MIN(0.5,IF(G17=0,$B17,G17*(1+$C17)))) -> 0 | I17: =IF(I$5<$D17,0,MIN(0.5,IF(H17=0,$B17,H17*(1+$C17)))) -> 0 | J17: =IF(J$5<$D17,0,MIN(0.5,IF(I17=0,$B17,I17*(1+$C17)))) -> 0 | K17: =IF(K$5<$D17,0,MIN(0.5,IF(J17=0,$B17,J17*(1+$C17)))) -> 0 | L17: =IF(L$5<$D17,0,MIN(0.5,IF(K17=0,$B17,K17*(1+$C17)))) -> 0 | M17: =IF(M$5<$D17,0,MIN(0.5,IF(L17=0,$B17,L17*(1+$C17)))) -> 0 | ... BL17: =IF(BL$5<$D17,0,MIN(0.5,IF(BK17=0,$B17,BK17*(1+$C17)))) -> 0.032852641 | BM17: =BL17 -> 0.032852641 | BN17: 0,5% no lançamento crescendo 4% ao mês: 0,8% em um ano, 3,3% em dez/2030. Isto substitui a rampa de maturação da versão anterior — aqui a rampa é a própria curva. Mediana de freemium é 2% a 3%; o quartil de cima chega a 8%.
A18: Preço médio por assinante no mês (R$) | B18: 39.9 | C18: 0 | D18: 12 | E18: =IF(E$5<$D18,0,$B18) -> 0 | F18: =IF(F$5<$D18,0,IF(E18=0,$B18,E18*(1+$C18))) -> 0 | G18: =IF(G$5<$D18,0,IF(F18=0,$B18,F18*(1+$C18))) -> 0 | H18: =IF(H$5<$D18,0,IF(G18=0,$B18,G18*(1+$C18))) -> 0 | I18: =IF(I$5<$D18,0,IF(H18=0,$B18,H18*(1+$C18))) -> 0 | J18: =IF(J$5<$D18,0,IF(I18=0,$B18,I18*(1+$C18))) -> 0 | K18: =IF(K$5<$D18,0,IF(J18=0,$B18,J18*(1+$C18))) -> 0 | L18: =IF(L$5<$D18,0,IF(K18=0,$B18,K18*(1+$C18))) -> 0 | M18: =IF(M$5<$D18,0,IF(L18=0,$B18,L18*(1+$C18))) -> 0 | ... BL18: =IF(BL$5<$D18,0,IF(BK18=0,$B18,BK18*(1+$C18))) -> 39.9 | BM18: =BL18 -> 39.9 | BN18: A média ponderada do que cada pagante paga. Com um plano só, é o preço dele. Ponha a evolução em 0,4%/mês para embutir reajuste anual de ~5%.
A20: 3. USUÁRIOS
A21: Base no início do mês | E21: =0 -> 0 | F21: =E24 -> 0 | G21: =F24 -> 0 | H21: =G24 -> 0 | I21: =H24 -> 0 | J21: =I24 -> 0 | K21: =J24 -> 0 | L21: =K24 -> 0 | M21: =L24 -> 0 | ... BL21: =BK24 -> 894602 | BM21: =BL21 -> 894602
A22: (+) Novos usuários captados | E22: =ROUND(E15*$B$10,0) -> 0 | F22: =ROUND(F15*$B$10,0) -> 0 | G22: =ROUND(G15*$B$10,0) -> 0 | H22: =ROUND(H15*$B$10,0) -> 0 | I22: =ROUND(I15*$B$10,0) -> 0 | J22: =ROUND(J15*$B$10,0) -> 0 | K22: =ROUND(K15*$B$10,0) -> 0 | L22: =ROUND(L15*$B$10,0) -> 0 | ... BL22: =ROUND(BL15*$B$10,0) -> 90087 | BM22: =SUM(E22:BL22) -> 2207370
A23: (−) Usuários perdidos (churn) | E23: =-ROUND(E21*E16*$B$12,0) -> 0 | F23: =-ROUND(F21*F16*$B$12,0) -> 0 | G23: =-ROUND(G21*G16*$B$12,0) -> 0 | H23: =-ROUND(H21*H16*$B$12,0) -> 0 | I23: =-ROUND(I21*I16*$B$12,0) -> 0 | J23: =-ROUND(J21*J16*$B$12,0) -> 0 | K23: =-ROUND(K21*K16*$B$12,0) -> 0 | L23: =-ROUND(L21*L16*$B$12,0) -> 0 | ... BL23: =-ROUND(BL21*BL16*$B$12,0) -> -56264 | BM23: =SUM(E23:BL23) -> -1278945
A24: (=) BASE NO FIM DO MÊS | E24: =E21+E22+E23 -> 0 | F24: =F21+F22+F23 -> 0 | G24: =G21+G22+G23 -> 0 | H24: =H21+H22+H23 -> 0 | I24: =I21+I22+I23 -> 0 | J24: =J21+J22+J23 -> 0 | K24: =K21+K22+K23 -> 0 | L24: =L21+L22+L23 -> 0 | ... BL24: =BL21+BL22+BL23 -> 928425 | BM24: =BL24 -> 928425 | BN24: Pagantes + gratuitos. É esta linha que a aba Nuvem e Escala usa para achar a faixa.
A25: Assinantes pagantes | E25: =ROUND(E24*E17*$B$11,0) -> 0 | F25: =ROUND(F24*F17*$B$11,0) -> 0 | G25: =ROUND(G24*G17*$B$11,0) -> 0 | H25: =ROUND(H24*H17*$B$11,0) -> 0 | I25: =ROUND(I24*I17*$B$11,0) -> 0 | J25: =ROUND(J24*J17*$B$11,0) -> 0 | K25: =ROUND(K24*K17*$B$11,0) -> 0 | L25: =ROUND(L24*L17*$B$11,0) -> 0 | ... BL25: =ROUND(BL24*BL17*$B$11,0) -> 30501 | BM25: =BL25 -> 30501
A26: Usuários no plano gratuito | E26: =E24-E25 -> 0 | F26: =F24-F25 -> 0 | G26: =G24-G25 -> 0 | H26: =H24-H25 -> 0 | I26: =I24-I25 -> 0 | J26: =J24-J25 -> 0 | K26: =K24-K25 -> 0 | L26: =L24-L25 -> 0 | ... BL26: =BL24-BL25 -> 897924 | BM26: =BL26 -> 897924 | BN26: Não pagam e consomem nuvem. Quem assina sustenta quem não assina.
A27: % da base que paga | E27: =IFERROR(E25/E24,0) -> 0 | F27: =IFERROR(F25/F24,0) -> 0 | G27: =IFERROR(G25/G24,0) -> 0 | H27: =IFERROR(H25/H24,0) -> 0 | I27: =IFERROR(I25/I24,0) -> 0 | J27: =IFERROR(J25/J24,0) -> 0 | K27: =IFERROR(K25/K24,0) -> 0 | L27: =IFERROR(L25/L24,0) -> 0 | ... BL27: =IFERROR(BL25/BL24,0) -> 0.032852411 | BM27: =BL27 -> 0.032852411
A29: 4. FATURAMENTO
A30: Receita de assinaturas | E30: =E25*E18 -> 0 | F30: =F25*F18 -> 0 | G30: =G25*G18 -> 0 | H30: =H25*H18 -> 0 | I30: =I25*I18 -> 0 | J30: =J25*J18 -> 0 | K30: =K25*K18 -> 0 | L30: =L25*L18 -> 0 | ... BL30: =BL25*BL18 -> 1216989.9 | BM30: =SUM(E30:BL30) -> 15681219
A31: Receita B2B do investidor estratégico | E31: =Aportes!E55 -> 0 | F31: =Aportes!F55 -> 0 | G31: =Aportes!G55 -> 0 | H31: =Aportes!H55 -> 0 | I31: =Aportes!I55 -> 0 | J31: =Aportes!J55 -> 0 | K31: =Aportes!K55 -> 0 | L31: =Aportes!L55 -> 0 | ... BL31: =Aportes!BL55 -> 5000 | BM31: =SUM(E31:BL31) -> 230000 | BN31: Vem da aba Aportes, tabela 2. Entra só se o status permitir.
A32: Outras receitas (digite no mês) | B32: — | C32: — | D32: — | BM32: =SUM(E32:BL32) -> 0 | BN32: Venda de dados, marketplace, parceria pontual. Cada mês é uma célula livre.
A33: (=) FATURAMENTO BRUTO | E33: =SUM(E30:E32) -> 0 | F33: =SUM(F30:F32) -> 0 | G33: =SUM(G30:G32) -> 0 | H33: =SUM(H30:H32) -> 0 | I33: =SUM(I30:I32) -> 0 | J33: =SUM(J30:J32) -> 0 | K33: =SUM(K30:K32) -> 0 | L33: =SUM(L30:L32) -> 0 | ... BL33: =SUM(BL30:BL32) -> 1221989.9 | BM33: =SUM(E33:BL33) -> 15911219
A34: Faturamento dos últimos 12 meses (RBT12) | E34: =E33*12 -> 0 | F34: =SUM(E33:E33)/1*12 -> 0 | G34: =SUM(E33:F33)/2*12 -> 0 | H34: =SUM(E33:G33)/3*12 -> 0 | I34: =SUM(E33:H33)/4*12 -> 0 | J34: =SUM(E33:I33)/5*12 -> 0 | K34: =SUM(E33:J33)/6*12 -> 0 | L34: =SUM(E33:K33)/7*12 -> 0 | M34: =SUM(E33:L33)/8*12 -> 0 | N34: =SUM(E33:M33)/9*12 -> 0 | O34: =SUM(E33:N33)/10*12 -> 0 | P34: =SUM(E33:O33)/11*12 -> 0 | Q34: =SUM(E33:P33) -> 3630.9 | R34: =SUM(F33:Q33) -> 10972.5 | S34: =SUM(G33:R33) -> 22184.4 | T34: =SUM(H33:S33) -> 42426.2 | U34: =SUM(I33:T33) -> 66857.5 | V34: =SUM(J33:U33) -> 95677.8 | W34: =SUM(K33:V33) -> 129086.6 | X34: =SUM(L33:W33) -> 167363.2 | ... BL34: =SUM(AZ33:BK33) -> 9250605.9 | BM34: =BL34 -> 9250605.9 | BN34: Base de cálculo da faixa do Simples. Nos 12 primeiros meses é a média anualizada.
A35: (−) Imposto sobre a receita | B35: 0.155 | C35: 0 | D35: 1 | E35: =IF(E$5<$D35,0,$B35) -> 0.155 | F35: =IF(F$5<$D35,0,IF(E35=0,$B35,E35*(1+$C35))) -> 0.155 | G35: =IF(G$5<$D35,0,IF(F35=0,$B35,F35*(1+$C35))) -> 0.155 | H35: =IF(H$5<$D35,0,IF(G35=0,$B35,G35*(1+$C35))) -> 0.155 | I35: =IF(I$5<$D35,0,IF(H35=0,$B35,H35*(1+$C35))) -> 0.155 | J35: =IF(J$5<$D35,0,IF(I35=0,$B35,I35*(1+$C35))) -> 0.155 | K35: =IF(K$5<$D35,0,IF(J35=0,$B35,J35*(1+$C35))) -> 0.155 | L35: =IF(L$5<$D35,0,IF(K35=0,$B35,K35*(1+$C35))) -> 0.155 | M35: =IF(M$5<$D35,0,IF(L35=0,$B35,L35*(1+$C35))) -> 0.155 | ... BL35: =IF(BL$5<$D35,0,IF(BK35=0,$B35,BK35*(1+$C35))) -> 0.155 | BM35: =BL35 -> 0.155 | BN35: Você digita a alíquota. A linha cinza logo abaixo sugere a alíquota efetiva pela tabela do Anexo V, calculada a partir do RBT12 do mês.
A36: sugestão pela tabela do Simples (Anexo V) | E36: =IF(E34<=0,$B$92,IF(E34>4800000,$B$98,MAX($B$92,(INDEX($B$92:$B$97,MATCH(E34,$A$92:$A$97,1))*E34-INDEX($C$92:$C$97,MATCH(E34,$A$92:$A$97,1)))/E34))) -> 0.155 | F36: =IF(F34<=0,$B$92,IF(F34>4800000,$B$98,MAX($B$92,(INDEX($B$92:$B$97,MATCH(F34,$A$92:$A$97,1))*F34-INDEX($C$92:$C$97,MATCH(F34,$A$92:$A$97,1)))/F34))) -> 0.155 | G36: =IF(G34<=0,$B$92,IF(G34>4800000,$B$98,MAX($B$92,(INDEX($B$92:$B$97,MATCH(G34,$A$92:$A$97,1))*G34-INDEX($C$92:$C$97,MATCH(G34,$A$92:$A$97,1)))/G34))) -> 0.155 | H36: =IF(H34<=0,$B$92,IF(H34>4800000,$B$98,MAX($B$92,(INDEX($B$92:$B$97,MATCH(H34,$A$92:$A$97,1))*H34-INDEX($C$92:$C$97,MATCH(H34,$A$92:$A$97,1)))/H34))) -> 0.155 | I36: =IF(I34<=0,$B$92,IF(I34>4800000,$B$98,MAX($B$92,(INDEX($B$92:$B$97,MATCH(I34,$A$92:$A$97,1))*I34-INDEX($C$92:$C$97,MATCH(I34,$A$92:$A$97,1)))/I34))) -> 0.155 | J36: =IF(J34<=0,$B$92,IF(J34>4800000,$B$98,MAX($B$92,(INDEX($B$92:$B$97,MATCH(J34,$A$92:$A$97,1))*J34-INDEX($C$92:$C$97,MATCH(J34,$A$92:$A$97,1)))/J34))) -> 0.155 | K36: =IF(K34<=0,$B$92,IF(K34>4800000,$B$98,MAX($B$92,(INDEX($B$92:$B$97,MATCH(K34,$A$92:$A$97,1))*K34-INDEX($C$92:$C$97,MATCH(K34,$A$92:$A$97,1)))/K34))) -> 0.155 | L36: =IF(L34<=0,$B$92,IF(L34>4800000,$B$98,MAX($B$92,(INDEX($B$92:$B$97,MATCH(L34,$A$92:$A$97,1))*L34-INDEX($C$92:$C$97,MATCH(L34,$A$92:$A$97,1)))/L34))) -> 0.155 | ... BL36: =IF(BL34<=0,$B$92,IF(BL34>4800000,$B$98,MAX($B$92,(INDEX($B$92:$B$97,MATCH(BL34,$A$92:$A$97,1))*BL34-INDEX($C$92:$C$97,MATCH(BL34,$A$92:$A$97,1)))/BL34))) -> 0.1633 | BM36: =BL36 -> 0.1633 | BN36: Alíquota efetiva do Anexo V pelo RBT12 do mês. Se o número que você digitou acima estiver muito abaixo desta linha, o modelo está otimista no imposto.
A37: (−) Impostos sobre a receita | E37: =-E33*E35 -> 0 | F37: =-F33*F35 -> 0 | G37: =-G33*G35 -> 0 | H37: =-H33*H35 -> 0 | I37: =-I33*I35 -> 0 | J37: =-J33*J35 -> 0 | K37: =-K33*K35 -> 0 | L37: =-L33*L35 -> 0 | ... BL37: =-BL33*BL35 -> -189408.43 | BM37: =SUM(E37:BL37) -> -2466238.9
A38: (−) Comissão das lojas de aplicativos (% do bruto) | B38: 0.128 | C38: -0.003 | D38: 1 | E38: =IF(E$5<$D38,0,$B38) -> 0.128 | F38: =IF(F$5<$D38,0,IF(E38=0,$B38,E38*(1+$C38))) -> 0.127616 | G38: =IF(G$5<$D38,0,IF(F38=0,$B38,F38*(1+$C38))) -> 0.12723315 | H38: =IF(H$5<$D38,0,IF(G38=0,$B38,G38*(1+$C38))) -> 0.12685145 | I38: =IF(I$5<$D38,0,IF(H38=0,$B38,H38*(1+$C38))) -> 0.1264709 | J38: =IF(J$5<$D38,0,IF(I38=0,$B38,I38*(1+$C38))) -> 0.12609149 | K38: =IF(K$5<$D38,0,IF(J38=0,$B38,J38*(1+$C38))) -> 0.12571321 | L38: =IF(L$5<$D38,0,IF(K38=0,$B38,K38*(1+$C38))) -> 0.12533607 | M38: =IF(M$5<$D38,0,IF(L38=0,$B38,L38*(1+$C38))) -> 0.12496006 | ... BL38: =IF(BL$5<$D38,0,IF(BK38=0,$B38,BK38*(1+$C38))) -> 0.10720729 | BM38: =BL38 -> 0.10720729 | BN38: 15% da Apple/Google aplicados sobre a fatia cobrada dentro do app. Com 85% dentro do app: 15% × 85% = 12,8%. Vender fora do app reduz isto.
A39: (−) Comissão das lojas de aplicativos | E39: =-E30*E38 -> 0 | F39: =-F30*F38 -> 0 | G39: =-G30*G38 -> 0 | H39: =-H30*H38 -> 0 | I39: =-I30*I38 -> 0 | J39: =-J30*J38 -> 0 | K39: =-K30*K38 -> 0 | L39: =-L30*L38 -> 0 | ... BL39: =-BL30*BL38 -> -130470.19 | BM39: =SUM(E39:BL39) -> -1736683.3
A40: (−) Taxa de meio de pagamento (% do bruto) | B40: 0.0068 | C40: 0 | D40: 1 | E40: =IF(E$5<$D40,0,$B40) -> 0.0068 | F40: =IF(F$5<$D40,0,IF(E40=0,$B40,E40*(1+$C40))) -> 0.0068 | G40: =IF(G$5<$D40,0,IF(F40=0,$B40,F40*(1+$C40))) -> 0.0068 | H40: =IF(H$5<$D40,0,IF(G40=0,$B40,G40*(1+$C40))) -> 0.0068 | I40: =IF(I$5<$D40,0,IF(H40=0,$B40,H40*(1+$C40))) -> 0.0068 | J40: =IF(J$5<$D40,0,IF(I40=0,$B40,I40*(1+$C40))) -> 0.0068 | K40: =IF(K$5<$D40,0,IF(J40=0,$B40,J40*(1+$C40))) -> 0.0068 | L40: =IF(L$5<$D40,0,IF(K40=0,$B40,K40*(1+$C40))) -> 0.0068 | M40: =IF(M$5<$D40,0,IF(L40=0,$B40,L40*(1+$C40))) -> 0.0068 | ... BL40: =IF(BL$5<$D40,0,IF(BK40=0,$B40,BK40*(1+$C40))) -> 0.0068 | BM40: =BL40 -> 0.0068 | BN40: 4,5% de cartão/PIX sobre os 15% cobrados fora do app = 0,68%.
A41: (−) Taxas de meio de pagamento | E41: =-E33*E40 -> 0 | F41: =-F33*F40 -> 0 | G41: =-G33*G40 -> 0 | H41: =-H33*H40 -> 0 | I41: =-I33*I40 -> 0 | J41: =-J33*J40 -> 0 | K41: =-K33*K40 -> 0 | L41: =-L33*L40 -> 0 | ... BL41: =-BL33*BL40 -> -8309.5313 | BM41: =SUM(E41:BL41) -> -108196.29
A42: (=) FATURAMENTO LÍQUIDO | E42: =E33+E37+E39+E41 -> 0 | F42: =F33+F37+F39+F41 -> 0 | G42: =G33+G37+G39+G41 -> 0 | H42: =H33+H37+H39+H41 -> 0 | I42: =I33+I37+I39+I41 -> 0 | J42: =J33+J37+J39+J41 -> 0 | K42: =K33+K37+K39+K41 -> 0 | L42: =L33+L37+L39+L41 -> 0 | ... BL42: =BL33+BL37+BL39+BL41 -> 893801.75 | BM42: =SUM(E42:BL42) -> 11600100
A43: Fica para a empresa, de cada R$ 1 faturado | E43: =IFERROR(E42/E33,0) -> 0 | F43: =IFERROR(F42/F33,0) -> 0 | G43: =IFERROR(G42/G33,0) -> 0 | H43: =IFERROR(H42/H33,0) -> 0 | I43: =IFERROR(I42/I33,0) -> 0 | J43: =IFERROR(J42/J33,0) -> 0 | K43: =IFERROR(K42/K33,0) -> 0 | L43: =IFERROR(L42/L33,0) -> 0 | ... BL43: =IFERROR(BL42/BL33,0) -> 0.73143137 | BM43: =BL43 -> 0.73143137 | BN43: É o divisor de qualquer conta de preço: cobrar R$ 1 não é receber R$ 1.
A45: 5. CUSTOS E DESPESAS
A46: (−) Nuvem e infraestrutura | E46: =-'Nuvem e Escala'!E31 -> 0 | F46: =-'Nuvem e Escala'!F31 -> 0 | G46: =-'Nuvem e Escala'!G31 -> 0 | H46: =-'Nuvem e Escala'!H31 -> 0 | I46: =-'Nuvem e Escala'!I31 -> 0 | J46: =-'Nuvem e Escala'!J31 -> 0 | K46: =-'Nuvem e Escala'!K31 -> 0 | L46: =-'Nuvem e Escala'!L31 -> 0 | ... BL46: =-'Nuvem e Escala'!BL31 -> -100371.98 | BM46: =SUM(E46:BL46) -> -2268358.9 | BN46: Vem da aba Nuvem e Escala: a conta interpolada pela base deste mês.
...

Sheet Nuvem e Escala
A1: NUVEM E ESCALA — A CONTA DE NUVEM, DE TRÁS PRA FRENTE
A2: Você digita a CONTA mensal esperada em cada tamanho de base. O custo por usuário é calculado, e cai conforme a base cresce. Mês a mês, o modelo interpola pela base daquele mês.
A4: Linha do tempo | B4: valor inicial | C4: evolução/mês | D4: mês de início | E4: 46023 | F4: 46054 | G4: 46082 | H4: 46113 | I4: 46143 | J4: 46174 | K4: 46204 | L4: 46235 | M4: 46266 | N4: 46296 | O4: 46327 | P4: 46357 | Q4: 46388 | R4: 46419 | S4: 46447 | T4: 46478 | U4: 46508 | V4: 46539 | W4: 46569 | X4: 46600 | Y4: 46631 | Z4: 46661 | AA4: 46692 | AB4: 46722 | AC4: 46753 | AD4: 46784 | AE4: 46813 | AF4: 46844 | AG4: 46874 | AH4: 46905 | AI4: 46935 | AJ4: 46966 | AK4: 46997 | AL4: 47027 | AM4: 47058 | AN4: 47088 | AO4: 47119 | AP4: 47150 | AQ4: 47178 | AR4: 47209 | AS4: 47239 | AT4: 47270 | AU4: 47300 | AV4: 47331 | AW4: 47362 | AX4: 47392 | AY4: 47423 | AZ4: 47453 | BA4: 47484 | BB4: 47515 | BC4: 47543 | BD4: 47574 | BE4: 47604 | BF4: 47635 | BG4: 47665 | BH4: 47696 | BI4: 47727 | BJ4: 47757 | BK4: 47788 | BL4: 47818 | BM4: TOTAL | BN4: O que é / como mexer
A5: Mês nº | E5: 1 | F5: 2 | G5: 3 | H5: 4 | I5: 5 | J5: 6 | K5: 7 | L5: 8 | M5: 9 | N5: 10 | O5: 11 | P5: 12 | Q5: 13 | R5: 14 | S5: 15 | T5: 16 | U5: 17 | V5: 18 | W5: 19 | X5: 20 | Y5: 21 | Z5: 22 | AA5: 23 | AB5: 24 | AC5: 25 | AD5: 26 | AE5: 27 | AF5: 28 | AG5: 29 | AH5: 30 | AI5: 31 | AJ5: 32 | AK5: 33 | AL5: 34 | AM5: 35 | AN5: 36 | AO5: 37 | AP5: 38 | AQ5: 39 | AR5: 40 | AS5: 41 | AT5: 42 | AU5: 43 | AV5: 44 | AW5: 45 | AX5: 46 | AY5: 47 | AZ5: 48 | BA5: 49 | BB5: 50 | BC5: 51 | BD5: 52 | BE5: 53 | BF5: 54 | BG5: 55 | BH5: 56 | BI5: 57 | BJ5: 58 | BK5: 59 | BL5: 60
A6: Ano | E6: =YEAR(E4) -> 2026 | F6: =YEAR(F4) -> 2026 | G6: =YEAR(G4) -> 2026 | H6: =YEAR(H4) -> 2026 | I6: =YEAR(I4) -> 2026 | J6: =YEAR(J4) -> 2026 | K6: =YEAR(K4) -> 2026 | L6: =YEAR(L4) -> 2026 | ... BL6: =YEAR(BL4) -> 2030
A8: 0. QUEM CONSOME NUVEM
A9: Peso de um usuário do plano GRATUITO no consumo de nuvem | B9: 0.1 | D9: Um assinante pagante tem monitoramento contínuo: vale 100%. Um usuário do plano gratuito abre o app de vez em quando, recebe notificação e guarda pouco dado — aqui vale 10% de um pagante. É a premissa que mais muda o resultado do modelo, porque a base gratuita é 30 vezes maior que a pagante. Com 100% você está dizendo que o gratuito custa igual ao pagante; com 0%, que não custa nada.
A10: Mês em que a nuvem começa a custar | B10: 9 | D10: 1 = jan/2026 · 9 = set/2026 · 60 = dez/2030. Antes deste mês a conta é zero: não existe ambiente para pagar. Padrão 9, quando começa o desenvolvimento do MVP.
A12: 1. ÂNCORAS — a conta de nuvem em cada tamanho de base (você digita as colunas B e C)
A13: Usuários na base | B13: Conta de nuvem no mês (R$) | C13: R$ por usuário (calculado) | D13: O que entra nessa conta
A14: 0 | B14: 300 | C14: =IFERROR($B14/$A14,"–") -> – | D14: Ambiente mínimo: banco de dados pequeno, um servidor, backup e monitoramento. Existe mesmo com zero usuário.
A15: 100 | B15: 640 | C15: =IFERROR($B15/$A15,"–") -> 6.4 | D15: Piloto. Daqui sai o R$ 6,40 por usuário que apareceu na conta do sócio.
A16: 1000 | B16: 3200 | C16: =IFERROR($B16/$A16,"–") -> 3.2 | D16: Primeiro degrau de verdade: banco maior, fila de notificações, CDN.
A17: 10000 | B17: 16000 | C17: =IFERROR($B17/$A17,"–") -> 1.6 | D17: Começa a valer reserva de capacidade e desconto de compromisso.
A18: 100000 | B18: 90000 | C18: =IFERROR($B18/$A18,"–") -> 0.9 | D18: Escala em que se negocia contrato anual com o provedor.
A19: 1000000 | B19: 550000 | C19: =IFERROR($B19/$A19,"–") -> 0.55 | D19: Escala de operação nacional.
A21: Como ler: a terceira coluna é a divisão simples da conta pelo número de usuários. É ela que mostra o custo por usuário caindo de R$ 6,40 para R$ 0,55 conforme a base vai de 100 para 1 milhão. Se o provedor der uma cotação diferente, troque a conta na coluna B e todo o modelo se ajusta.
A23: 2. O QUE ISSO DÁ MÊS A MÊS — interpolado pela base de cada mês
A24: Assinantes pagantes (vem da DRE Mensal) | E24: ='DRE Mensal'!E$25 -> 0 | F24: ='DRE Mensal'!F$25 -> 0 | G24: ='DRE Mensal'!G$25 -> 0 | H24: ='DRE Mensal'!H$25 -> 0 | I24: ='DRE Mensal'!I$25 -> 0 | J24: ='DRE Mensal'!J$25 -> 0 | K24: ='DRE Mensal'!K$25 -> 0 | L24: ='DRE Mensal'!L$25 -> 0 | ... BL24: ='DRE Mensal'!BL$25 -> 30501 | BM24: =BL24 -> 30501
A25: Usuários do plano gratuito (vem da DRE Mensal) | E25: ='DRE Mensal'!E$26 -> 0 | F25: ='DRE Mensal'!F$26 -> 0 | G25: ='DRE Mensal'!G$26 -> 0 | H25: ='DRE Mensal'!H$26 -> 0 | I25: ='DRE Mensal'!I$26 -> 0 | J25: ='DRE Mensal'!J$26 -> 0 | K25: ='DRE Mensal'!K$26 -> 0 | L25: ='DRE Mensal'!L$26 -> 0 | ... BL25: ='DRE Mensal'!BL$26 -> 897924 | BM25: =BL25 -> 897924
A26: Usuários equivalentes que consomem nuvem | E26: =ROUND(E24+E25*$B$9,0) -> 0 | F26: =ROUND(F24+F25*$B$9,0) -> 0 | G26: =ROUND(G24+G25*$B$9,0) -> 0 | H26: =ROUND(H24+H25*$B$9,0) -> 0 | I26: =ROUND(I24+I25*$B$9,0) -> 0 | J26: =ROUND(J24+J25*$B$9,0) -> 0 | K26: =ROUND(K24+K25*$B$9,0) -> 0 | L26: =ROUND(L24+L25*$B$9,0) -> 0 | ... BL26: =ROUND(BL24+BL25*$B$9,0) -> 120293 | BM26: =BL26 -> 120293 | BN26: Pagantes contam 100%; gratuitos contam pelo peso da seção 0. É este número que entra na tabela de âncoras.
A27: Âncora imediatamente abaixo — usuários | E27: =INDEX($A$14:$A$19,MATCH(MIN(E26,MAX($A$14:$A$19)),$A$14:$A$19,1)) -> 0 | F27: =INDEX($A$14:$A$19,MATCH(MIN(F26,MAX($A$14:$A$19)),$A$14:$A$19,1)) -> 0 | G27: =INDEX($A$14:$A$19,MATCH(MIN(G26,MAX($A$14:$A$19)),$A$14:$A$19,1)) -> 0 | H27: =INDEX($A$14:$A$19,MATCH(MIN(H26,MAX($A$14:$A$19)),$A$14:$A$19,1)) -> 0 | I27: =INDEX($A$14:$A$19,MATCH(MIN(I26,MAX($A$14:$A$19)),$A$14:$A$19,1)) -> 0 | J27: =INDEX($A$14:$A$19,MATCH(MIN(J26,MAX($A$14:$A$19)),$A$14:$A$19,1)) -> 0 | K27: =INDEX($A$14:$A$19,MATCH(MIN(K26,MAX($A$14:$A$19)),$A$14:$A$19,1)) -> 0 | L27: =INDEX($A$14:$A$19,MATCH(MIN(L26,MAX($A$14:$A$19)),$A$14:$A$19,1)) -> 0 | ... BL27: =INDEX($A$14:$A$19,MATCH(MIN(BL26,MAX($A$14:$A$19)),$A$14:$A$19,1)) -> 100000 | BM27: =BL27 -> 100000
A28: Âncora imediatamente abaixo — conta | E28: =INDEX($B$14:$B$19,MATCH(MIN(E26,MAX($A$14:$A$19)),$A$14:$A$19,1)) -> 300 | F28: =INDEX($B$14:$B$19,MATCH(MIN(F26,MAX($A$14:$A$19)),$A$14:$A$19,1)) -> 300 | G28: =INDEX($B$14:$B$19,MATCH(MIN(G26,MAX($A$14:$A$19)),$A$14:$A$19,1)) -> 300 | H28: =INDEX($B$14:$B$19,MATCH(MIN(H26,MAX($A$14:$A$19)),$A$14:$A$19,1)) -> 300 | I28: =INDEX($B$14:$B$19,MATCH(MIN(I26,MAX($A$14:$A$19)),$A$14:$A$19,1)) -> 300 | J28: =INDEX($B$14:$B$19,MATCH(MIN(J26,MAX($A$14:$A$19)),$A$14:$A$19,1)) -> 300 | K28: =INDEX($B$14:$B$19,MATCH(MIN(K26,MAX($A$14:$A$19)),$A$14:$A$19,1)) -> 300 | L28: =INDEX($B$14:$B$19,MATCH(MIN(L26,MAX($A$14:$A$19)),$A$14:$A$19,1)) -> 300 | ... BL28: =INDEX($B$14:$B$19,MATCH(MIN(BL26,MAX($A$14:$A$19)),$A$14:$A$19,1)) -> 90000 | BM28: =SUM(E28:BL28) -> 1093300
A29: Âncora de cima — usuários | E29: =INDEX($A$14:$A$19,MIN(6,MATCH(MIN(E26,MAX($A$14:$A$19)),$A$14:$A$19,1)+1)) -> 100 | F29: =INDEX($A$14:$A$19,MIN(6,MATCH(MIN(F26,MAX($A$14:$A$19)),$A$14:$A$19,1)+1)) -> 100 | G29: =INDEX($A$14:$A$19,MIN(6,MATCH(MIN(G26,MAX($A$14:$A$19)),$A$14:$A$19,1)+1)) -> 100 | H29: =INDEX($A$14:$A$19,MIN(6,MATCH(MIN(H26,MAX($A$14:$A$19)),$A$14:$A$19,1)+1)) -> 100 | I29: =INDEX($A$14:$A$19,MIN(6,MATCH(MIN(I26,MAX($A$14:$A$19)),$A$14:$A$19,1)+1)) -> 100 | J29: =INDEX($A$14:$A$19,MIN(6,MATCH(MIN(J26,MAX($A$14:$A$19)),$A$14:$A$19,1)+1)) -> 100 | K29: =INDEX($A$14:$A$19,MIN(6,MATCH(MIN(K26,MAX($A$14:$A$19)),$A$14:$A$19,1)+1)) -> 100 | L29: =INDEX($A$14:$A$19,MIN(6,MATCH(MIN(L26,MAX($A$14:$A$19)),$A$14:$A$19,1)+1)) -> 100 | ... BL29: =INDEX($A$14:$A$19,MIN(6,MATCH(MIN(BL26,MAX($A$14:$A$19)),$A$14:$A$19,1)+1)) -> 1000000 | BM29: =BL29 -> 1000000
A30: Âncora de cima — conta | E30: =INDEX($B$14:$B$19,MIN(6,MATCH(MIN(E26,MAX($A$14:$A$19)),$A$14:$A$19,1)+1)) -> 640 | F30: =INDEX($B$14:$B$19,MIN(6,MATCH(MIN(F26,MAX($A$14:$A$19)),$A$14:$A$19,1)+1)) -> 640 | G30: =INDEX($B$14:$B$19,MIN(6,MATCH(MIN(G26,MAX($A$14:$A$19)),$A$14:$A$19,1)+1)) -> 640 | H30: =INDEX($B$14:$B$19,MIN(6,MATCH(MIN(H26,MAX($A$14:$A$19)),$A$14:$A$19,1)+1)) -> 640 | I30: =INDEX($B$14:$B$19,MIN(6,MATCH(MIN(I26,MAX($A$14:$A$19)),$A$14:$A$19,1)+1)) -> 640 | J30: =INDEX($B$14:$B$19,MIN(6,MATCH(MIN(J26,MAX($A$14:$A$19)),$A$14:$A$19,1)+1)) -> 640 | K30: =INDEX($B$14:$B$19,MIN(6,MATCH(MIN(K26,MAX($A$14:$A$19)),$A$14:$A$19,1)+1)) -> 640 | L30: =INDEX($B$14:$B$19,MIN(6,MATCH(MIN(L26,MAX($A$14:$A$19)),$A$14:$A$19,1)+1)) -> 640 | ... BL30: =INDEX($B$14:$B$19,MIN(6,MATCH(MIN(BL26,MAX($A$14:$A$19)),$A$14:$A$19,1)+1)) -> 550000 | BM30: =SUM(E30:BL30) -> 6347040
A31: CONTA DE NUVEM DO MÊS | E31: =IF(E$5<$B$10,0,IF(E26<=0,E28,IF(E29<=E27,E30/MAX(1,E29)*E26,E28+(E26-E27)*(E30-E28)/(E29-E27)))) -> 0 | F31: =IF(F$5<$B$10,0,IF(F26<=0,F28,IF(F29<=F27,F30/MAX(1,F29)*F26,F28+(F26-F27)*(F30-F28)/(F29-F27)))) -> 0 | G31: =IF(G$5<$B$10,0,IF(G26<=0,G28,IF(G29<=G27,G30/MAX(1,G29)*G26,G28+(G26-G27)*(G30-G28)/(G29-G27)))) -> 0 | H31: =IF(H$5<$B$10,0,IF(H26<=0,H28,IF(H29<=H27,H30/MAX(1,H29)*H26,H28+(H26-H27)*(H30-H28)/(H29-H27)))) -> 0 | I31: =IF(I$5<$B$10,0,IF(I26<=0,I28,IF(I29<=I27,I30/MAX(1,I29)*I26,I28+(I26-I27)*(I30-I28)/(I29-I27)))) -> 0 | J31: =IF(J$5<$B$10,0,IF(J26<=0,J28,IF(J29<=J27,J30/MAX(1,J29)*J26,J28+(J26-J27)*(J30-J28)/(J29-J27)))) -> 0 | K31: =IF(K$5<$B$10,0,IF(K26<=0,K28,IF(K29<=K27,K30/MAX(1,K29)*K26,K28+(K26-K27)*(K30-K28)/(K29-K27)))) -> 0 | L31: =IF(L$5<$B$10,0,IF(L26<=0,L28,IF(L29<=L27,L30/MAX(1,L29)*L26,L28+(L26-L27)*(L30-L28)/(L29-L27)))) -> 0 | ... BL31: =IF(BL$5<$B$10,0,IF(BL26<=0,BL28,IF(BL29<=BL27,BL30/MAX(1,BL29)*BL26,BL28+(BL26-BL27)*(BL30-BL28)/(BL29-BL27)))) -> 100371.98 | BM31: =SUM(E31:BL31) -> 2268358.9 | BN31: Interpolação linear entre as duas âncoras. Acima da última âncora, mantém o custo por usuário da última faixa.
A32: Custo de nuvem por usuário equivalente | E32: =IFERROR(E31/E26,0) -> 0 | F32: =IFERROR(F31/F26,0) -> 0 | G32: =IFERROR(G31/G26,0) -> 0 | H32: =IFERROR(H31/H26,0) -> 0 | I32: =IFERROR(I31/I26,0) -> 0 | J32: =IFERROR(J31/J26,0) -> 0 | K32: =IFERROR(K31/K26,0) -> 0 | L32: =IFERROR(L31/L26,0) -> 0 | ... BL32: =IFERROR(BL31/BL26,0) -> 0.83439583 | BM32: =BL32 -> 0.83439583 | BN32: É esta linha que cai com a escala. Compare o mês do lançamento com dezembro de 2030.
A34: Parcela da conta que vem dos assinantes pagantes | E34: =IFERROR(E31*E24/E26,0) -> 0 | F34: =IFERROR(F31*F24/F26,0) -> 0 | G34: =IFERROR(G31*G24/G26,0) -> 0 | H34: =IFERROR(H31*H24/H26,0) -> 0 | I34: =IFERROR(I31*I24/I26,0) -> 0 | J34: =IFERROR(J31*J24/J26,0) -> 0 | K34: =IFERROR(K31*K24/K26,0) -> 0 | L34: =IFERROR(L31*L24/L26,0) -> 0 | ... BL34: =IFERROR(BL31*BL24/BL26,0) -> 25449.907 | BM34: =SUM(E34:BL34) -> 367172.37
A35: Parcela da conta que vem do plano gratuito | E35: =IFERROR(E31*(E26-E24)/E26,0) -> 0 | F35: =IFERROR(F31*(F26-F24)/F26,0) -> 0 | G35: =IFERROR(G31*(G26-G24)/G26,0) -> 0 | H35: =IFERROR(H31*(H26-H24)/H26,0) -> 0 | I35: =IFERROR(I31*(I26-I24)/I26,0) -> 0 | J35: =IFERROR(J31*(J26-J24)/J26,0) -> 0 | K35: =IFERROR(K31*(K26-K24)/K26,0) -> 0 | L35: =IFERROR(L31*(L26-L24)/L26,0) -> 0 | ... BL35: =IFERROR(BL31*(BL26-BL24)/BL26,0) -> 74922.071 | BM35: =SUM(E35:BL35) -> 1900286.5 | BN35: O que o plano gratuito custa em nuvem. Não gera receita nenhuma.
A36: Subsídio do plano gratuito, por assinante pagante | E36: =IFERROR(E35/E24,0) -> 0 | F36: =IFERROR(F35/F24,0) -> 0 | G36: =IFERROR(G35/G24,0) -> 0 | H36: =IFERROR(H35/H24,0) -> 0 | I36: =IFERROR(I35/I24,0) -> 0 | J36: =IFERROR(J35/J24,0) -> 0 | K36: =IFERROR(K35/K24,0) -> 0 | L36: =IFERROR(L35/L24,0) -> 0 | ... BL36: =IFERROR(BL35/BL24,0) -> 2.4563808 | BM36: =SUM(E36:BL36) -> 563.40499 | BN36: Quanto cada assinante paga, sem saber, para sustentar os usuários gratuitos. Compare com o preço da assinatura: é a conta que decide se o plano gratuito cabe no modelo.
A37: Custo de nuvem por assinante pagante (total da conta ÷ pagantes) | E37: =IFERROR(E31/E24,0) -> 0 | F37: =IFERROR(F31/F24,0) -> 0 | G37: =IFERROR(G31/G24,0) -> 0 | H37: =IFERROR(H31/H24,0) -> 0 | I37: =IFERROR(I31/I24,0) -> 0 | J37: =IFERROR(J31/J24,0) -> 0 | K37: =IFERROR(K31/K24,0) -> 0 | L37: =IFERROR(L31/L24,0) -> 0 | ... BL37: =IFERROR(BL31/BL24,0) -> 3.2907766 | BM37: =SUM(E37:BL37) -> 618.7754 | BN37: É este o número que se compara com o preço da assinatura — não o custo por usuário equivalente.
A39: ✔ Conferência: a conta nunca pode cair quando a base sobe | E39: =1 -> 1 | F39: =IF(AND(F26>=E26,F31<E31-0.01),0,1) -> 1 | G39: =IF(AND(G26>=F26,G31<F31-0.01),0,1) -> 1 | H39: =IF(AND(H26>=G26,H31<G31-0.01),0,1) -> 1 | I39: =IF(AND(I26>=H26,I31<H31-0.01),0,1) -> 1 | J39: =IF(AND(J26>=I26,J31<I31-0.01),0,1) -> 1 | K39: =IF(AND(K26>=J26,K31<J31-0.01),0,1) -> 1 | L39: =IF(AND(L26>=K26,L31<K31-0.01),0,1) -> 1 | M39: =IF(AND(M26>=L26,M31<L31-0.01),0,1) -> 1 | ... BL39: =IF(AND(BL26>=BK26,BL31<BK31-0.01),0,1) -> 1 | BM39: =IF(MIN(E39:BL39)=1,"✔ monotônica","⚠ a conta caiu com a base subindo") -> ✔ monotônica | BN39: Com faixas em degrau esta linha acusaria erro. Com interpolação, não.
A41: Mesma mecânica serve para qualquer custo que escale: se o suporte, as licenças de software ou a taxa de um parceiro tiverem desconto por volume, copie este bloco. A aba DRE Mensal trata suporte como R$ por pagante porque, no tamanho da Oppa, suporte escala quase linear.

Sheet Equipe
A1: EQUIPE — UMA LINHA POR PAPEL
A2: Cada linha vale do mês de início ao mês de fim. As linhas de ampliação são ADICIONAIS: somam-se às anteriores. O interruptor de plano desliga tudo o que ainda não foi contratado.
A4: Linha do tempo | B4: valor inicial | C4: evolução/mês | D4: mês de início | E4: 46023 | F4: 46054 | G4: 46082 | H4: 46113 | I4: 46143 | J4: 46174 | K4: 46204 | L4: 46235 | M4: 46266 | N4: 46296 | O4: 46327 | P4: 46357 | Q4: 46388 | R4: 46419 | S4: 46447 | T4: 46478 | U4: 46508 | V4: 46539 | W4: 46569 | X4: 46600 | Y4: 46631 | Z4: 46661 | AA4: 46692 | AB4: 46722 | AC4: 46753 | AD4: 46784 | AE4: 46813 | AF4: 46844 | AG4: 46874 | AH4: 46905 | AI4: 46935 | AJ4: 46966 | AK4: 46997 | AL4: 47027 | AM4: 47058 | AN4: 47088 | AO4: 47119 | AP4: 47150 | AQ4: 47178 | AR4: 47209 | AS4: 47239 | AT4: 47270 | AU4: 47300 | AV4: 47331 | AW4: 47362 | AX4: 47392 | AY4: 47423 | AZ4: 47453 | BA4: 47484 | BB4: 47515 | BC4: 47543 | BD4: 47574 | BE4: 47604 | BF4: 47635 | BG4: 47665 | BH4: 47696 | BI4: 47727 | BJ4: 47757 | BK4: 47788 | BL4: 47818 | BM4: TOTAL | BN4: O que é / como mexer
A5: Mês nº | E5: 1 | F5: 2 | G5: 3 | H5: 4 | I5: 5 | J5: 6 | K5: 7 | L5: 8 | M5: 9 | N5: 10 | O5: 11 | P5: 12 | Q5: 13 | R5: 14 | S5: 15 | T5: 16 | U5: 17 | V5: 18 | W5: 19 | X5: 20 | Y5: 21 | Z5: 22 | AA5: 23 | AB5: 24 | AC5: 25 | AD5: 26 | AE5: 27 | AF5: 28 | AG5: 29 | AH5: 30 | AI5: 31 | AJ5: 32 | AK5: 33 | AL5: 34 | AM5: 35 | AN5: 36 | AO5: 37 | AP5: 38 | AQ5: 39 | AR5: 40 | AS5: 41 | AT5: 42 | AU5: 43 | AV5: 44 | AW5: 45 | AX5: 46 | AY5: 47 | AZ5: 48 | BA5: 49 | BB5: 50 | BC5: 51 | BD5: 52 | BE5: 53 | BF5: 54 | BG5: 55 | BH5: 56 | BI5: 57 | BJ5: 58 | BK5: 59 | BL5: 60
A6: Ano | E6: =YEAR(E4) -> 2026 | F6: =YEAR(F4) -> 2026 | G6: =YEAR(G4) -> 2026 | H6: =YEAR(H4) -> 2026 | I6: =YEAR(I4) -> 2026 | J6: =YEAR(J4) -> 2026 | K6: =YEAR(K4) -> 2026 | L6: =YEAR(L4) -> 2026 | ... BL6: =YEAR(BL4) -> 2030
A8: Considerar o plano de contratações? 1 = Sim · 0 = só o que já está contratado | B8: 1 | D8: Com 0, o modelo mostra a Oppa apenas com a equipe do MVP. Serve para ver o piso de custo.
A10: QUADRO — edite, acrescente ou apague linhas
A11: Função / papel | B11: Tipo | C11: Status | D11: Qtd | E11: Custo mensal por pessoa (R$) | F11: Encargos (% sobre o custo) | G11: Custo total mensal (R$) | H11: Início | I11: Fim | J11: Classificação
A12: Equipe PJ — desenvolvimento do MVP | B12: PJ | C12: Contratado | D12: 1 | E12: 10500 | F12: 0 | G12: =$D12*$E12*(1+$F12) -> 10500 | H12: 46266 | I12: 46296 | J12: Investimento
A13: Desenvolvimento — time base | B13: PJ | C13: Plano | D13: 2 | E13: 9000 | F13: 0 | G13: =$D13*$E13*(1+$F13) -> 18000 | H13: 46388 | I13: 47818 | J13: Despesa
A14: Desenvolvimento — ampliação 2028 (adicional) | B14: PJ | C14: Plano | D14: 3 | E14: 9500 | F14: 0 | G14: =$D14*$E14*(1+$F14) -> 28500 | H14: 46753 | I14: 47818 | J14: Despesa
A15: Desenvolvimento — ampliação 2029 (adicional) | B15: PJ | C15: Plano | D15: 5 | E15: 10000 | F15: 0 | G15: =$D15*$E15*(1+$F15) -> 50000 | H15: 47119 | I15: 47818 | J15: Despesa
A16: Desenvolvimento — ampliação 2030 (adicional) | B16: PJ | C16: Plano | D16: 6 | E16: 10500 | F16: 0 | G16: =$D16*$E16*(1+$F16) -> 63000 | H16: 47484 | I16: 47818 | J16: Despesa
A17: Suporte ao cliente — time base | B17: PJ | C17: Plano | D17: 1 | E17: 3500 | F17: 0 | G17: =$D17*$E17*(1+$F17) -> 3500 | H17: 46388 | I17: 47818 | J17: Despesa
A18: Suporte — ampliação 2028 (adicional) | B18: PJ | C18: Plano | D18: 3 | E18: 3500 | F18: 0 | G18: =$D18*$E18*(1+$F18) -> 10500 | H18: 46753 | I18: 47818 | J18: Despesa
A19: Suporte — ampliação 2029 (adicional) | B19: PJ | C19: Plano | D19: 6 | E19: 3800 | F19: 0 | G19: =$D19*$E19*(1+$F19) -> 22800 | H19: 47119 | I19: 47818 | J19: Despesa
A20: Suporte — ampliação 2030 (adicional) | B20: PJ | C20: Plano | D20: 8 | E20: 4000 | F20: 0 | G20: =$D20*$E20*(1+$F20) -> 32000 | H20: 47484 | I20: 47818 | J20: Despesa
A21: Growth e marketing | B21: PJ | C21: Plano | D21: 1 | E21: 6000 | F21: 0 | G21: =$D21*$E21*(1+$F21) -> 6000 | H21: 46388 | I21: 47818 | J21: Despesa
A22: Growth — ampliação 2028 (adicional) | B22: PJ | C22: Plano | D22: 2 | E22: 7000 | F22: 0 | G22: =$D22*$E22*(1+$F22) -> 14000 | H22: 46753 | I22: 47818 | J22: Despesa
A23: Growth — ampliação 2029 (adicional) | B23: PJ | C23: Plano | D23: 3 | E23: 8000 | F23: 0 | G23: =$D23*$E23*(1+$F23) -> 24000 | H23: 47119 | I23: 47818 | J23: Despesa
... A30: (exemplo) Contratação CLT | B30: CLT | C30: Plano | D30: 0 | E30: 8000 | F30: 0.7 | G30: =$D30*$E30*(1+$F30) -> 0 | H30: 46753 | I30: 47818 | J30: Despesa
B31: PJ | C31: Plano | D31: 0 | E31: 0 | F31: 0 | G31: =$D31*$E31*(1+$F31) -> 0 | H31: 46388 | I31: 47818 | J31: Despesa
B32: PJ | C32: Plano | D32: 0 | E32: 0 | F32: 0 | G32: =$D32*$E32*(1+$F32) -> 0 | H32: 46388 | I32: 47818 | J32: Despesa
B33: PJ | C33: Plano | D33: 0 | E33: 0 | F33: 0 | G33: =$D33*$E33*(1+$F33) -> 0 | H33: 46388 | I33: 47818 | J33: Despesa
B34: PJ | C34: Plano | D34: 0 | E34: 0 | F34: 0 | G34: =$D34*$E34*(1+$F34) -> 0 | H34: 46388 | I34: 47818 | J34: Despesa
B35: PJ | C35: Plano | D35: 0 | E35: 0 | F35: 0 | G35: =$D35*$E35*(1+$F35) -> 0 | H35: 46388 | I35: 47818 | J35: Despesa
B36: PJ | C36: Plano | D36: 0 | E36: 0 | F36: 0 | G36: =$D36*$E36*(1+$F36) -> 0 | H36: 46388 | I36: 47818 | J36: Despesa
B37: PJ | C37: Plano | D37: 0 | E37: 0 | F37: 0 | G37: =$D37*$E37*(1+$F37) -> 0 | H37: 46388 | I37: 47818 | J37: Despesa
B38: PJ | C38: Plano | D38: 0 | E38: 0 | F38: 0 | G38: =$D38*$E38*(1+$F38) -> 0 | H38: 46388 | I38: 47818 | J38: Despesa
A39: TOTAL DO QUADRO (soma de tudo, sem olhar data) | G39: =SUM(G12:G38) -> 399800
A41: O CUSTO MÊS A MÊS
A42: CUSTO DE EQUIPE NO MÊS (despesa) | E42: =SUMPRODUCT(($J$12:$J$38="Despesa")*(($C$12:$C$38="Contratado")+($C$12:$C$38="Plano")*$B$8)*($H$12:$H$38<=E$4)*($I$12:$I$38>=E$4)*$G$12:$G$38) -> 0 | F42: =SUMPRODUCT(($J$12:$J$38="Despesa")*(($C$12:$C$38="Contratado")+($C$12:$C$38="Plano")*$B$8)*($H$12:$H$38<=F$4)*($I$12:$I$38>=F$4)*$G$12:$G$38) -> 0 | G42: =SUMPRODUCT(($J$12:$J$38="Despesa")*(($C$12:$C$38="Contratado")+($C$12:$C$38="Plano")*$B$8)*($H$12:$H$38<=G$4)*($I$12:$I$38>=G$4)*$G$12:$G$38) -> 0 | H42: =SUMPRODUCT(($J$12:$J$38="Despesa")*(($C$12:$C$38="Contratado")+($C$12:$C$38="Plano")*$B$8)*($H$12:$H$38<=H$4)*($I$12:$I$38>=H$4)*$G$12:$G$38) -> 0 | I42: =SUMPRODUCT(($J$12:$J$38="Despesa")*(($C$12:$C$38="Contratado")+($C$12:$C$38="Plano")*$B$8)*($H$12:$H$38<=I$4)*($I$12:$I$38>=I$4)*$G$12:$G$38) -> 0 | J42: =SUMPRODUCT(($J$12:$J$38="Despesa")*(($C$12:$C$38="Contratado")+($C$12:$C$38="Plano")*$B$8)*($H$12:$H$38<=J$4)*($I$12:$I$38>=J$4)*$G$12:$G$38) -> 0 | K42: =SUMPRODUCT(($J$12:$J$38="Despesa")*(($C$12:$C$38="Contratado")+($C$12:$C$38="Plano")*$B$8)*($H$12:$H$38<=K$4)*($I$12:$I$38>=K$4)*$G$12:$G$38) -> 0 | L42: =SUMPRODUCT(($J$12:$J$38="Despesa")*(($C$12:$C$38="Contratado")+($C$12:$C$38="Plano")*$B$8)*($H$12:$H$38<=L$4)*($I$12:$I$38>=L$4)*$G$12:$G$38) -> 0 | ... BL42: =SUMPRODUCT(($J$12:$J$38="Despesa")*(($C$12:$C$38="Contratado")+($C$12:$C$38="Plano")*$B$8)*($H$12:$H$38<=BL$4)*($I$12:$I$38>=BL$4)*$G$12:$G$38) -> 374300 | BM42: =SUM(E42:BL42) -> 9451200 | BN42: Entra na DRE como despesa de pessoal.
A43: Equipe PJ | E43: =SUMPRODUCT(($B$12:$B$38="PJ")*($J$12:$J$38="Despesa")*(($C$12:$C$38="Contratado")+($C$12:$C$38="Plano")*$B$8)*($H$12:$H$38<=E$4)*($I$12:$I$38>=E$4)*$G$12:$G$38) -> 0 | F43: =SUMPRODUCT(($B$12:$B$38="PJ")*($J$12:$J$38="Despesa")*(($C$12:$C$38="Contratado")+($C$12:$C$38="Plano")*$B$8)*($H$12:$H$38<=F$4)*($I$12:$I$38>=F$4)*$G$12:$G$38) -> 0 | G43: =SUMPRODUCT(($B$12:$B$38="PJ")*($J$12:$J$38="Despesa")*(($C$12:$C$38="Contratado")+($C$12:$C$38="Plano")*$B$8)*($H$12:$H$38<=G$4)*($I$12:$I$38>=G$4)*$G$12:$G$38) -> 0 | H43: =SUMPRODUCT(($B$12:$B$38="PJ")*($J$12:$J$38="Despesa")*(($C$12:$C$38="Contratado")+($C$12:$C$38="Plano")*$B$8)*($H$12:$H$38<=H$4)*($I$12:$I$38>=H$4)*$G$12:$G$38) -> 0 | I43: =SUMPRODUCT(($B$12:$B$38="PJ")*($J$12:$J$38="Despesa")*(($C$12:$C$38="Contratado")+($C$12:$C$38="Plano")*$B$8)*($H$12:$H$38<=I$4)*($I$12:$I$38>=I$4)*$G$12:$G$38) -> 0 | J43: =SUMPRODUCT(($B$12:$B$38="PJ")*($J$12:$J$38="Despesa")*(($C$12:$C$38="Contratado")+($C$12:$C$38="Plano")*$B$8)*($H$12:$H$38<=J$4)*($I$12:$I$38>=J$4)*$G$12:$G$38) -> 0 | K43: =SUMPRODUCT(($B$12:$B$38="PJ")*($J$12:$J$38="Despesa")*(($C$12:$C$38="Contratado")+($C$12:$C$38="Plano")*$B$8)*($H$12:$H$38<=K$4)*($I$12:$I$38>=K$4)*$G$12:$G$38) -> 0 | L43: =SUMPRODUCT(($B$12:$B$38="PJ")*($J$12:$J$38="Despesa")*(($C$12:$C$38="Contratado")+($C$12:$C$38="Plano")*$B$8)*($H$12:$H$38<=L$4)*($I$12:$I$38>=L$4)*$G$12:$G$38) -> 0 | ... BL43: =SUMPRODUCT(($B$12:$B$38="PJ")*($J$12:$J$38="Despesa")*(($C$12:$C$38="Contratado")+($C$12:$C$38="Plano")*$B$8)*($H$12:$H$38<=BL$4)*($I$12:$I$38>=BL$4)*$G$12:$G$38) -> 342300 | BM43: =SUM(E43:BL43) -> 8323200
A44: Equipe CLT (com encargos) | E44: =SUMPRODUCT(($B$12:$B$38="CLT")*($J$12:$J$38="Despesa")*(($C$12:$C$38="Contratado")+($C$12:$C$38="Plano")*$B$8)*($H$12:$H$38<=E$4)*($I$12:$I$38>=E$4)*$G$12:$G$38) -> 0 | F44: =SUMPRODUCT(($B$12:$B$38="CLT")*($J$12:$J$38="Despesa")*(($C$12:$C$38="Contratado")+($C$12:$C$38="Plano")*$B$8)*($H$12:$H$38<=F$4)*($I$12:$I$38>=F$4)*$G$12:$G$38) -> 0 | G44: =SUMPRODUCT(($B$12:$B$38="CLT")*($J$12:$J$38="Despesa")*(($C$12:$C$38="Contratado")+($C$12:$C$38="Plano")*$B$8)*($H$12:$H$38<=G$4)*($I$12:$I$38>=G$4)*$G$12:$G$38) -> 0 | H44: =SUMPRODUCT(($B$12:$B$38="CLT")*($J$12:$J$38="Despesa")*(($C$12:$C$38="Contratado")+($C$12:$C$38="Plano")*$B$8)*($H$12:$H$38<=H$4)*($I$12:$I$38>=H$4)*$G$12:$G$38) -> 0 | I44: =SUMPRODUCT(($B$12:$B$38="CLT")*($J$12:$J$38="Despesa")*(($C$12:$C$38="Contratado")+($C$12:$C$38="Plano")*$B$8)*($H$12:$H$38<=I$4)*($I$12:$I$38>=I$4)*$G$12:$G$38) -> 0 | J44: =SUMPRODUCT(($B$12:$B$38="CLT")*($J$12:$J$38="Despesa")*(($C$12:$C$38="Contratado")+($C$12:$C$38="Plano")*$B$8)*($H$12:$H$38<=J$4)*($I$12:$I$38>=J$4)*$G$12:$G$38) -> 0 | K44: =SUMPRODUCT(($B$12:$B$38="CLT")*($J$12:$J$38="Despesa")*(($C$12:$C$38="Contratado")+($C$12:$C$38="Plano")*$B$8)*($H$12:$H$38<=K$4)*($I$12:$I$38>=K$4)*$G$12:$G$38) -> 0 | L44: =SUMPRODUCT(($B$12:$B$38="CLT")*($J$12:$J$38="Despesa")*(($C$12:$C$38="Contratado")+($C$12:$C$38="Plano")*$B$8)*($H$12:$H$38<=L$4)*($I$12:$I$38>=L$4)*$G$12:$G$38) -> 0 | ... BL44: =SUMPRODUCT(($B$12:$B$38="CLT")*($J$12:$J$38="Despesa")*(($C$12:$C$38="Contratado")+($C$12:$C$38="Plano")*$B$8)*($H$12:$H$38<=BL$4)*($I$12:$I$38>=BL$4)*$G$12:$G$38) -> 0 | BM44: =SUM(E44:BL44) -> 0
A45: Pró-labore dos sócios | E45: =SUMPRODUCT(($B$12:$B$38="Sócio")*($J$12:$J$38="Despesa")*(($C$12:$C$38="Contratado")+($C$12:$C$38="Plano")*$B$8)*($H$12:$H$38<=E$4)*($I$12:$I$38>=E$4)*$G$12:$G$38) -> 0 | F45: =SUMPRODUCT(($B$12:$B$38="Sócio")*($J$12:$J$38="Despesa")*(($C$12:$C$38="Contratado")+($C$12:$C$38="Plano")*$B$8)*($H$12:$H$38<=F$4)*($I$12:$I$38>=F$4)*$G$12:$G$38) -> 0 | G45: =SUMPRODUCT(($B$12:$B$38="Sócio")*($J$12:$J$38="Despesa")*(($C$12:$C$38="Contratado")+($C$12:$C$38="Plano")*$B$8)*($H$12:$H$38<=G$4)*($I$12:$I$38>=G$4)*$G$12:$G$38) -> 0 | H45: =SUMPRODUCT(($B$12:$B$38="Sócio")*($J$12:$J$38="Despesa")*(($C$12:$C$38="Contratado")+($C$12:$C$38="Plano")*$B$8)*($H$12:$H$38<=H$4)*($I$12:$I$38>=H$4)*$G$12:$G$38) -> 0 | I45: =SUMPRODUCT(($B$12:$B$38="Sócio")*($J$12:$J$38="Despesa")*(($C$12:$C$38="Contratado")+($C$12:$C$38="Plano")*$B$8)*($H$12:$H$38<=I$4)*($I$12:$I$38>=I$4)*$G$12:$G$38) -> 0 | J45: =SUMPRODUCT(($B$12:$B$38="Sócio")*($J$12:$J$38="Despesa")*(($C$12:$C$38="Contratado")+($C$12:$C$38="Plano")*$B$8)*($H$12:$H$38<=J$4)*($I$12:$I$38>=J$4)*$G$12:$G$38) -> 0 | K45: =SUMPRODUCT(($B$12:$B$38="Sócio")*($J$12:$J$38="Despesa")*(($C$12:$C$38="Contratado")+($C$12:$C$38="Plano")*$B$8)*($H$12:$H$38<=K$4)*($I$12:$I$38>=K$4)*$G$12:$G$38) -> 0 | L45: =SUMPRODUCT(($B$12:$B$38="Sócio")*($J$12:$J$38="Despesa")*(($C$12:$C$38="Contratado")+($C$12:$C$38="Plano")*$B$8)*($H$12:$H$38<=L$4)*($I$12:$I$38>=L$4)*$G$12:$G$38) -> 0 | ... BL45: =SUMPRODUCT(($B$12:$B$38="Sócio")*($J$12:$J$38="Despesa")*(($C$12:$C$38="Contratado")+($C$12:$C$38="Plano")*$B$8)*($H$12:$H$38<=BL$4)*($I$12:$I$38>=BL$4)*$G$12:$G$38) -> 32000 | BM45: =SUM(E45:BL45) -> 1128000
A46: Desenvolvimento capitalizado (investimento, não despesa) | E46: =SUMPRODUCT(($J$12:$J$38="Investimento")*(($C$12:$C$38="Contratado")+($C$12:$C$38="Plano")*$B$8)*($H$12:$H$38<=E$4)*($I$12:$I$38>=E$4)*$G$12:$G$38) -> 0 | F46: =SUMPRODUCT(($J$12:$J$38="Investimento")*(($C$12:$C$38="Contratado")+($C$12:$C$38="Plano")*$B$8)*($H$12:$H$38<=F$4)*($I$12:$I$38>=F$4)*$G$12:$G$38) -> 0 | G46: =SUMPRODUCT(($J$12:$J$38="Investimento")*(($C$12:$C$38="Contratado")+($C$12:$C$38="Plano")*$B$8)*($H$12:$H$38<=G$4)*($I$12:$I$38>=G$4)*$G$12:$G$38) -> 0 | H46: =SUMPRODUCT(($J$12:$J$38="Investimento")*(($C$12:$C$38="Contratado")+($C$12:$C$38="Plano")*$B$8)*($H$12:$H$38<=H$4)*($I$12:$I$38>=H$4)*$G$12:$G$38) -> 0 | I46: =SUMPRODUCT(($J$12:$J$38="Investimento")*(($C$12:$C$38="Contratado")+($C$12:$C$38="Plano")*$B$8)*($H$12:$H$38<=I$4)*($I$12:$I$38>=I$4)*$G$12:$G$38) -> 0 | J46: =SUMPRODUCT(($J$12:$J$38="Investimento")*(($C$12:$C$38="Contratado")+($C$12:$C$38="Plano")*$B$8)*($H$12:$H$38<=J$4)*($I$12:$I$38>=J$4)*$G$12:$G$38) -> 0 | K46: =SUMPRODUCT(($J$12:$J$38="Investimento")*(($C$12:$C$38="Contratado")+($C$12:$C$38="Plano")*$B$8)*($H$12:$H$38<=K$4)*($I$12:$I$38>=K$4)*$G$12:$G$38) -> 0 | L46: =SUMPRODUCT(($J$12:$J$38="Investimento")*(($C$12:$C$38="Contratado")+($C$12:$C$38="Plano")*$B$8)*($H$12:$H$38<=L$4)*($I$12:$I$38>=L$4)*$G$12:$G$38) -> 0 | ... BL46: =SUMPRODUCT(($J$12:$J$38="Investimento")*(($C$12:$C$38="Contratado")+($C$12:$C$38="Plano")*$B$8)*($H$12:$H$38<=BL$4)*($I$12:$I$38>=BL$4)*$G$12:$G$38) -> 0 | BM46: =SUM(E46:BL46) -> 21000 | BN46: Vai para a linha de investimento da DRE, não para a de pessoal.
A47: Pessoas na operação (headcount) | E47: =SUMPRODUCT((($C$12:$C$38="Contratado")+($C$12:$C$38="Plano")*$B$8)*($H$12:$H$38<=E$4)*($I$12:$I$38>=E$4)*$D$12:$D$38) -> 0 | F47: =SUMPRODUCT((($C$12:$C$38="Contratado")+($C$12:$C$38="Plano")*$B$8)*($H$12:$H$38<=F$4)*($I$12:$I$38>=F$4)*$D$12:$D$38) -> 0 | G47: =SUMPRODUCT((($C$12:$C$38="Contratado")+($C$12:$C$38="Plano")*$B$8)*($H$12:$H$38<=G$4)*($I$12:$I$38>=G$4)*$D$12:$D$38) -> 0 | H47: =SUMPRODUCT((($C$12:$C$38="Contratado")+($C$12:$C$38="Plano")*$B$8)*($H$12:$H$38<=H$4)*($I$12:$I$38>=H$4)*$D$12:$D$38) -> 0 | I47: =SUMPRODUCT((($C$12:$C$38="Contratado")+($C$12:$C$38="Plano")*$B$8)*($H$12:$H$38<=I$4)*($I$12:$I$38>=I$4)*$D$12:$D$38) -> 0 | J47: =SUMPRODUCT((($C$12:$C$38="Contratado")+($C$12:$C$38="Plano")*$B$8)*($H$12:$H$38<=J$4)*($I$12:$I$38>=J$4)*$D$12:$D$38) -> 0 | K47: =SUMPRODUCT((($C$12:$C$38="Contratado")+($C$12:$C$38="Plano")*$B$8)*($H$12:$H$38<=K$4)*($I$12:$I$38>=K$4)*$D$12:$D$38) -> 0 | L47: =SUMPRODUCT((($C$12:$C$38="Contratado")+($C$12:$C$38="Plano")*$B$8)*($H$12:$H$38<=L$4)*($I$12:$I$38>=L$4)*$D$12:$D$38) -> 0 | ... BL47: =SUMPRODUCT((($C$12:$C$38="Contratado")+($C$12:$C$38="Plano")*$B$8)*($H$12:$H$38<=BL$4)*($I$12:$I$38>=BL$4)*$D$12:$D$38) -> 50 | BM47: =BL47 -> 50

Sheet Aportes
A1: APORTES E INVESTIDORES — TODO O CAPITAL QUE ENTRA
A2: O STATUS de cada linha decide se ela entra no modelo. Os dois interruptores abaixo ligam e desligam o que ainda não está assinado.
A4: Linha do tempo | B4: valor inicial | C4: evolução/mês | D4: mês de início | E4: 46023 | F4: 46054 | G4: 46082 | H4: 46113 | I4: 46143 | J4: 46174 | K4: 46204 | L4: 46235 | M4: 46266 | N4: 46296 | O4: 46327 | P4: 46357 | Q4: 46388 | R4: 46419 | S4: 46447 | T4: 46478 | U4: 46508 | V4: 46539 | W4: 46569 | X4: 46600 | Y4: 46631 | Z4: 46661 | AA4: 46692 | AB4: 46722 | AC4: 46753 | AD4: 46784 | AE4: 46813 | AF4: 46844 | AG4: 46874 | AH4: 46905 | AI4: 46935 | AJ4: 46966 | AK4: 46997 | AL4: 47027 | AM4: 47058 | AN4: 47088 | AO4: 47119 | AP4: 47150 | AQ4: 47178 | AR4: 47209 | AS4: 47239 | AT4: 47270 | AU4: 47300 | AV4: 47331 | AW4: 47362 | AX4: 47392 | AY4: 47423 | AZ4: 47453 | BA4: 47484 | BB4: 47515 | BC4: 47543 | BD4: 47574 | BE4: 47604 | BF4: 47635 | BG4: 47665 | BH4: 47696 | BI4: 47727 | BJ4: 47757 | BK4: 47788 | BL4: 47818 | BM4: TOTAL | BN4: O que é / como mexer
A5: Mês nº | E5: 1 | F5: 2 | G5: 3 | H5: 4 | I5: 5 | J5: 6 | K5: 7 | L5: 8 | M5: 9 | N5: 10 | O5: 11 | P5: 12 | Q5: 13 | R5: 14 | S5: 15 | T5: 16 | U5: 17 | V5: 18 | W5: 19 | X5: 20 | Y5: 21 | Z5: 22 | AA5: 23 | AB5: 24 | AC5: 25 | AD5: 26 | AE5: 27 | AF5: 28 | AG5: 29 | AH5: 30 | AI5: 31 | AJ5: 32 | AK5: 33 | AL5: 34 | AM5: 35 | AN5: 36 | AO5: 37 | AP5: 38 | AQ5: 39 | AR5: 40 | AS5: 41 | AT5: 42 | AU5: 43 | AV5: 44 | AW5: 45 | AX5: 46 | AY5: 47 | AZ5: 48 | BA5: 49 | BB5: 50 | BC5: 51 | BD5: 52 | BE5: 53 | BF5: 54 | BG5: 55 | BH5: 56 | BI5: 57 | BJ5: 58 | BK5: 59 | BL5: 60
A6: Ano | E6: =YEAR(E4) -> 2026 | F6: =YEAR(F4) -> 2026 | G6: =YEAR(G4) -> 2026 | H6: =YEAR(H4) -> 2026 | I6: =YEAR(I4) -> 2026 | J6: =YEAR(J4) -> 2026 | K6: =YEAR(K4) -> 2026 | L6: =YEAR(L4) -> 2026 | ... BL6: =YEAR(BL4) -> 2030
A8: Considerar aportes PREVISTOS? 1 = Sim · 0 = Não | B8: 1 | D8: Negociação adiantada, sem assinatura.
A9: Considerar acordos EM NEGOCIAÇÃO? 1 = Sim · 0 = Não | B9: 1 | D9: Sem compromisso nenhum. Hoje são os R$ 80 mil de C-ioT e Martinelli e os R$ 200 mil da Boston. Desligue para ver a Oppa só com o dinheiro que já entrou.
A11: 1. LANÇAMENTOS DE APORTE
A12: Data | B12: Sócio / Investidor | C12: Valor (R$) | D12: Status | E12: Tipo
A13: 46128 | B13: Paulo Kapp | C13: 10000 | D13: Realizado | E13: Fundador
A14: 46207 | B14: Lucas Medina | C14: 5000 | D14: Realizado | E14: Fundador
A15: 46254 | B15: Paulo Kapp | C15: 10000 | D15: Realizado | E15: Fundador
A16: 46254 | B16: Felipe Toescher | C16: 3000 | D16: Realizado | E16: Fundador
A17: 46254 | B17: Lucas Iung | C17: 2000 | D17: Realizado | E17: Fundador
A18: 46263 | B18: Lucas Iung | C18: 3000 | D18: Realizado | E18: Fundador
A19: 46269 | B19: Felipe Toescher | C19: 2000 | D19: Realizado | E19: Fundador
A20: 46281 | B20: Lucas Iung | C20: 1000 | D20: Realizado | E20: Fundador
A21: 46281 | B21: Lucas Medina | C21: 1000 | D21: Realizado | E21: Fundador
A22: 46310 | B22: C-ioT | C22: 40000 | D22: Em negociação | E22: Novo sócio
A23: 46310 | B23: Felipe Martinelli | C23: 40000 | D23: Em negociação | E23: Novo sócio
A24: 46402 | C24: 0 | D24: Previsto | E24: Novo sócio
A25: 46402 | C25: 0 | D25: Previsto | E25: Novo sócio
A26: 46402 | C26: 0 | D26: Previsto | E26: Novo sócio
A27: 46402 | C27: 0 | D27: Previsto | E27: Novo sócio
A28: 46402 | C28: 0 | D28: Previsto | E28: Novo sócio
A29: 46402 | C29: 0 | D29: Previsto | E29: Novo sócio
A30: 46402 | C30: 0 | D30: Previsto | E30: Novo sócio
A31: 46402 | C31: 0 | D31: Previsto | E31: Novo sócio
A32: 46402 | C32: 0 | D32: Previsto | E32: Novo sócio
A33: 46402 | C33: 0 | D33: Previsto | E33: Novo sócio
A34: 46402 | C34: 0 | D34: Previsto | E34: Novo sócio
A35: 46402 | C35: 0 | D35: Previsto | E35: Novo sócio
... A37: 46402 | C37: 0 | D37: Previsto | E37: Novo sócio
B38: TOTAL que o modelo considera | C38: =SUMPRODUCT((($D$13:$D$37="Realizado")+($D$13:$D$37="Compromisso")+($D$13:$D$37="Previsto")*$B$8+($D$13:$D$37="Em negociação")*$B$9)*$C$13:$C$37) -> 117000
A40: 2. INVESTIDOR ESTRATÉGICO — aporta e traz receita recorrente
A41: Investidor | B41: Status | C41: Aporte (R$) | D41: Mês do aporte | E41: Receita B2B (R$/mês) | F41: Início da receita | G41: Fim da receita
A42: Boston Scientific | B42: Em negociação | C42: 200000 | D42: 46419 | E42: 5000 | F42: 46447 | G42: 47818
B43: Em negociação | C43: 0 | D43: 46753 | E43: 0 | F43: 46753 | G43: 47818
B44: Em negociação | C44: 0 | D44: 46753 | E44: 0 | F44: 46753 | G44: 47818
B45: Em negociação | C45: 0 | D45: 46753 | E45: 0 | F45: 46753 | G45: 47818
...
